Warning: no access to tty (Bad file descriptor).
Thus no job control in this shell.
WARNING:torch.distributed.run:
*****************************************
Setting OMP_NUM_THREADS environment variable for each process to be 1 in default, to avoid your system being overloaded, please further tune the variable for optimal performance in your application as needed. 
*****************************************
Traceback (most recent call last):
Traceback (most recent call last):
Traceback (most recent call last):
  File "/sciclone/home20/hmbaier/tm/run.py", line 242, in <module>
  File "/sciclone/home20/hmbaier/tm/run.py", line 242, in <module>
  File "/sciclone/home20/hmbaier/tm/run.py", line 242, in <module>
            main(int(os.environ["RANK"]), int(os.environ['WORLD_SIZE']), model_group)main(int(os.environ["RANK"]), int(os.environ['WORLD_SIZE']), model_group)main(int(os.environ["RANK"]), int(os.environ['WORLD_SIZE']), model_group)


  File "/sciclone/home20/hmbaier/.conda/envs/dhsrl4/lib/python3.9/site-packages/torch/distributed/elastic/multiprocessing/errors/__init__.py", line 345, in wrapper
  File "/sciclone/home20/hmbaier/.conda/envs/dhsrl4/lib/python3.9/site-packages/torch/distributed/elastic/multiprocessing/errors/__init__.py", line 345, in wrapper
  File "/sciclone/home20/hmbaier/.conda/envs/dhsrl4/lib/python3.9/site-packages/torch/distributed/elastic/multiprocessing/errors/__init__.py", line 345, in wrapper
Traceback (most recent call last):
  File "/sciclone/home20/hmbaier/tm/run.py", line 242, in <module>
Traceback (most recent call last):
  File "/sciclone/home20/hmbaier/tm/run.py", line 242, in <module>
                return f(*args, **kwargs)return f(*args, **kwargs)return f(*args, **kwargs)main(int(os.environ["RANK"]), int(os.environ['WORLD_SIZE']), model_group)



  File "/sciclone/home20/hmbaier/tm/run.py", line 100, in main
  File "/sciclone/home20/hmbaier/tm/run.py", line 100, in main
  File "/sciclone/home20/hmbaier/tm/run.py", line 100, in main
  File "/sciclone/home20/hmbaier/.conda/envs/dhsrl4/lib/python3.9/site-packages/torch/distributed/elastic/multiprocessing/errors/__init__.py", line 345, in wrapper
    main(int(os.environ["RANK"]), int(os.environ['WORLD_SIZE']), model_group)
  File "/sciclone/home20/hmbaier/.conda/envs/dhsrl4/lib/python3.9/site-packages/torch/distributed/elastic/multiprocessing/errors/__init__.py", line 345, in wrapper
Traceback (most recent call last):
  File "/sciclone/home20/hmbaier/tm/run.py", line 242, in <module>
            ddp_model = DDP(model, process_group = model_group)ddp_model = DDP(model, process_group = model_group)ddp_model = DDP(model, process_group = model_group)


  File "/sciclone/home20/hmbaier/.conda/envs/dhsrl4/lib/python3.9/site-packages/torch/nn/parallel/distributed.py", line 578, in __init__
  File "/sciclone/home20/hmbaier/.conda/envs/dhsrl4/lib/python3.9/site-packages/torch/nn/parallel/distributed.py", line 578, in __init__
  File "/sciclone/home20/hmbaier/.conda/envs/dhsrl4/lib/python3.9/site-packages/torch/nn/parallel/distributed.py", line 578, in __init__
        return f(*args, **kwargs)return f(*args, **kwargs)

  File "/sciclone/home20/hmbaier/tm/run.py", line 100, in main
  File "/sciclone/home20/hmbaier/tm/run.py", line 100, in main
    main(int(os.environ["RANK"]), int(os.environ['WORLD_SIZE']), model_group)
  File "/sciclone/home20/hmbaier/.conda/envs/dhsrl4/lib/python3.9/site-packages/torch/distributed/elastic/multiprocessing/errors/__init__.py", line 345, in wrapper
    dist._verify_model_across_ranks(self.process_group, parameters)
RuntimeError: [/opt/conda/conda-bld/pytorch_1634272107467/work/third_party/gloo/gloo/transport/tcp/pair.cc:598] Connection closed by peer [10.3.59.5]:11694
    ddp_model = DDP(model, process_group = model_group)
  File "/sciclone/home20/hmbaier/.conda/envs/dhsrl4/lib/python3.9/site-packages/torch/nn/parallel/distributed.py", line 578, in __init__
    ddp_model = DDP(model, process_group = model_group)
          File "/sciclone/home20/hmbaier/.conda/envs/dhsrl4/lib/python3.9/site-packages/torch/nn/parallel/distributed.py", line 578, in __init__
dist._verify_model_across_ranks(self.process_group, parameters)dist._verify_model_across_ranks(self.process_group, parameters)

RuntimeErrorRuntimeError: : [/opt/conda/conda-bld/pytorch_1634272107467/work/third_party/gloo/gloo/transport/tcp/pair.cc:598] Connection closed by peer [10.3.59.5]:56492[/opt/conda/conda-bld/pytorch_1634272107467/work/third_party/gloo/gloo/transport/tcp/pair.cc:598] Connection closed by peer [10.3.59.5]:65199

    return f(*args, **kwargs)
  File "/sciclone/home20/hmbaier/tm/run.py", line 100, in main
    dist._verify_model_across_ranks(self.process_group, parameters)
RuntimeError: [/opt/conda/conda-bld/pytorch_1634272107467/work/third_party/gloo/gloo/transport/tcp/pair.cc:598] Connection closed by peer [10.3.59.5]:62867
    dist._verify_model_across_ranks(self.process_group, parameters)    
ddp_model = DDP(model, process_group = model_group)
RuntimeError  File "/sciclone/home20/hmbaier/.conda/envs/dhsrl4/lib/python3.9/site-packages/torch/nn/parallel/distributed.py", line 578, in __init__
: [/opt/conda/conda-bld/pytorch_1634272107467/work/third_party/gloo/gloo/transport/tcp/pair.cc:598] Connection closed by peer [10.3.59.5]:43912
    dist._verify_model_across_ranks(self.process_group, parameters)
RuntimeError: [/opt/conda/conda-bld/pytorch_1634272107467/work/third_party/gloo/gloo/transport/tcp/pair.cc:598] Connection closed by peer [10.3.59.5]:63145
Traceback (most recent call last):
  File "/sciclone/home20/hmbaier/tm/run.py", line 242, in <module>
    main(int(os.environ["RANK"]), int(os.environ['WORLD_SIZE']), model_group)
  File "/sciclone/home20/hmbaier/.conda/envs/dhsrl4/lib/python3.9/site-packages/torch/distributed/elastic/multiprocessing/errors/__init__.py", line 345, in wrapper
    return f(*args, **kwargs)
  File "/sciclone/home20/hmbaier/tm/run.py", line 100, in main
    ddp_model = DDP(model, process_group = model_group)
  File "/sciclone/home20/hmbaier/.conda/envs/dhsrl4/lib/python3.9/site-packages/torch/nn/parallel/distributed.py", line 580, in __init__
    self._sync_params_and_buffers(authoritative_rank=0)
  File "/sciclone/home20/hmbaier/.conda/envs/dhsrl4/lib/python3.9/site-packages/torch/nn/parallel/distributed.py", line 597, in _sync_params_and_buffers
Traceback (most recent call last):
  File "/sciclone/home20/hmbaier/tm/run.py", line 242, in <module>
    main(int(os.environ["RANK"]), int(os.environ['WORLD_SIZE']), model_group)
  File "/sciclone/home20/hmbaier/.conda/envs/dhsrl4/lib/python3.9/site-packages/torch/distributed/elastic/multiprocessing/errors/__init__.py", line 345, in wrapper
    return f(*args, **kwargs)
  File "/sciclone/home20/hmbaier/tm/run.py", line 100, in main
    ddp_model = DDP(model, process_group = model_group)
  File "/sciclone/home20/hmbaier/.conda/envs/dhsrl4/lib/python3.9/site-packages/torch/nn/parallel/distributed.py", line 580, in __init__
    self._sync_params_and_buffers(authoritative_rank=0)
  File "/sciclone/home20/hmbaier/.conda/envs/dhsrl4/lib/python3.9/site-packages/torch/nn/parallel/distributed.py", line 597, in _sync_params_and_buffers
    self._distributed_broadcast_coalesced(
  File "/sciclone/home20/hmbaier/.conda/envs/dhsrl4/lib/python3.9/site-packages/torch/nn/parallel/distributed.py", line 1334, in _distributed_broadcast_coalesced
    dist._broadcast_coalesced(
RuntimeError: [/opt/conda/conda-bld/pytorch_1634272107467/work/third_party/gloo/gloo/transport/tcp/pair.cc:598] Connection closed by peer [10.3.59.5]:7059
    self._distributed_broadcast_coalesced(
  File "/sciclone/home20/hmbaier/.conda/envs/dhsrl4/lib/python3.9/site-packages/torch/nn/parallel/distributed.py", line 1334, in _distributed_broadcast_coalesced
    dist._broadcast_coalesced(
RuntimeError: [/opt/conda/conda-bld/pytorch_1634272107467/work/third_party/gloo/gloo/transport/tcp/pair.cc:598] Connection closed by peer [10.3.59.5]:32921
Traceback (most recent call last):
  File "/sciclone/home20/hmbaier/tm/run.py", line 242, in <module>
Traceback (most recent call last):
  File "/sciclone/home20/hmbaier/tm/run.py", line 242, in <module>
    main(int(os.environ["RANK"]), int(os.environ['WORLD_SIZE']), model_group)
  File "/sciclone/home20/hmbaier/.conda/envs/dhsrl4/lib/python3.9/site-packages/torch/distributed/elastic/multiprocessing/errors/__init__.py", line 345, in wrapper
    main(int(os.environ["RANK"]), int(os.environ['WORLD_SIZE']), model_group)
  File "/sciclone/home20/hmbaier/.conda/envs/dhsrl4/lib/python3.9/site-packages/torch/distributed/elastic/multiprocessing/errors/__init__.py", line 345, in wrapper
        return f(*args, **kwargs)return f(*args, **kwargs)

  File "/sciclone/home20/hmbaier/tm/run.py", line 100, in main
  File "/sciclone/home20/hmbaier/tm/run.py", line 100, in main
        ddp_model = DDP(model, process_group = model_group)ddp_model = DDP(model, process_group = model_group)

  File "/sciclone/home20/hmbaier/.conda/envs/dhsrl4/lib/python3.9/site-packages/torch/nn/parallel/distributed.py", line 580, in __init__
  File "/sciclone/home20/hmbaier/.conda/envs/dhsrl4/lib/python3.9/site-packages/torch/nn/parallel/distributed.py", line 580, in __init__
        self._sync_params_and_buffers(authoritative_rank=0)self._sync_params_and_buffers(authoritative_rank=0)

  File "/sciclone/home20/hmbaier/.conda/envs/dhsrl4/lib/python3.9/site-packages/torch/nn/parallel/distributed.py", line 597, in _sync_params_and_buffers
  File "/sciclone/home20/hmbaier/.conda/envs/dhsrl4/lib/python3.9/site-packages/torch/nn/parallel/distributed.py", line 597, in _sync_params_and_buffers
    self._distributed_broadcast_coalesced(
  File "/sciclone/home20/hmbaier/.conda/envs/dhsrl4/lib/python3.9/site-packages/torch/nn/parallel/distributed.py", line 1334, in _distributed_broadcast_coalesced
    self._distributed_broadcast_coalesced(
  File "/sciclone/home20/hmbaier/.conda/envs/dhsrl4/lib/python3.9/site-packages/torch/nn/parallel/distributed.py", line 1334, in _distributed_broadcast_coalesced
    dist._broadcast_coalesced(
RuntimeError: [/opt/conda/conda-bld/pytorch_1634272107467/work/third_party/gloo/gloo/transport/tcp/pair.cc:598] Connection closed by peer [10.3.59.5]:24219
    dist._broadcast_coalesced(
RuntimeError: [/opt/conda/conda-bld/pytorch_1634272107467/work/third_party/gloo/gloo/transport/tcp/pair.cc:598] Connection closed by peer [10.3.59.5]:49841
Traceback (most recent call last):
  File "/sciclone/home20/hmbaier/tm/run.py", line 242, in <module>
    main(int(os.environ["RANK"]), int(os.environ['WORLD_SIZE']), model_group)
  File "/sciclone/home20/hmbaier/.conda/envs/dhsrl4/lib/python3.9/site-packages/torch/distributed/elastic/multiprocessing/errors/__init__.py", line 345, in wrapper
    return f(*args, **kwargs)
  File "/sciclone/home20/hmbaier/tm/run.py", line 100, in main
Traceback (most recent call last):
  File "/sciclone/home20/hmbaier/tm/run.py", line 242, in <module>
    main(int(os.environ["RANK"]), int(os.environ['WORLD_SIZE']), model_group)
  File "/sciclone/home20/hmbaier/.conda/envs/dhsrl4/lib/python3.9/site-packages/torch/distributed/elastic/multiprocessing/errors/__init__.py", line 345, in wrapper
    ddp_model = DDP(model, process_group = model_group)
  File "/sciclone/home20/hmbaier/.conda/envs/dhsrl4/lib/python3.9/site-packages/torch/nn/parallel/distributed.py", line 580, in __init__
    return f(*args, **kwargs)
  File "/sciclone/home20/hmbaier/tm/run.py", line 100, in main
    ddp_model = DDP(model, process_group = model_group)
  File "/sciclone/home20/hmbaier/.conda/envs/dhsrl4/lib/python3.9/site-packages/torch/nn/parallel/distributed.py", line 580, in __init__
    self._sync_params_and_buffers(authoritative_rank=0)
  File "/sciclone/home20/hmbaier/.conda/envs/dhsrl4/lib/python3.9/site-packages/torch/nn/parallel/distributed.py", line 597, in _sync_params_and_buffers
    self._sync_params_and_buffers(authoritative_rank=0)
  File "/sciclone/home20/hmbaier/.conda/envs/dhsrl4/lib/python3.9/site-packages/torch/nn/parallel/distributed.py", line 597, in _sync_params_and_buffers
    self._distributed_broadcast_coalesced(
  File "/sciclone/home20/hmbaier/.conda/envs/dhsrl4/lib/python3.9/site-packages/torch/nn/parallel/distributed.py", line 1334, in _distributed_broadcast_coalesced
    dist._broadcast_coalesced(
RuntimeError: [/opt/conda/conda-bld/pytorch_1634272107467/work/third_party/gloo/gloo/transport/tcp/pair.cc:598] Connection closed by peer [10.3.59.5]:25742
    self._distributed_broadcast_coalesced(
  File "/sciclone/home20/hmbaier/.conda/envs/dhsrl4/lib/python3.9/site-packages/torch/nn/parallel/distributed.py", line 1334, in _distributed_broadcast_coalesced
    dist._broadcast_coalesced(
RuntimeError: [/opt/conda/conda-bld/pytorch_1634272107467/work/third_party/gloo/gloo/transport/tcp/pair.cc:598] Connection closed by peer [10.3.59.5]:25510
Traceback (most recent call last):
  File "/sciclone/home20/hmbaier/tm/run.py", line 242, in <module>
    main(int(os.environ["RANK"]), int(os.environ['WORLD_SIZE']), model_group)
  File "/sciclone/home20/hmbaier/.conda/envs/dhsrl4/lib/python3.9/site-packages/torch/distributed/elastic/multiprocessing/errors/__init__.py", line 345, in wrapper
    return f(*args, **kwargs)
  File "/sciclone/home20/hmbaier/tm/run.py", line 100, in main
    ddp_model = DDP(model, process_group = model_group)
  File "/sciclone/home20/hmbaier/.conda/envs/dhsrl4/lib/python3.9/site-packages/torch/nn/parallel/distributed.py", line 580, in __init__
    self._sync_params_and_buffers(authoritative_rank=0)
  File "/sciclone/home20/hmbaier/.conda/envs/dhsrl4/lib/python3.9/site-packages/torch/nn/parallel/distributed.py", line 597, in _sync_params_and_buffers
    self._distributed_broadcast_coalesced(
  File "/sciclone/home20/hmbaier/.conda/envs/dhsrl4/lib/python3.9/site-packages/torch/nn/parallel/distributed.py", line 1334, in _distributed_broadcast_coalesced
    dist._broadcast_coalesced(
RuntimeError: [/opt/conda/conda-bld/pytorch_1634272107467/work/third_party/gloo/gloo/transport/tcp/pair.cc:598] Connection closed by peer [10.3.59.1]:2708
Traceback (most recent call last):
  File "/sciclone/home20/hmbaier/tm/run.py", line 242, in <module>
    main(int(os.environ["RANK"]), int(os.environ['WORLD_SIZE']), model_group)
  File "/sciclone/home20/hmbaier/.conda/envs/dhsrl4/lib/python3.9/site-packages/torch/distributed/elastic/multiprocessing/errors/__init__.py", line 345, in wrapper
    return f(*args, **kwargs)
  File "/sciclone/home20/hmbaier/tm/run.py", line 100, in main
    ddp_model = DDP(model, process_group = model_group)
  File "/sciclone/home20/hmbaier/.conda/envs/dhsrl4/lib/python3.9/site-packages/torch/nn/parallel/distributed.py", line 580, in __init__
    self._sync_params_and_buffers(authoritative_rank=0)
  File "/sciclone/home20/hmbaier/.conda/envs/dhsrl4/lib/python3.9/site-packages/torch/nn/parallel/distributed.py", line 597, in _sync_params_and_buffers
    self._distributed_broadcast_coalesced(
  File "/sciclone/home20/hmbaier/.conda/envs/dhsrl4/lib/python3.9/site-packages/torch/nn/parallel/distributed.py", line 1334, in _distributed_broadcast_coalesced
    dist._broadcast_coalesced(
RuntimeError: [/opt/conda/conda-bld/pytorch_1634272107467/work/third_party/gloo/gloo/transport/tcp/pair.cc:598] Connection closed by peer [10.3.59.1]:15530
Traceback (most recent call last):
  File "/sciclone/home20/hmbaier/tm/run.py", line 242, in <module>
    main(int(os.environ["RANK"]), int(os.environ['WORLD_SIZE']), model_group)
  File "/sciclone/home20/hmbaier/.conda/envs/dhsrl4/lib/python3.9/site-packages/torch/distributed/elastic/multiprocessing/errors/__init__.py", line 345, in wrapper
    return f(*args, **kwargs)
  File "/sciclone/home20/hmbaier/tm/run.py", line 100, in main
    ddp_model = DDP(model, process_group = model_group)
  File "/sciclone/home20/hmbaier/.conda/envs/dhsrl4/lib/python3.9/site-packages/torch/nn/parallel/distributed.py", line 580, in __init__
    self._sync_params_and_buffers(authoritative_rank=0)
  File "/sciclone/home20/hmbaier/.conda/envs/dhsrl4/lib/python3.9/site-packages/torch/nn/parallel/distributed.py", line 597, in _sync_params_and_buffers
    self._distributed_broadcast_coalesced(
  File "/sciclone/home20/hmbaier/.conda/envs/dhsrl4/lib/python3.9/site-packages/torch/nn/parallel/distributed.py", line 1334, in _distributed_broadcast_coalesced
    dist._broadcast_coalesced(
RuntimeError: [/opt/conda/conda-bld/pytorch_1634272107467/work/third_party/gloo/gloo/transport/tcp/pair.cc:598] Connection closed by peer [10.3.59.1]:32667
Traceback (most recent call last):
  File "/sciclone/home20/hmbaier/tm/run.py", line 242, in <module>
    main(int(os.environ["RANK"]), int(os.environ['WORLD_SIZE']), model_group)
  File "/sciclone/home20/hmbaier/.conda/envs/dhsrl4/lib/python3.9/site-packages/torch/distributed/elastic/multiprocessing/errors/__init__.py", line 345, in wrapper
    return f(*args, **kwargs)
  File "/sciclone/home20/hmbaier/tm/run.py", line 100, in main
    ddp_model = DDP(model, process_group = model_group)
  File "/sciclone/home20/hmbaier/.conda/envs/dhsrl4/lib/python3.9/site-packages/torch/nn/parallel/distributed.py", line 580, in __init__
    self._sync_params_and_buffers(authoritative_rank=0)
  File "/sciclone/home20/hmbaier/.conda/envs/dhsrl4/lib/python3.9/site-packages/torch/nn/parallel/distributed.py", line 597, in _sync_params_and_buffers
    self._distributed_broadcast_coalesced(
  File "/sciclone/home20/hmbaier/.conda/envs/dhsrl4/lib/python3.9/site-packages/torch/nn/parallel/distributed.py", line 1334, in _distributed_broadcast_coalesced
    dist._broadcast_coalesced(
RuntimeError: [/opt/conda/conda-bld/pytorch_1634272107467/work/third_party/gloo/gloo/transport/tcp/pair.cc:598] Connection closed by peer [10.3.59.1]:11667
Traceback (most recent call last):
  File "/sciclone/home20/hmbaier/tm/run.py", line 242, in <module>
    main(int(os.environ["RANK"]), int(os.environ['WORLD_SIZE']), model_group)
  File "/sciclone/home20/hmbaier/.conda/envs/dhsrl4/lib/python3.9/site-packages/torch/distributed/elastic/multiprocessing/errors/__init__.py", line 345, in wrapper
    return f(*args, **kwargs)
  File "/sciclone/home20/hmbaier/tm/run.py", line 100, in main
    ddp_model = DDP(model, process_group = model_group)
  File "/sciclone/home20/hmbaier/.conda/envs/dhsrl4/lib/python3.9/site-packages/torch/nn/parallel/distributed.py", line 580, in __init__
    self._sync_params_and_buffers(authoritative_rank=0)
  File "/sciclone/home20/hmbaier/.conda/envs/dhsrl4/lib/python3.9/site-packages/torch/nn/parallel/distributed.py", line 597, in _sync_params_and_buffers
    self._distributed_broadcast_coalesced(
  File "/sciclone/home20/hmbaier/.conda/envs/dhsrl4/lib/python3.9/site-packages/torch/nn/parallel/distributed.py", line 1334, in _distributed_broadcast_coalesced
    dist._broadcast_coalesced(
RuntimeError: [/opt/conda/conda-bld/pytorch_1634272107467/work/third_party/gloo/gloo/transport/tcp/pair.cc:598] Connection closed by peer [10.3.59.1]:13968
Traceback (most recent call last):
  File "/sciclone/home20/hmbaier/tm/run.py", line 242, in <module>
    Traceback (most recent call last):
main(int(os.environ["RANK"]), int(os.environ['WORLD_SIZE']), model_group)
  File "/sciclone/home20/hmbaier/tm/run.py", line 242, in <module>
  File "/sciclone/home20/hmbaier/.conda/envs/dhsrl4/lib/python3.9/site-packages/torch/distributed/elastic/multiprocessing/errors/__init__.py", line 345, in wrapper
        return f(*args, **kwargs)main(int(os.environ["RANK"]), int(os.environ['WORLD_SIZE']), model_group)

  File "/sciclone/home20/hmbaier/tm/run.py", line 122, in main
  File "/sciclone/home20/hmbaier/.conda/envs/dhsrl4/lib/python3.9/site-packages/torch/distributed/elastic/multiprocessing/errors/__init__.py", line 345, in wrapper
    output = ddp_model(input)
  File "/sciclone/home20/hmbaier/.conda/envs/dhsrl4/lib/python3.9/site-packages/torch/nn/modules/module.py", line 1102, in _call_impl
    return f(*args, **kwargs)
  File "/sciclone/home20/hmbaier/tm/run.py", line 122, in main
    output = ddp_model(input)
  File "/sciclone/home20/hmbaier/.conda/envs/dhsrl4/lib/python3.9/site-packages/torch/nn/modules/module.py", line 1102, in _call_impl
    return forward_call(*input, **kwargs)
  File "/sciclone/home20/hmbaier/.conda/envs/dhsrl4/lib/python3.9/site-packages/torch/nn/parallel/distributed.py", line 878, in forward
    return forward_call(*input, **kwargs)
      File "/sciclone/home20/hmbaier/.conda/envs/dhsrl4/lib/python3.9/site-packages/torch/nn/parallel/distributed.py", line 878, in forward
self._sync_params()
  File "/sciclone/home20/hmbaier/.conda/envs/dhsrl4/lib/python3.9/site-packages/torch/nn/parallel/distributed.py", line 1379, in _sync_params
    self._sync_params()
  File "/sciclone/home20/hmbaier/.conda/envs/dhsrl4/lib/python3.9/site-packages/torch/nn/parallel/distributed.py", line 1379, in _sync_params
Traceback (most recent call last):
  File "/sciclone/home20/hmbaier/tm/run.py", line 242, in <module>
    self._distributed_broadcast_coalesced(
  File "/sciclone/home20/hmbaier/.conda/envs/dhsrl4/lib/python3.9/site-packages/torch/nn/parallel/distributed.py", line 1334, in _distributed_broadcast_coalesced
    main(int(os.environ["RANK"]), int(os.environ['WORLD_SIZE']), model_group)
  File "/sciclone/home20/hmbaier/.conda/envs/dhsrl4/lib/python3.9/site-packages/torch/distributed/elastic/multiprocessing/errors/__init__.py", line 345, in wrapper
    dist._broadcast_coalesced(
RuntimeError: [/opt/conda/conda-bld/pytorch_1634272107467/work/third_party/gloo/gloo/transport/tcp/pair.cc:598] Connection closed by peer [10.3.59.1]:10414    
self._distributed_broadcast_coalesced(
  File "/sciclone/home20/hmbaier/.conda/envs/dhsrl4/lib/python3.9/site-packages/torch/nn/parallel/distributed.py", line 1334, in _distributed_broadcast_coalesced
    return f(*args, **kwargs)
  File "/sciclone/home20/hmbaier/tm/run.py", line 122, in main
    output = ddp_model(input)
  File "/sciclone/home20/hmbaier/.conda/envs/dhsrl4/lib/python3.9/site-packages/torch/nn/modules/module.py", line 1102, in _call_impl
    dist._broadcast_coalesced(
RuntimeError: [/opt/conda/conda-bld/pytorch_1634272107467/work/third_party/gloo/gloo/transport/tcp/pair.cc:598] Connection closed by peer [10.3.59.1]:32917
    return forward_call(*input, **kwargs)
  File "/sciclone/home20/hmbaier/.conda/envs/dhsrl4/lib/python3.9/site-packages/torch/nn/parallel/distributed.py", line 878, in forward
    self._sync_params()
  File "/sciclone/home20/hmbaier/.conda/envs/dhsrl4/lib/python3.9/site-packages/torch/nn/parallel/distributed.py", line 1379, in _sync_params
    self._distributed_broadcast_coalesced(
  File "/sciclone/home20/hmbaier/.conda/envs/dhsrl4/lib/python3.9/site-packages/torch/nn/parallel/distributed.py", line 1334, in _distributed_broadcast_coalesced
    dist._broadcast_coalesced(
RuntimeError: [/opt/conda/conda-bld/pytorch_1634272107467/work/third_party/gloo/gloo/transport/tcp/pair.cc:598] Connection closed by peer [10.3.59.1]:9961
Traceback (most recent call last):
  File "/sciclone/home20/hmbaier/tm/run.py", line 242, in <module>
    main(int(os.environ["RANK"]), int(os.environ['WORLD_SIZE']), model_group)
  File "/sciclone/home20/hmbaier/.conda/envs/dhsrl4/lib/python3.9/site-packages/torch/distributed/elastic/multiprocessing/errors/__init__.py", line 345, in wrapper
    return f(*args, **kwargs)
  File "/sciclone/home20/hmbaier/tm/run.py", line 122, in main
    output = ddp_model(input)
  File "/sciclone/home20/hmbaier/.conda/envs/dhsrl4/lib/python3.9/site-packages/torch/nn/modules/module.py", line 1102, in _call_impl
    return forward_call(*input, **kwargs)
  File "/sciclone/home20/hmbaier/.conda/envs/dhsrl4/lib/python3.9/site-packages/torch/nn/parallel/distributed.py", line 878, in forward
    self._sync_params()
  File "/sciclone/home20/hmbaier/.conda/envs/dhsrl4/lib/python3.9/site-packages/torch/nn/parallel/distributed.py", line 1379, in _sync_params
Traceback (most recent call last):
  File "/sciclone/home20/hmbaier/tm/run.py", line 242, in <module>
    main(int(os.environ["RANK"]), int(os.environ['WORLD_SIZE']), model_group)
  File "/sciclone/home20/hmbaier/.conda/envs/dhsrl4/lib/python3.9/site-packages/torch/distributed/elastic/multiprocessing/errors/__init__.py", line 345, in wrapper
        return f(*args, **kwargs)self._distributed_broadcast_coalesced(

  File "/sciclone/home20/hmbaier/tm/run.py", line 100, in main
  File "/sciclone/home20/hmbaier/.conda/envs/dhsrl4/lib/python3.9/site-packages/torch/nn/parallel/distributed.py", line 1334, in _distributed_broadcast_coalesced
    ddp_model = DDP(model, process_group = model_group)
  File "/sciclone/home20/hmbaier/.conda/envs/dhsrl4/lib/python3.9/site-packages/torch/nn/parallel/distributed.py", line 580, in __init__
    self._sync_params_and_buffers(authoritative_rank=0)
  File "/sciclone/home20/hmbaier/.conda/envs/dhsrl4/lib/python3.9/site-packages/torch/nn/parallel/distributed.py", line 597, in _sync_params_and_buffers
    dist._broadcast_coalesced(
RuntimeError: [/opt/conda/conda-bld/pytorch_1634272107467/work/third_party/gloo/gloo/transport/tcp/pair.cc:598] Connection closed by peer [10.3.59.1]:28551
    self._distributed_broadcast_coalesced(
  File "/sciclone/home20/hmbaier/.conda/envs/dhsrl4/lib/python3.9/site-packages/torch/nn/parallel/distributed.py", line 1334, in _distributed_broadcast_coalesced
    dist._broadcast_coalesced(
RuntimeError: [/opt/conda/conda-bld/pytorch_1634272107467/work/third_party/gloo/gloo/transport/tcp/pair.cc:598] Connection closed by peer [10.3.59.1]:23684
Traceback (most recent call last):
  File "/sciclone/home20/hmbaier/tm/run.py", line 242, in <module>
    main(int(os.environ["RANK"]), int(os.environ['WORLD_SIZE']), model_group)
  File "/sciclone/home20/hmbaier/.conda/envs/dhsrl4/lib/python3.9/site-packages/torch/distributed/elastic/multiprocessing/errors/__init__.py", line 345, in wrapper
    return f(*args, **kwargs)
  File "/sciclone/home20/hmbaier/tm/run.py", line 100, in main
    ddp_model = DDP(model, process_group = model_group)
  File "/sciclone/home20/hmbaier/.conda/envs/dhsrl4/lib/python3.9/site-packages/torch/nn/parallel/distributed.py", line 580, in __init__
    self._sync_params_and_buffers(authoritative_rank=0)
  File "/sciclone/home20/hmbaier/.conda/envs/dhsrl4/lib/python3.9/site-packages/torch/nn/parallel/distributed.py", line 597, in _sync_params_and_buffers
    self._distributed_broadcast_coalesced(
  File "/sciclone/home20/hmbaier/.conda/envs/dhsrl4/lib/python3.9/site-packages/torch/nn/parallel/distributed.py", line 1334, in _distributed_broadcast_coalesced
    dist._broadcast_coalesced(
RuntimeError: [/opt/conda/conda-bld/pytorch_1634272107467/work/third_party/gloo/gloo/transport/tcp/pair.cc:598] Connection closed by peer [10.3.59.1]:13522
Traceback (most recent call last):
  File "/sciclone/home20/hmbaier/tm/run.py", line 242, in <module>
    main(int(os.environ["RANK"]), int(os.environ['WORLD_SIZE']), model_group)
  File "/sciclone/home20/hmbaier/.conda/envs/dhsrl4/lib/python3.9/site-packages/torch/distributed/elastic/multiprocessing/errors/__init__.py", line 345, in wrapper
    return f(*args, **kwargs)
  File "/sciclone/home20/hmbaier/tm/run.py", line 100, in main
    ddp_model = DDP(model, process_group = model_group)
  File "/sciclone/home20/hmbaier/.conda/envs/dhsrl4/lib/python3.9/site-packages/torch/nn/parallel/distributed.py", line 580, in __init__
    self._sync_params_and_buffers(authoritative_rank=0)
  File "/sciclone/home20/hmbaier/.conda/envs/dhsrl4/lib/python3.9/site-packages/torch/nn/parallel/distributed.py", line 597, in _sync_params_and_buffers
    self._distributed_broadcast_coalesced(
  File "/sciclone/home20/hmbaier/.conda/envs/dhsrl4/lib/python3.9/site-packages/torch/nn/parallel/distributed.py", line 1334, in _distributed_broadcast_coalesced
    dist._broadcast_coalesced(
RuntimeError: [/opt/conda/conda-bld/pytorch_1634272107467/work/third_party/gloo/gloo/transport/tcp/pair.cc:598] Connection closed by peer [10.3.59.1]:63652
Traceback (most recent call last):
  File "/sciclone/home20/hmbaier/tm/run.py", line 242, in <module>
    main(int(os.environ["RANK"]), int(os.environ['WORLD_SIZE']), model_group)
  File "/sciclone/home20/hmbaier/.conda/envs/dhsrl4/lib/python3.9/site-packages/torch/distributed/elastic/multiprocessing/errors/__init__.py", line 345, in wrapper
    return f(*args, **kwargs)
  File "/sciclone/home20/hmbaier/tm/run.py", line 122, in main
    output = ddp_model(input)
  File "/sciclone/home20/hmbaier/.conda/envs/dhsrl4/lib/python3.9/site-packages/torch/nn/modules/module.py", line 1102, in _call_impl
    return forward_call(*input, **kwargs)
  File "/sciclone/home20/hmbaier/.conda/envs/dhsrl4/lib/python3.9/site-packages/torch/nn/parallel/distributed.py", line 878, in forward
    self._sync_params()
  File "/sciclone/home20/hmbaier/.conda/envs/dhsrl4/lib/python3.9/site-packages/torch/nn/parallel/distributed.py", line 1379, in _sync_params
    self._distributed_broadcast_coalesced(
  File "/sciclone/home20/hmbaier/.conda/envs/dhsrl4/lib/python3.9/site-packages/torch/nn/parallel/distributed.py", line 1334, in _distributed_broadcast_coalesced
    dist._broadcast_coalesced(
RuntimeError: [/opt/conda/conda-bld/pytorch_1634272107467/work/third_party/gloo/gloo/transport/tcp/pair.cc:598] Connection closed by peer [10.3.59.1]:21659
Traceback (most recent call last):
  File "/sciclone/home20/hmbaier/tm/run.py", line 242, in <module>
    main(int(os.environ["RANK"]), int(os.environ['WORLD_SIZE']), model_group)
  File "/sciclone/home20/hmbaier/.conda/envs/dhsrl4/lib/python3.9/site-packages/torch/distributed/elastic/multiprocessing/errors/__init__.py", line 345, in wrapper
    return f(*args, **kwargs)
  File "/sciclone/home20/hmbaier/tm/run.py", line 122, in main
    output = ddp_model(input)
  File "/sciclone/home20/hmbaier/.conda/envs/dhsrl4/lib/python3.9/site-packages/torch/nn/modules/module.py", line 1102, in _call_impl
    return forward_call(*input, **kwargs)
  File "/sciclone/home20/hmbaier/.conda/envs/dhsrl4/lib/python3.9/site-packages/torch/nn/parallel/distributed.py", line 878, in forward
    self._sync_params()
  File "/sciclone/home20/hmbaier/.conda/envs/dhsrl4/lib/python3.9/site-packages/torch/nn/parallel/distributed.py", line 1379, in _sync_params
    self._distributed_broadcast_coalesced(
  File "/sciclone/home20/hmbaier/.conda/envs/dhsrl4/lib/python3.9/site-packages/torch/nn/parallel/distributed.py", line 1334, in _distributed_broadcast_coalesced
    dist._broadcast_coalesced(
RuntimeError: [/opt/conda/conda-bld/pytorch_1634272107467/work/third_party/gloo/gloo/transport/tcp/pair.cc:598] Connection closed by peer [10.3.59.1]:3732
Traceback (most recent call last):
  File "/sciclone/home20/hmbaier/tm/run.py", line 242, in <module>
    main(int(os.environ["RANK"]), int(os.environ['WORLD_SIZE']), model_group)
  File "/sciclone/home20/hmbaier/.conda/envs/dhsrl4/lib/python3.9/site-packages/torch/distributed/elastic/multiprocessing/errors/__init__.py", line 345, in wrapper
    return f(*args, **kwargs)
  File "/sciclone/home20/hmbaier/tm/run.py", line 100, in main
    ddp_model = DDP(model, process_group = model_group)
  File "/sciclone/home20/hmbaier/.conda/envs/dhsrl4/lib/python3.9/site-packages/torch/nn/parallel/distributed.py", line 580, in __init__
    self._sync_params_and_buffers(authoritative_rank=0)
  File "/sciclone/home20/hmbaier/.conda/envs/dhsrl4/lib/python3.9/site-packages/torch/nn/parallel/distributed.py", line 597, in _sync_params_and_buffers
    self._distributed_broadcast_coalesced(
  File "/sciclone/home20/hmbaier/.conda/envs/dhsrl4/lib/python3.9/site-packages/torch/nn/parallel/distributed.py", line 1334, in _distributed_broadcast_coalesced
    dist._broadcast_coalesced(
RuntimeError: [/opt/conda/conda-bld/pytorch_1634272107467/work/third_party/gloo/gloo/transport/tcp/pair.cc:598] Connection closed by peer [10.3.59.1]:6555
Traceback (most recent call last):
  File "/sciclone/home20/hmbaier/tm/run.py", line 242, in <module>
    main(int(os.environ["RANK"]), int(os.environ['WORLD_SIZE']), model_group)
  File "/sciclone/home20/hmbaier/.conda/envs/dhsrl4/lib/python3.9/site-packages/torch/distributed/elastic/multiprocessing/errors/__init__.py", line 345, in wrapper
    return f(*args, **kwargs)
  File "/sciclone/home20/hmbaier/tm/run.py", line 122, in main
    output = ddp_model(input)
  File "/sciclone/home20/hmbaier/.conda/envs/dhsrl4/lib/python3.9/site-packages/torch/nn/modules/module.py", line 1102, in _call_impl
    return forward_call(*input, **kwargs)
  File "/sciclone/home20/hmbaier/.conda/envs/dhsrl4/lib/python3.9/site-packages/torch/nn/parallel/distributed.py", line 878, in forward
    self._sync_params()
  File "/sciclone/home20/hmbaier/.conda/envs/dhsrl4/lib/python3.9/site-packages/torch/nn/parallel/distributed.py", line 1379, in _sync_params
    self._distributed_broadcast_coalesced(
  File "/sciclone/home20/hmbaier/.conda/envs/dhsrl4/lib/python3.9/site-packages/torch/nn/parallel/distributed.py", line 1334, in _distributed_broadcast_coalesced
    dist._broadcast_coalesced(
RuntimeError: [/opt/conda/conda-bld/pytorch_1634272107467/work/third_party/gloo/gloo/transport/tcp/pair.cc:598] Connection closed by peer [10.3.59.1]:48282
WARNING:torch.distributed.elastic.multiprocessing.api:Sending process 177590 closing signal SIGTERM
WARNING:torch.distributed.elastic.multiprocessing.api:Sending process 177598 closing signal SIGTERM
WARNING:torch.distributed.elastic.multiprocessing.api:Sending process 177608 closing signal SIGTERM
WARNING:torch.distributed.elastic.multiprocessing.api:Sending process 177611 closing signal SIGTERM
WARNING:torch.distributed.elastic.multiprocessing.api:Sending process 177612 closing signal SIGTERM
ERROR:torch.distributed.elastic.multiprocessing.api:failed (exitcode: 1) local_rank: 1 (pid: 177580) of binary: /sciclone/home20/hmbaier/.conda/envs/dhsrl4/bin/python
ERROR:torch.distributed.elastic.agent.server.api:Error waiting on exit barrier. Elapsed: 4.240260124206543 seconds
Traceback (most recent call last):
  File "/sciclone/home20/hmbaier/.conda/envs/dhsrl4/lib/python3.9/site-packages/torch/distributed/elastic/agent/server/api.py", line 899, in _exit_barrier
    store_util.barrier(
  File "/sciclone/home20/hmbaier/.conda/envs/dhsrl4/lib/python3.9/site-packages/torch/distributed/elastic/utils/store.py", line 67, in barrier
    synchronize(store, data, rank, world_size, key_prefix, barrier_timeout)
  File "/sciclone/home20/hmbaier/.conda/envs/dhsrl4/lib/python3.9/site-packages/torch/distributed/elastic/utils/store.py", line 53, in synchronize
    agent_data = get_all(store, key_prefix, world_size)
  File "/sciclone/home20/hmbaier/.conda/envs/dhsrl4/lib/python3.9/site-packages/torch/distributed/elastic/utils/store.py", line 31, in get_all
    data = store.get(f"{prefix}{idx}")
RuntimeError: Connection reset by peer
WARNING:torch.distributed.elastic.rendezvous.dynamic_rendezvous:The node 'mlt001.sciclone.wm.edu_177570_0' has failed to send a keep-alive heartbeat to the rendezvous '790876' due to an error of type RendezvousConnectionError.
WARNING:torch.distributed.elastic.rendezvous.dynamic_rendezvous:The node 'mlt001.sciclone.wm.edu_177570_0' has failed to shutdown the rendezvous '790876' due to an error of type RendezvousConnectionError.
ERROR:torch.distributed.elastic.multiprocessing.errors.error_handler:no error file defined for parent, to copy child error file (/local/scr/hmbaier/TMPDIR/torchelastic_kpuq9f13/790876_z6o4ujg5/attempt_0/1/error.json)
Traceback (most recent call last):
  File "/sciclone/home20/hmbaier/.conda/envs/dhsrl4/bin/torchrun", line 33, in <module>
    sys.exit(load_entry_point('torch==1.10.0', 'console_scripts', 'torchrun')())
  File "/sciclone/home20/hmbaier/.conda/envs/dhsrl4/lib/python3.9/site-packages/torch/distributed/elastic/multiprocessing/errors/__init__.py", line 345, in wrapper
    return f(*args, **kwargs)
  File "/sciclone/home20/hmbaier/.conda/envs/dhsrl4/lib/python3.9/site-packages/torch/distributed/run.py", line 719, in main
    run(args)
  File "/sciclone/home20/hmbaier/.conda/envs/dhsrl4/lib/python3.9/site-packages/torch/distributed/run.py", line 710, in run
    elastic_launch(
  File "/sciclone/home20/hmbaier/.conda/envs/dhsrl4/lib/python3.9/site-packages/torch/distributed/launcher/api.py", line 131, in __call__
    return launch_agent(self._config, self._entrypoint, list(args))
  File "/sciclone/home20/hmbaier/.conda/envs/dhsrl4/lib/python3.9/site-packages/torch/distributed/launcher/api.py", line 259, in launch_agent
    raise ChildFailedError(
torch.distributed.elastic.multiprocessing.errors.ChildFailedError: 
============================================================
/sciclone/home20/hmbaier/tm/run.py FAILED
------------------------------------------------------------
Failures:
[1]:
  time      : 2022-03-10_15:54:47
  host      : mlt001.sciclone.wm.edu
  rank      : 2 (local_rank: 2)
  exitcode  : 1 (pid: 177581)
  error_file: /local/scr/hmbaier/TMPDIR/torchelastic_kpuq9f13/790876_z6o4ujg5/attempt_0/2/error.json
  traceback : Traceback (most recent call last):
    File "/sciclone/home20/hmbaier/.conda/envs/dhsrl4/lib/python3.9/site-packages/torch/distributed/elastic/multiprocessing/errors/__init__.py", line 345, in wrapper
      return f(*args, **kwargs)
    File "/sciclone/home20/hmbaier/tm/run.py", line 100, in main
      ddp_model = DDP(model, process_group = model_group)
    File "/sciclone/home20/hmbaier/.conda/envs/dhsrl4/lib/python3.9/site-packages/torch/nn/parallel/distributed.py", line 578, in __init__
      dist._verify_model_across_ranks(self.process_group, parameters)
  RuntimeError: [/opt/conda/conda-bld/pytorch_1634272107467/work/third_party/gloo/gloo/transport/tcp/pair.cc:598] Connection closed by peer [10.3.59.5]:63145
  
[2]:
  time      : 2022-03-10_15:54:47
  host      : mlt001.sciclone.wm.edu
  rank      : 3 (local_rank: 3)
  exitcode  : 1 (pid: 177582)
  error_file: /local/scr/hmbaier/TMPDIR/torchelastic_kpuq9f13/790876_z6o4ujg5/attempt_0/3/error.json
  traceback : Traceback (most recent call last):
    File "/sciclone/home20/hmbaier/.conda/envs/dhsrl4/lib/python3.9/site-packages/torch/distributed/elastic/multiprocessing/errors/__init__.py", line 345, in wrapper
      return f(*args, **kwargs)
    File "/sciclone/home20/hmbaier/tm/run.py", line 100, in main
      ddp_model = DDP(model, process_group = model_group)
    File "/sciclone/home20/hmbaier/.conda/envs/dhsrl4/lib/python3.9/site-packages/torch/nn/parallel/distributed.py", line 580, in __init__
      self._sync_params_and_buffers(authoritative_rank=0)
    File "/sciclone/home20/hmbaier/.conda/envs/dhsrl4/lib/python3.9/site-packages/torch/nn/parallel/distributed.py", line 597, in _sync_params_and_buffers
      self._distributed_broadcast_coalesced(
    File "/sciclone/home20/hmbaier/.conda/envs/dhsrl4/lib/python3.9/site-packages/torch/nn/parallel/distributed.py", line 1334, in _distributed_broadcast_coalesced
      dist._broadcast_coalesced(
  RuntimeError: [/opt/conda/conda-bld/pytorch_1634272107467/work/third_party/gloo/gloo/transport/tcp/pair.cc:598] Connection closed by peer [10.3.59.5]:32921
  
[3]:
  time      : 2022-03-10_15:54:47
  host      : mlt001.sciclone.wm.edu
  rank      : 4 (local_rank: 4)
  exitcode  : 1 (pid: 177583)
  error_file: /local/scr/hmbaier/TMPDIR/torchelastic_kpuq9f13/790876_z6o4ujg5/attempt_0/4/error.json
  traceback : Traceback (most recent call last):
    File "/sciclone/home20/hmbaier/.conda/envs/dhsrl4/lib/python3.9/site-packages/torch/distributed/elastic/multiprocessing/errors/__init__.py", line 345, in wrapper
      return f(*args, **kwargs)
    File "/sciclone/home20/hmbaier/tm/run.py", line 100, in main
      ddp_model = DDP(model, process_group = model_group)
    File "/sciclone/home20/hmbaier/.conda/envs/dhsrl4/lib/python3.9/site-packages/torch/nn/parallel/distributed.py", line 578, in __init__
      dist._verify_model_across_ranks(self.process_group, parameters)
  RuntimeError: [/opt/conda/conda-bld/pytorch_1634272107467/work/third_party/gloo/gloo/transport/tcp/pair.cc:598] Connection closed by peer [10.3.59.5]:43912
  
[4]:
  time      : 2022-03-10_15:54:47
  host      : mlt001.sciclone.wm.edu
  rank      : 5 (local_rank: 5)
  exitcode  : 1 (pid: 177584)
  error_file: /local/scr/hmbaier/TMPDIR/torchelastic_kpuq9f13/790876_z6o4ujg5/attempt_0/5/error.json
  traceback : Traceback (most recent call last):
    File "/sciclone/home20/hmbaier/.conda/envs/dhsrl4/lib/python3.9/site-packages/torch/distributed/elastic/multiprocessing/errors/__init__.py", line 345, in wrapper
      return f(*args, **kwargs)
    File "/sciclone/home20/hmbaier/tm/run.py", line 100, in main
      ddp_model = DDP(model, process_group = model_group)
    File "/sciclone/home20/hmbaier/.conda/envs/dhsrl4/lib/python3.9/site-packages/torch/nn/parallel/distributed.py", line 580, in __init__
      self._sync_params_and_buffers(authoritative_rank=0)
    File "/sciclone/home20/hmbaier/.conda/envs/dhsrl4/lib/python3.9/site-packages/torch/nn/parallel/distributed.py", line 597, in _sync_params_and_buffers
      self._distributed_broadcast_coalesced(
    File "/sciclone/home20/hmbaier/.conda/envs/dhsrl4/lib/python3.9/site-packages/torch/nn/parallel/distributed.py", line 1334, in _distributed_broadcast_coalesced
      dist._broadcast_coalesced(
  RuntimeError: [/opt/conda/conda-bld/pytorch_1634272107467/work/third_party/gloo/gloo/transport/tcp/pair.cc:598] Connection closed by peer [10.3.59.5]:7059
  
[5]:
  time      : 2022-03-10_15:54:47
  host      : mlt001.sciclone.wm.edu
  rank      : 6 (local_rank: 6)
  exitcode  : 1 (pid: 177585)
  error_file: /local/scr/hmbaier/TMPDIR/torchelastic_kpuq9f13/790876_z6o4ujg5/attempt_0/6/error.json
  traceback : Traceback (most recent call last):
    File "/sciclone/home20/hmbaier/.conda/envs/dhsrl4/lib/python3.9/site-packages/torch/distributed/elastic/multiprocessing/errors/__init__.py", line 345, in wrapper
      return f(*args, **kwargs)
    File "/sciclone/home20/hmbaier/tm/run.py", line 100, in main
      ddp_model = DDP(model, process_group = model_group)
    File "/sciclone/home20/hmbaier/.conda/envs/dhsrl4/lib/python3.9/site-packages/torch/nn/parallel/distributed.py", line 578, in __init__
      dist._verify_model_across_ranks(self.process_group, parameters)
  RuntimeError: [/opt/conda/conda-bld/pytorch_1634272107467/work/third_party/gloo/gloo/transport/tcp/pair.cc:598] Connection closed by peer [10.3.59.5]:56492
  
[6]:
  time      : 2022-03-10_15:54:47
  host      : mlt001.sciclone.wm.edu
  rank      : 7 (local_rank: 7)
  exitcode  : 1 (pid: 177586)
  error_file: /local/scr/hmbaier/TMPDIR/torchelastic_kpuq9f13/790876_z6o4ujg5/attempt_0/7/error.json
  traceback : Traceback (most recent call last):
    File "/sciclone/home20/hmbaier/.conda/envs/dhsrl4/lib/python3.9/site-packages/torch/distributed/elastic/multiprocessing/errors/__init__.py", line 345, in wrapper
      return f(*args, **kwargs)
    File "/sciclone/home20/hmbaier/tm/run.py", line 100, in main
      ddp_model = DDP(model, process_group = model_group)
    File "/sciclone/home20/hmbaier/.conda/envs/dhsrl4/lib/python3.9/site-packages/torch/nn/parallel/distributed.py", line 580, in __init__
      self._sync_params_and_buffers(authoritative_rank=0)
    File "/sciclone/home20/hmbaier/.conda/envs/dhsrl4/lib/python3.9/site-packages/torch/nn/parallel/distributed.py", line 597, in _sync_params_and_buffers
      self._distributed_broadcast_coalesced(
    File "/sciclone/home20/hmbaier/.conda/envs/dhsrl4/lib/python3.9/site-packages/torch/nn/parallel/distributed.py", line 1334, in _distributed_broadcast_coalesced
      dist._broadcast_coalesced(
  RuntimeError: [/opt/conda/conda-bld/pytorch_1634272107467/work/third_party/gloo/gloo/transport/tcp/pair.cc:598] Connection closed by peer [10.3.59.5]:25742
  
[7]:
  time      : 2022-03-10_15:54:47
  host      : mlt001.sciclone.wm.edu
  rank      : 8 (local_rank: 8)
  exitcode  : 1 (pid: 177587)
  error_file: /local/scr/hmbaier/TMPDIR/torchelastic_kpuq9f13/790876_z6o4ujg5/attempt_0/8/error.json
  traceback : Traceback (most recent call last):
    File "/sciclone/home20/hmbaier/.conda/envs/dhsrl4/lib/python3.9/site-packages/torch/distributed/elastic/multiprocessing/errors/__init__.py", line 345, in wrapper
      return f(*args, **kwargs)
    File "/sciclone/home20/hmbaier/tm/run.py", line 100, in main
      ddp_model = DDP(model, process_group = model_group)
    File "/sciclone/home20/hmbaier/.conda/envs/dhsrl4/lib/python3.9/site-packages/torch/nn/parallel/distributed.py", line 578, in __init__
      dist._verify_model_across_ranks(self.process_group, parameters)
  RuntimeError: [/opt/conda/conda-bld/pytorch_1634272107467/work/third_party/gloo/gloo/transport/tcp/pair.cc:598] Connection closed by peer [10.3.59.5]:62867
  
[8]:
  time      : 2022-03-10_15:54:47
  host      : mlt001.sciclone.wm.edu
  rank      : 9 (local_rank: 9)
  exitcode  : 1 (pid: 177588)
  error_file: /local/scr/hmbaier/TMPDIR/torchelastic_kpuq9f13/790876_z6o4ujg5/attempt_0/9/error.json
  traceback : Traceback (most recent call last):
    File "/sciclone/home20/hmbaier/.conda/envs/dhsrl4/lib/python3.9/site-packages/torch/distributed/elastic/multiprocessing/errors/__init__.py", line 345, in wrapper
      return f(*args, **kwargs)
    File "/sciclone/home20/hmbaier/tm/run.py", line 100, in main
      ddp_model = DDP(model, process_group = model_group)
    File "/sciclone/home20/hmbaier/.conda/envs/dhsrl4/lib/python3.9/site-packages/torch/nn/parallel/distributed.py", line 580, in __init__
      self._sync_params_and_buffers(authoritative_rank=0)
    File "/sciclone/home20/hmbaier/.conda/envs/dhsrl4/lib/python3.9/site-packages/torch/nn/parallel/distributed.py", line 597, in _sync_params_and_buffers
      self._distributed_broadcast_coalesced(
    File "/sciclone/home20/hmbaier/.conda/envs/dhsrl4/lib/python3.9/site-packages/torch/nn/parallel/distributed.py", line 1334, in _distributed_broadcast_coalesced
      dist._broadcast_coalesced(
  RuntimeError: [/opt/conda/conda-bld/pytorch_1634272107467/work/third_party/gloo/gloo/transport/tcp/pair.cc:598] Connection closed by peer [10.3.59.5]:49841
  
[9]:
  time      : 2022-03-10_15:54:47
  host      : mlt001.sciclone.wm.edu
  rank      : 10 (local_rank: 10)
  exitcode  : 1 (pid: 177589)
  error_file: /local/scr/hmbaier/TMPDIR/torchelastic_kpuq9f13/790876_z6o4ujg5/attempt_0/10/error.json
  traceback : Traceback (most recent call last):
    File "/sciclone/home20/hmbaier/.conda/envs/dhsrl4/lib/python3.9/site-packages/torch/distributed/elastic/multiprocessing/errors/__init__.py", line 345, in wrapper
      return f(*args, **kwargs)
    File "/sciclone/home20/hmbaier/tm/run.py", line 100, in main
      ddp_model = DDP(model, process_group = model_group)
    File "/sciclone/home20/hmbaier/.conda/envs/dhsrl4/lib/python3.9/site-packages/torch/nn/parallel/distributed.py", line 578, in __init__
      dist._verify_model_across_ranks(self.process_group, parameters)
  RuntimeError: [/opt/conda/conda-bld/pytorch_1634272107467/work/third_party/gloo/gloo/transport/tcp/pair.cc:598] Connection closed by peer [10.3.59.5]:65199
  
[10]:
  time      : 2022-03-10_15:54:47
  host      : mlt001.sciclone.wm.edu
  rank      : 12 (local_rank: 12)
  exitcode  : 1 (pid: 177591)
  error_file: /local/scr/hmbaier/TMPDIR/torchelastic_kpuq9f13/790876_z6o4ujg5/attempt_0/12/error.json
  traceback : Traceback (most recent call last):
    File "/sciclone/home20/hmbaier/.conda/envs/dhsrl4/lib/python3.9/site-packages/torch/distributed/elastic/multiprocessing/errors/__init__.py", line 345, in wrapper
      return f(*args, **kwargs)
    File "/sciclone/home20/hmbaier/tm/run.py", line 100, in main
      ddp_model = DDP(model, process_group = model_group)
    File "/sciclone/home20/hmbaier/.conda/envs/dhsrl4/lib/python3.9/site-packages/torch/nn/parallel/distributed.py", line 578, in __init__
      dist._verify_model_across_ranks(self.process_group, parameters)
  RuntimeError: [/opt/conda/conda-bld/pytorch_1634272107467/work/third_party/gloo/gloo/transport/tcp/pair.cc:598] Connection closed by peer [10.3.59.5]:11694
  
[11]:
  time      : 2022-03-10_15:54:47
  host      : mlt001.sciclone.wm.edu
  rank      : 13 (local_rank: 13)
  exitcode  : 1 (pid: 177592)
  error_file: /local/scr/hmbaier/TMPDIR/torchelastic_kpuq9f13/790876_z6o4ujg5/attempt_0/13/error.json
  traceback : Traceback (most recent call last):
    File "/sciclone/home20/hmbaier/.conda/envs/dhsrl4/lib/python3.9/site-packages/torch/distributed/elastic/multiprocessing/errors/__init__.py", line 345, in wrapper
      return f(*args, **kwargs)
    File "/sciclone/home20/hmbaier/tm/run.py", line 100, in main
      ddp_model = DDP(model, process_group = model_group)
    File "/sciclone/home20/hmbaier/.conda/envs/dhsrl4/lib/python3.9/site-packages/torch/nn/parallel/distributed.py", line 580, in __init__
      self._sync_params_and_buffers(authoritative_rank=0)
    File "/sciclone/home20/hmbaier/.conda/envs/dhsrl4/lib/python3.9/site-packages/torch/nn/parallel/distributed.py", line 597, in _sync_params_and_buffers
      self._distributed_broadcast_coalesced(
    File "/sciclone/home20/hmbaier/.conda/envs/dhsrl4/lib/python3.9/site-packages/torch/nn/parallel/distributed.py", line 1334, in _distributed_broadcast_coalesced
      dist._broadcast_coalesced(
  RuntimeError: [/opt/conda/conda-bld/pytorch_1634272107467/work/third_party/gloo/gloo/transport/tcp/pair.cc:598] Connection closed by peer [10.3.59.5]:24219
  
[12]:
  time      : 2022-03-10_15:54:49
  host      : mlt001.sciclone.wm.edu
  rank      : 14 (local_rank: 14)
  exitcode  : 1 (pid: 177593)
  error_file: /local/scr/hmbaier/TMPDIR/torchelastic_kpuq9f13/790876_z6o4ujg5/attempt_0/14/error.json
  traceback : Traceback (most recent call last):
    File "/sciclone/home20/hmbaier/.conda/envs/dhsrl4/lib/python3.9/site-packages/torch/distributed/elastic/multiprocessing/errors/__init__.py", line 345, in wrapper
      return f(*args, **kwargs)
    File "/sciclone/home20/hmbaier/tm/run.py", line 100, in main
      ddp_model = DDP(model, process_group = model_group)
    File "/sciclone/home20/hmbaier/.conda/envs/dhsrl4/lib/python3.9/site-packages/torch/nn/parallel/distributed.py", line 580, in __init__
      self._sync_params_and_buffers(authoritative_rank=0)
    File "/sciclone/home20/hmbaier/.conda/envs/dhsrl4/lib/python3.9/site-packages/torch/nn/parallel/distributed.py", line 597, in _sync_params_and_buffers
      self._distributed_broadcast_coalesced(
    File "/sciclone/home20/hmbaier/.conda/envs/dhsrl4/lib/python3.9/site-packages/torch/nn/parallel/distributed.py", line 1334, in _distributed_broadcast_coalesced
      dist._broadcast_coalesced(
  RuntimeError: [/opt/conda/conda-bld/pytorch_1634272107467/work/third_party/gloo/gloo/transport/tcp/pair.cc:598] Connection closed by peer [10.3.59.1]:2708
  
[13]:
  time      : 2022-03-10_15:54:49
  host      : mlt001.sciclone.wm.edu
  rank      : 15 (local_rank: 15)
  exitcode  : 1 (pid: 177594)
  error_file: /local/scr/hmbaier/TMPDIR/torchelastic_kpuq9f13/790876_z6o4ujg5/attempt_0/15/error.json
  traceback : Traceback (most recent call last):
    File "/sciclone/home20/hmbaier/.conda/envs/dhsrl4/lib/python3.9/site-packages/torch/distributed/elastic/multiprocessing/errors/__init__.py", line 345, in wrapper
      return f(*args, **kwargs)
    File "/sciclone/home20/hmbaier/tm/run.py", line 122, in main
      output = ddp_model(input)
    File "/sciclone/home20/hmbaier/.conda/envs/dhsrl4/lib/python3.9/site-packages/torch/nn/modules/module.py", line 1102, in _call_impl
      return forward_call(*input, **kwargs)
    File "/sciclone/home20/hmbaier/.conda/envs/dhsrl4/lib/python3.9/site-packages/torch/nn/parallel/distributed.py", line 878, in forward
      self._sync_params()
    File "/sciclone/home20/hmbaier/.conda/envs/dhsrl4/lib/python3.9/site-packages/torch/nn/parallel/distributed.py", line 1379, in _sync_params
      self._distributed_broadcast_coalesced(
    File "/sciclone/home20/hmbaier/.conda/envs/dhsrl4/lib/python3.9/site-packages/torch/nn/parallel/distributed.py", line 1334, in _distributed_broadcast_coalesced
      dist._broadcast_coalesced(
  RuntimeError: [/opt/conda/conda-bld/pytorch_1634272107467/work/third_party/gloo/gloo/transport/tcp/pair.cc:598] Connection closed by peer [10.3.59.1]:32917
  
[14]:
  time      : 2022-03-10_15:54:49
  host      : mlt001.sciclone.wm.edu
  rank      : 16 (local_rank: 16)
  exitcode  : 1 (pid: 177595)
  error_file: /local/scr/hmbaier/TMPDIR/torchelastic_kpuq9f13/790876_z6o4ujg5/attempt_0/16/error.json
  traceback : Traceback (most recent call last):
    File "/sciclone/home20/hmbaier/.conda/envs/dhsrl4/lib/python3.9/site-packages/torch/distributed/elastic/multiprocessing/errors/__init__.py", line 345, in wrapper
      return f(*args, **kwargs)
    File "/sciclone/home20/hmbaier/tm/run.py", line 100, in main
      ddp_model = DDP(model, process_group = model_group)
    File "/sciclone/home20/hmbaier/.conda/envs/dhsrl4/lib/python3.9/site-packages/torch/nn/parallel/distributed.py", line 580, in __init__
      self._sync_params_and_buffers(authoritative_rank=0)
    File "/sciclone/home20/hmbaier/.conda/envs/dhsrl4/lib/python3.9/site-packages/torch/nn/parallel/distributed.py", line 597, in _sync_params_and_buffers
      self._distributed_broadcast_coalesced(
    File "/sciclone/home20/hmbaier/.conda/envs/dhsrl4/lib/python3.9/site-packages/torch/nn/parallel/distributed.py", line 1334, in _distributed_broadcast_coalesced
      dist._broadcast_coalesced(
  RuntimeError: [/opt/conda/conda-bld/pytorch_1634272107467/work/third_party/gloo/gloo/transport/tcp/pair.cc:598] Connection closed by peer [10.3.59.1]:15530
  
[15]:
  time      : 2022-03-10_15:54:49
  host      : mlt001.sciclone.wm.edu
  rank      : 17 (local_rank: 17)
  exitcode  : 1 (pid: 177596)
  error_file: /local/scr/hmbaier/TMPDIR/torchelastic_kpuq9f13/790876_z6o4ujg5/attempt_0/17/error.json
  traceback : Traceback (most recent call last):
    File "/sciclone/home20/hmbaier/.conda/envs/dhsrl4/lib/python3.9/site-packages/torch/distributed/elastic/multiprocessing/errors/__init__.py", line 345, in wrapper
      return f(*args, **kwargs)
    File "/sciclone/home20/hmbaier/tm/run.py", line 122, in main
      output = ddp_model(input)
    File "/sciclone/home20/hmbaier/.conda/envs/dhsrl4/lib/python3.9/site-packages/torch/nn/modules/module.py", line 1102, in _call_impl
      return forward_call(*input, **kwargs)
    File "/sciclone/home20/hmbaier/.conda/envs/dhsrl4/lib/python3.9/site-packages/torch/nn/parallel/distributed.py", line 878, in forward
      self._sync_params()
    File "/sciclone/home20/hmbaier/.conda/envs/dhsrl4/lib/python3.9/site-packages/torch/nn/parallel/distributed.py", line 1379, in _sync_params
      self._distributed_broadcast_coalesced(
    File "/sciclone/home20/hmbaier/.conda/envs/dhsrl4/lib/python3.9/site-packages/torch/nn/parallel/distributed.py", line 1334, in _distributed_broadcast_coalesced
      dist._broadcast_coalesced(
  RuntimeError: [/opt/conda/conda-bld/pytorch_1634272107467/work/third_party/gloo/gloo/transport/tcp/pair.cc:598] Connection closed by peer [10.3.59.1]:28551
  
[16]:
  time      : 2022-03-10_15:54:50
  host      : mlt001.sciclone.wm.edu
  rank      : 18 (local_rank: 18)
  exitcode  : 1 (pid: 177597)
  error_file: /local/scr/hmbaier/TMPDIR/torchelastic_kpuq9f13/790876_z6o4ujg5/attempt_0/18/error.json
  traceback : Traceback (most recent call last):
    File "/sciclone/home20/hmbaier/.conda/envs/dhsrl4/lib/python3.9/site-packages/torch/distributed/elastic/multiprocessing/errors/__init__.py", line 345, in wrapper
      return f(*args, **kwargs)
    File "/sciclone/home20/hmbaier/tm/run.py", line 100, in main
      ddp_model = DDP(model, process_group = model_group)
    File "/sciclone/home20/hmbaier/.conda/envs/dhsrl4/lib/python3.9/site-packages/torch/nn/parallel/distributed.py", line 580, in __init__
      self._sync_params_and_buffers(authoritative_rank=0)
    File "/sciclone/home20/hmbaier/.conda/envs/dhsrl4/lib/python3.9/site-packages/torch/nn/parallel/distributed.py", line 597, in _sync_params_and_buffers
      self._distributed_broadcast_coalesced(
    File "/sciclone/home20/hmbaier/.conda/envs/dhsrl4/lib/python3.9/site-packages/torch/nn/parallel/distributed.py", line 1334, in _distributed_broadcast_coalesced
      dist._broadcast_coalesced(
  RuntimeError: [/opt/conda/conda-bld/pytorch_1634272107467/work/third_party/gloo/gloo/transport/tcp/pair.cc:598] Connection closed by peer [10.3.59.1]:13522
  
[17]:
  time      : 2022-03-10_15:54:49
  host      : mlt001.sciclone.wm.edu
  rank      : 20 (local_rank: 20)
  exitcode  : 1 (pid: 177599)
  error_file: /local/scr/hmbaier/TMPDIR/torchelastic_kpuq9f13/790876_z6o4ujg5/attempt_0/20/error.json
  traceback : Traceback (most recent call last):
    File "/sciclone/home20/hmbaier/.conda/envs/dhsrl4/lib/python3.9/site-packages/torch/distributed/elastic/multiprocessing/errors/__init__.py", line 345, in wrapper
      return f(*args, **kwargs)
    File "/sciclone/home20/hmbaier/tm/run.py", line 100, in main
      ddp_model = DDP(model, process_group = model_group)
    File "/sciclone/home20/hmbaier/.conda/envs/dhsrl4/lib/python3.9/site-packages/torch/nn/parallel/distributed.py", line 580, in __init__
      self._sync_params_and_buffers(authoritative_rank=0)
    File "/sciclone/home20/hmbaier/.conda/envs/dhsrl4/lib/python3.9/site-packages/torch/nn/parallel/distributed.py", line 597, in _sync_params_and_buffers
      self._distributed_broadcast_coalesced(
    File "/sciclone/home20/hmbaier/.conda/envs/dhsrl4/lib/python3.9/site-packages/torch/nn/parallel/distributed.py", line 1334, in _distributed_broadcast_coalesced
      dist._broadcast_coalesced(
  RuntimeError: [/opt/conda/conda-bld/pytorch_1634272107467/work/third_party/gloo/gloo/transport/tcp/pair.cc:598] Connection closed by peer [10.3.59.1]:32667
  
[18]:
  time      : 2022-03-10_15:54:50
  host      : mlt001.sciclone.wm.edu
  rank      : 21 (local_rank: 21)
  exitcode  : 1 (pid: 177600)
  error_file: /local/scr/hmbaier/TMPDIR/torchelastic_kpuq9f13/790876_z6o4ujg5/attempt_0/21/error.json
  traceback : Traceback (most recent call last):
    File "/sciclone/home20/hmbaier/.conda/envs/dhsrl4/lib/python3.9/site-packages/torch/distributed/elastic/multiprocessing/errors/__init__.py", line 345, in wrapper
      return f(*args, **kwargs)
    File "/sciclone/home20/hmbaier/tm/run.py", line 122, in main
      output = ddp_model(input)
    File "/sciclone/home20/hmbaier/.conda/envs/dhsrl4/lib/python3.9/site-packages/torch/nn/modules/module.py", line 1102, in _call_impl
      return forward_call(*input, **kwargs)
    File "/sciclone/home20/hmbaier/.conda/envs/dhsrl4/lib/python3.9/site-packages/torch/nn/parallel/distributed.py", line 878, in forward
      self._sync_params()
    File "/sciclone/home20/hmbaier/.conda/envs/dhsrl4/lib/python3.9/site-packages/torch/nn/parallel/distributed.py", line 1379, in _sync_params
      self._distributed_broadcast_coalesced(
    File "/sciclone/home20/hmbaier/.conda/envs/dhsrl4/lib/python3.9/site-packages/torch/nn/parallel/distributed.py", line 1334, in _distributed_broadcast_coalesced
      dist._broadcast_coalesced(
  RuntimeError: [/opt/conda/conda-bld/pytorch_1634272107467/work/third_party/gloo/gloo/transport/tcp/pair.cc:598] Connection closed by peer [10.3.59.1]:21659
  
[19]:
  time      : 2022-03-10_15:54:49
  host      : mlt001.sciclone.wm.edu
  rank      : 22 (local_rank: 22)
  exitcode  : 1 (pid: 177601)
  error_file: /local/scr/hmbaier/TMPDIR/torchelastic_kpuq9f13/790876_z6o4ujg5/attempt_0/22/error.json
  traceback : Traceback (most recent call last):
    File "/sciclone/home20/hmbaier/.conda/envs/dhsrl4/lib/python3.9/site-packages/torch/distributed/elastic/multiprocessing/errors/__init__.py", line 345, in wrapper
      return f(*args, **kwargs)
    File "/sciclone/home20/hmbaier/tm/run.py", line 100, in main
      ddp_model = DDP(model, process_group = model_group)
    File "/sciclone/home20/hmbaier/.conda/envs/dhsrl4/lib/python3.9/site-packages/torch/nn/parallel/distributed.py", line 580, in __init__
      self._sync_params_and_buffers(authoritative_rank=0)
    File "/sciclone/home20/hmbaier/.conda/envs/dhsrl4/lib/python3.9/site-packages/torch/nn/parallel/distributed.py", line 597, in _sync_params_and_buffers
      self._distributed_broadcast_coalesced(
    File "/sciclone/home20/hmbaier/.conda/envs/dhsrl4/lib/python3.9/site-packages/torch/nn/parallel/distributed.py", line 1334, in _distributed_broadcast_coalesced
      dist._broadcast_coalesced(
  RuntimeError: [/opt/conda/conda-bld/pytorch_1634272107467/work/third_party/gloo/gloo/transport/tcp/pair.cc:598] Connection closed by peer [10.3.59.1]:11667
  
[20]:
  time      : 2022-03-10_15:54:49
  host      : mlt001.sciclone.wm.edu
  rank      : 23 (local_rank: 23)
  exitcode  : 1 (pid: 177602)
  error_file: /local/scr/hmbaier/TMPDIR/torchelastic_kpuq9f13/790876_z6o4ujg5/attempt_0/23/error.json
  traceback : Traceback (most recent call last):
    File "/sciclone/home20/hmbaier/.conda/envs/dhsrl4/lib/python3.9/site-packages/torch/distributed/elastic/multiprocessing/errors/__init__.py", line 345, in wrapper
      return f(*args, **kwargs)
    File "/sciclone/home20/hmbaier/tm/run.py", line 122, in main
      output = ddp_model(input)
    File "/sciclone/home20/hmbaier/.conda/envs/dhsrl4/lib/python3.9/site-packages/torch/nn/modules/module.py", line 1102, in _call_impl
      return forward_call(*input, **kwargs)
    File "/sciclone/home20/hmbaier/.conda/envs/dhsrl4/lib/python3.9/site-packages/torch/nn/parallel/distributed.py", line 878, in forward
      self._sync_params()
    File "/sciclone/home20/hmbaier/.conda/envs/dhsrl4/lib/python3.9/site-packages/torch/nn/parallel/distributed.py", line 1379, in _sync_params
      self._distributed_broadcast_coalesced(
    File "/sciclone/home20/hmbaier/.conda/envs/dhsrl4/lib/python3.9/site-packages/torch/nn/parallel/distributed.py", line 1334, in _distributed_broadcast_coalesced
      dist._broadcast_coalesced(
  RuntimeError: [/opt/conda/conda-bld/pytorch_1634272107467/work/third_party/gloo/gloo/transport/tcp/pair.cc:598] Connection closed by peer [10.3.59.1]:10414
  
[21]:
  time      : 2022-03-10_15:54:49
  host      : mlt001.sciclone.wm.edu
  rank      : 24 (local_rank: 24)
  exitcode  : 1 (pid: 177603)
  error_file: /local/scr/hmbaier/TMPDIR/torchelastic_kpuq9f13/790876_z6o4ujg5/attempt_0/24/error.json
  traceback : Traceback (most recent call last):
    File "/sciclone/home20/hmbaier/.conda/envs/dhsrl4/lib/python3.9/site-packages/torch/distributed/elastic/multiprocessing/errors/__init__.py", line 345, in wrapper
      return f(*args, **kwargs)
    File "/sciclone/home20/hmbaier/tm/run.py", line 100, in main
      ddp_model = DDP(model, process_group = model_group)
    File "/sciclone/home20/hmbaier/.conda/envs/dhsrl4/lib/python3.9/site-packages/torch/nn/parallel/distributed.py", line 580, in __init__
      self._sync_params_and_buffers(authoritative_rank=0)
    File "/sciclone/home20/hmbaier/.conda/envs/dhsrl4/lib/python3.9/site-packages/torch/nn/parallel/distributed.py", line 597, in _sync_params_and_buffers
      self._distributed_broadcast_coalesced(
    File "/sciclone/home20/hmbaier/.conda/envs/dhsrl4/lib/python3.9/site-packages/torch/nn/parallel/distributed.py", line 1334, in _distributed_broadcast_coalesced
      dist._broadcast_coalesced(
  RuntimeError: [/opt/conda/conda-bld/pytorch_1634272107467/work/third_party/gloo/gloo/transport/tcp/pair.cc:598] Connection closed by peer [10.3.59.1]:13968
  
[22]:
  time      : 2022-03-10_15:54:49
  host      : mlt001.sciclone.wm.edu
  rank      : 25 (local_rank: 25)
  exitcode  : 1 (pid: 177606)
  error_file: /local/scr/hmbaier/TMPDIR/torchelastic_kpuq9f13/790876_z6o4ujg5/attempt_0/25/error.json
  traceback : Traceback (most recent call last):
    File "/sciclone/home20/hmbaier/.conda/envs/dhsrl4/lib/python3.9/site-packages/torch/distributed/elastic/multiprocessing/errors/__init__.py", line 345, in wrapper
      return f(*args, **kwargs)
    File "/sciclone/home20/hmbaier/tm/run.py", line 122, in main
      output = ddp_model(input)
    File "/sciclone/home20/hmbaier/.conda/envs/dhsrl4/lib/python3.9/site-packages/torch/nn/modules/module.py", line 1102, in _call_impl
      return forward_call(*input, **kwargs)
    File "/sciclone/home20/hmbaier/.conda/envs/dhsrl4/lib/python3.9/site-packages/torch/nn/parallel/distributed.py", line 878, in forward
      self._sync_params()
    File "/sciclone/home20/hmbaier/.conda/envs/dhsrl4/lib/python3.9/site-packages/torch/nn/parallel/distributed.py", line 1379, in _sync_params
      self._distributed_broadcast_coalesced(
    File "/sciclone/home20/hmbaier/.conda/envs/dhsrl4/lib/python3.9/site-packages/torch/nn/parallel/distributed.py", line 1334, in _distributed_broadcast_coalesced
      dist._broadcast_coalesced(
  RuntimeError: [/opt/conda/conda-bld/pytorch_1634272107467/work/third_party/gloo/gloo/transport/tcp/pair.cc:598] Connection closed by peer [10.3.59.1]:9961
  
[23]:
  time      : 2022-03-10_15:54:50
  host      : mlt001.sciclone.wm.edu
  rank      : 26 (local_rank: 26)
  exitcode  : 1 (pid: 177607)
  error_file: /local/scr/hmbaier/TMPDIR/torchelastic_kpuq9f13/790876_z6o4ujg5/attempt_0/26/error.json
  traceback : Traceback (most recent call last):
    File "/sciclone/home20/hmbaier/.conda/envs/dhsrl4/lib/python3.9/site-packages/torch/distributed/elastic/multiprocessing/errors/__init__.py", line 345, in wrapper
      return f(*args, **kwargs)
    File "/sciclone/home20/hmbaier/tm/run.py", line 100, in main
      ddp_model = DDP(model, process_group = model_group)
    File "/sciclone/home20/hmbaier/.conda/envs/dhsrl4/lib/python3.9/site-packages/torch/nn/parallel/distributed.py", line 580, in __init__
      self._sync_params_and_buffers(authoritative_rank=0)
    File "/sciclone/home20/hmbaier/.conda/envs/dhsrl4/lib/python3.9/site-packages/torch/nn/parallel/distributed.py", line 597, in _sync_params_and_buffers
      self._distributed_broadcast_coalesced(
    File "/sciclone/home20/hmbaier/.conda/envs/dhsrl4/lib/python3.9/site-packages/torch/nn/parallel/distributed.py", line 1334, in _distributed_broadcast_coalesced
      dist._broadcast_coalesced(
  RuntimeError: [/opt/conda/conda-bld/pytorch_1634272107467/work/third_party/gloo/gloo/transport/tcp/pair.cc:598] Connection closed by peer [10.3.59.1]:63652
  
[24]:
  time      : 2022-03-10_15:54:49
  host      : mlt001.sciclone.wm.edu
  rank      : 28 (local_rank: 28)
  exitcode  : 1 (pid: 177609)
  error_file: /local/scr/hmbaier/TMPDIR/torchelastic_kpuq9f13/790876_z6o4ujg5/attempt_0/28/error.json
  traceback : Traceback (most recent call last):
    File "/sciclone/home20/hmbaier/.conda/envs/dhsrl4/lib/python3.9/site-packages/torch/distributed/elastic/multiprocessing/errors/__init__.py", line 345, in wrapper
      return f(*args, **kwargs)
    File "/sciclone/home20/hmbaier/tm/run.py", line 100, in main
      ddp_model = DDP(model, process_group = model_group)
    File "/sciclone/home20/hmbaier/.conda/envs/dhsrl4/lib/python3.9/site-packages/torch/nn/parallel/distributed.py", line 580, in __init__
      self._sync_params_and_buffers(authoritative_rank=0)
    File "/sciclone/home20/hmbaier/.conda/envs/dhsrl4/lib/python3.9/site-packages/torch/nn/parallel/distributed.py", line 597, in _sync_params_and_buffers
      self._distributed_broadcast_coalesced(
    File "/sciclone/home20/hmbaier/.conda/envs/dhsrl4/lib/python3.9/site-packages/torch/nn/parallel/distributed.py", line 1334, in _distributed_broadcast_coalesced
      dist._broadcast_coalesced(
  RuntimeError: [/opt/conda/conda-bld/pytorch_1634272107467/work/third_party/gloo/gloo/transport/tcp/pair.cc:598] Connection closed by peer [10.3.59.1]:23684
  
[25]:
  time      : 2022-03-10_15:54:50
  host      : mlt001.sciclone.wm.edu
  rank      : 29 (local_rank: 29)
  exitcode  : 1 (pid: 177610)
  error_file: /local/scr/hmbaier/TMPDIR/torchelastic_kpuq9f13/790876_z6o4ujg5/attempt_0/29/error.json
  traceback : Traceback (most recent call last):
    File "/sciclone/home20/hmbaier/.conda/envs/dhsrl4/lib/python3.9/site-packages/torch/distributed/elastic/multiprocessing/errors/__init__.py", line 345, in wrapper
      return f(*args, **kwargs)
    File "/sciclone/home20/hmbaier/tm/run.py", line 122, in main
      output = ddp_model(input)
    File "/sciclone/home20/hmbaier/.conda/envs/dhsrl4/lib/python3.9/site-packages/torch/nn/modules/module.py", line 1102, in _call_impl
      return forward_call(*input, **kwargs)
    File "/sciclone/home20/hmbaier/.conda/envs/dhsrl4/lib/python3.9/site-packages/torch/nn/parallel/distributed.py", line 878, in forward
      self._sync_params()
    File "/sciclone/home20/hmbaier/.conda/envs/dhsrl4/lib/python3.9/site-packages/torch/nn/parallel/distributed.py", line 1379, in _sync_params
      self._distributed_broadcast_coalesced(
    File "/sciclone/home20/hmbaier/.conda/envs/dhsrl4/lib/python3.9/site-packages/torch/nn/parallel/distributed.py", line 1334, in _distributed_broadcast_coalesced
      dist._broadcast_coalesced(
  RuntimeError: [/opt/conda/conda-bld/pytorch_1634272107467/work/third_party/gloo/gloo/transport/tcp/pair.cc:598] Connection closed by peer [10.3.59.1]:3732
  
------------------------------------------------------------
Root Cause (first observed failure):
[0]:
  time      : 2022-03-10_15:54:47
  host      : mlt001.sciclone.wm.edu
  rank      : 1 (local_rank: 1)
  exitcode  : 1 (pid: 177580)
  error_file: /local/scr/hmbaier/TMPDIR/torchelastic_kpuq9f13/790876_z6o4ujg5/attempt_0/1/error.json
  traceback : Traceback (most recent call last):
    File "/sciclone/home20/hmbaier/.conda/envs/dhsrl4/lib/python3.9/site-packages/torch/distributed/elastic/multiprocessing/errors/__init__.py", line 345, in wrapper
      return f(*args, **kwargs)
    File "/sciclone/home20/hmbaier/tm/run.py", line 100, in main
      ddp_model = DDP(model, process_group = model_group)
    File "/sciclone/home20/hmbaier/.conda/envs/dhsrl4/lib/python3.9/site-packages/torch/nn/parallel/distributed.py", line 580, in __init__
      self._sync_params_and_buffers(authoritative_rank=0)
    File "/sciclone/home20/hmbaier/.conda/envs/dhsrl4/lib/python3.9/site-packages/torch/nn/parallel/distributed.py", line 597, in _sync_params_and_buffers
      self._distributed_broadcast_coalesced(
    File "/sciclone/home20/hmbaier/.conda/envs/dhsrl4/lib/python3.9/site-packages/torch/nn/parallel/distributed.py", line 1334, in _distributed_broadcast_coalesced
      dist._broadcast_coalesced(
  RuntimeError: [/opt/conda/conda-bld/pytorch_1634272107467/work/third_party/gloo/gloo/transport/tcp/pair.cc:598] Connection closed by peer [10.3.59.5]:25510
  
============================================================
