Warning: no access to tty (Bad file descriptor).
Thus no job control in this shell.
128.239.59.1
WARNING:torch.distributed.run:
*****************************************
Setting OMP_NUM_THREADS environment variable for each process to be 1 in default, to avoid your system being overloaded, please further tune the variable for optimal performance in your application as needed. 
*****************************************
Traceback (most recent call last):
  File "/sciclone/home20/hmbaier/tm/run.py", line 242, in <module>
    main(int(os.environ["RANK"]), int(os.environ['WORLD_SIZE']), model_group)
  File "/sciclone/home20/hmbaier/.conda/envs/dhsrl4/lib/python3.9/site-packages/torch/distributed/elastic/multiprocessing/errors/__init__.py", line 345, in wrapper
    return f(*args, **kwargs)
  File "/sciclone/home20/hmbaier/tm/run.py", line 100, in main
    ddp_model = DDP(model, process_group = model_group)
  File "/sciclone/home20/hmbaier/.conda/envs/dhsrl4/lib/python3.9/site-packages/torch/nn/parallel/distributed.py", line 580, in __init__
    self._sync_params_and_buffers(authoritative_rank=0)
  File "/sciclone/home20/hmbaier/.conda/envs/dhsrl4/lib/python3.9/site-packages/torch/nn/parallel/distributed.py", line 597, in _sync_params_and_buffers
    self._distributed_broadcast_coalesced(
  File "/sciclone/home20/hmbaier/.conda/envs/dhsrl4/lib/python3.9/site-packages/torch/nn/parallel/distributed.py", line 1334, in _distributed_broadcast_coalesced
    dist._broadcast_coalesced(
RuntimeError: [/opt/conda/conda-bld/pytorch_1634272107467/work/third_party/gloo/gloo/transport/tcp/pair.cc:598] Connection closed by peer [10.3.59.2]:11396
Traceback (most recent call last):
  File "/sciclone/home20/hmbaier/tm/run.py", line 242, in <module>
    main(int(os.environ["RANK"]), int(os.environ['WORLD_SIZE']), model_group)
  File "/sciclone/home20/hmbaier/.conda/envs/dhsrl4/lib/python3.9/site-packages/torch/distributed/elastic/multiprocessing/errors/__init__.py", line 345, in wrapper
    return f(*args, **kwargs)
  File "/sciclone/home20/hmbaier/tm/run.py", line 100, in main
    ddp_model = DDP(model, process_group = model_group)
  File "/sciclone/home20/hmbaier/.conda/envs/dhsrl4/lib/python3.9/site-packages/torch/nn/parallel/distributed.py", line 580, in __init__
    self._sync_params_and_buffers(authoritative_rank=0)
  File "/sciclone/home20/hmbaier/.conda/envs/dhsrl4/lib/python3.9/site-packages/torch/nn/parallel/distributed.py", line 597, in _sync_params_and_buffers
    self._distributed_broadcast_coalesced(
  File "/sciclone/home20/hmbaier/.conda/envs/dhsrl4/lib/python3.9/site-packages/torch/nn/parallel/distributed.py", line 1334, in _distributed_broadcast_coalesced
    dist._broadcast_coalesced(
RuntimeError: [/opt/conda/conda-bld/pytorch_1634272107467/work/third_party/gloo/gloo/transport/tcp/pair.cc:598] Connection closed by peer [10.3.59.2]:62118
Traceback (most recent call last):
  File "/sciclone/home20/hmbaier/tm/run.py", line 242, in <module>
    main(int(os.environ["RANK"]), int(os.environ['WORLD_SIZE']), model_group)
  File "/sciclone/home20/hmbaier/.conda/envs/dhsrl4/lib/python3.9/site-packages/torch/distributed/elastic/multiprocessing/errors/__init__.py", line 345, in wrapper
    return f(*args, **kwargs)
  File "/sciclone/home20/hmbaier/tm/run.py", line 100, in main
    ddp_model = DDP(model, process_group = model_group)
  File "/sciclone/home20/hmbaier/.conda/envs/dhsrl4/lib/python3.9/site-packages/torch/nn/parallel/distributed.py", line 580, in __init__
    self._sync_params_and_buffers(authoritative_rank=0)
  File "/sciclone/home20/hmbaier/.conda/envs/dhsrl4/lib/python3.9/site-packages/torch/nn/parallel/distributed.py", line 597, in _sync_params_and_buffers
    self._distributed_broadcast_coalesced(
  File "/sciclone/home20/hmbaier/.conda/envs/dhsrl4/lib/python3.9/site-packages/torch/nn/parallel/distributed.py", line 1334, in _distributed_broadcast_coalesced
    dist._broadcast_coalesced(
RuntimeError: [/opt/conda/conda-bld/pytorch_1634272107467/work/third_party/gloo/gloo/transport/tcp/pair.cc:598] Connection closed by peer [10.3.59.2]:7861
Traceback (most recent call last):
  File "/sciclone/home20/hmbaier/tm/run.py", line 242, in <module>
    main(int(os.environ["RANK"]), int(os.environ['WORLD_SIZE']), model_group)
  File "/sciclone/home20/hmbaier/.conda/envs/dhsrl4/lib/python3.9/site-packages/torch/distributed/elastic/multiprocessing/errors/__init__.py", line 345, in wrapper
    return f(*args, **kwargs)
  File "/sciclone/home20/hmbaier/tm/run.py", line 100, in main
    ddp_model = DDP(model, process_group = model_group)
  File "/sciclone/home20/hmbaier/.conda/envs/dhsrl4/lib/python3.9/site-packages/torch/nn/parallel/distributed.py", line 580, in __init__
    self._sync_params_and_buffers(authoritative_rank=0)
  File "/sciclone/home20/hmbaier/.conda/envs/dhsrl4/lib/python3.9/site-packages/torch/nn/parallel/distributed.py", line 597, in _sync_params_and_buffers
    self._distributed_broadcast_coalesced(
  File "/sciclone/home20/hmbaier/.conda/envs/dhsrl4/lib/python3.9/site-packages/torch/nn/parallel/distributed.py", line 1334, in _distributed_broadcast_coalesced
    dist._broadcast_coalesced(
RuntimeError: [/opt/conda/conda-bld/pytorch_1634272107467/work/third_party/gloo/gloo/transport/tcp/pair.cc:598] Connection closed by peer [10.3.59.2]:2956
Traceback (most recent call last):
  File "/sciclone/home20/hmbaier/tm/run.py", line 242, in <module>
    main(int(os.environ["RANK"]), int(os.environ['WORLD_SIZE']), model_group)
  File "/sciclone/home20/hmbaier/.conda/envs/dhsrl4/lib/python3.9/site-packages/torch/distributed/elastic/multiprocessing/errors/__init__.py", line 345, in wrapper
    return f(*args, **kwargs)
  File "/sciclone/home20/hmbaier/tm/run.py", line 100, in main
    ddp_model = DDP(model, process_group = model_group)
  File "/sciclone/home20/hmbaier/.conda/envs/dhsrl4/lib/python3.9/site-packages/torch/nn/parallel/distributed.py", line 580, in __init__
    self._sync_params_and_buffers(authoritative_rank=0)
  File "/sciclone/home20/hmbaier/.conda/envs/dhsrl4/lib/python3.9/site-packages/torch/nn/parallel/distributed.py", line 597, in _sync_params_and_buffers
    self._distributed_broadcast_coalesced(
  File "/sciclone/home20/hmbaier/.conda/envs/dhsrl4/lib/python3.9/site-packages/torch/nn/parallel/distributed.py", line 1334, in _distributed_broadcast_coalesced
    dist._broadcast_coalesced(
RuntimeError: [/opt/conda/conda-bld/pytorch_1634272107467/work/third_party/gloo/gloo/transport/tcp/pair.cc:598] Connection closed by peer [10.3.59.2]:27786
Traceback (most recent call last):
  File "/sciclone/home20/hmbaier/tm/run.py", line 242, in <module>
    main(int(os.environ["RANK"]), int(os.environ['WORLD_SIZE']), model_group)
  File "/sciclone/home20/hmbaier/.conda/envs/dhsrl4/lib/python3.9/site-packages/torch/distributed/elastic/multiprocessing/errors/__init__.py", line 345, in wrapper
    return f(*args, **kwargs)
  File "/sciclone/home20/hmbaier/tm/run.py", line 100, in main
    ddp_model = DDP(model, process_group = model_group)
  File "/sciclone/home20/hmbaier/.conda/envs/dhsrl4/lib/python3.9/site-packages/torch/nn/parallel/distributed.py", line 580, in __init__
    self._sync_params_and_buffers(authoritative_rank=0)
  File "/sciclone/home20/hmbaier/.conda/envs/dhsrl4/lib/python3.9/site-packages/torch/nn/parallel/distributed.py", line 597, in _sync_params_and_buffers
    self._distributed_broadcast_coalesced(
  File "/sciclone/home20/hmbaier/.conda/envs/dhsrl4/lib/python3.9/site-packages/torch/nn/parallel/distributed.py", line 1334, in _distributed_broadcast_coalesced
    dist._broadcast_coalesced(
RuntimeError: [/opt/conda/conda-bld/pytorch_1634272107467/work/third_party/gloo/gloo/transport/tcp/pair.cc:598] Connection closed by peer [10.3.59.2]:32420
Traceback (most recent call last):
  File "/sciclone/home20/hmbaier/tm/run.py", line 242, in <module>
    main(int(os.environ["RANK"]), int(os.environ['WORLD_SIZE']), model_group)
  File "/sciclone/home20/hmbaier/.conda/envs/dhsrl4/lib/python3.9/site-packages/torch/distributed/elastic/multiprocessing/errors/__init__.py", line 345, in wrapper
    return f(*args, **kwargs)
  File "/sciclone/home20/hmbaier/tm/run.py", line 100, in main
    ddp_model = DDP(model, process_group = model_group)
  File "/sciclone/home20/hmbaier/.conda/envs/dhsrl4/lib/python3.9/site-packages/torch/nn/parallel/distributed.py", line 580, in __init__
    self._sync_params_and_buffers(authoritative_rank=0)
  File "/sciclone/home20/hmbaier/.conda/envs/dhsrl4/lib/python3.9/site-packages/torch/nn/parallel/distributed.py", line 597, in _sync_params_and_buffers
    self._distributed_broadcast_coalesced(
  File "/sciclone/home20/hmbaier/.conda/envs/dhsrl4/lib/python3.9/site-packages/torch/nn/parallel/distributed.py", line 1334, in _distributed_broadcast_coalesced
    dist._broadcast_coalesced(
RuntimeError: [/opt/conda/conda-bld/pytorch_1634272107467/work/third_party/gloo/gloo/transport/tcp/pair.cc:598] Connection closed by peer [10.3.59.2]:30367
Traceback (most recent call last):
  File "/sciclone/home20/hmbaier/tm/run.py", line 242, in <module>
    main(int(os.environ["RANK"]), int(os.environ['WORLD_SIZE']), model_group)
  File "/sciclone/home20/hmbaier/.conda/envs/dhsrl4/lib/python3.9/site-packages/torch/distributed/elastic/multiprocessing/errors/__init__.py", line 345, in wrapper
    return f(*args, **kwargs)
  File "/sciclone/home20/hmbaier/tm/run.py", line 100, in main
    ddp_model = DDP(model, process_group = model_group)
  File "/sciclone/home20/hmbaier/.conda/envs/dhsrl4/lib/python3.9/site-packages/torch/nn/parallel/distributed.py", line 580, in __init__
    self._sync_params_and_buffers(authoritative_rank=0)
  File "/sciclone/home20/hmbaier/.conda/envs/dhsrl4/lib/python3.9/site-packages/torch/nn/parallel/distributed.py", line 597, in _sync_params_and_buffers
    self._distributed_broadcast_coalesced(
  File "/sciclone/home20/hmbaier/.conda/envs/dhsrl4/lib/python3.9/site-packages/torch/nn/parallel/distributed.py", line 1334, in _distributed_broadcast_coalesced
    dist._broadcast_coalesced(
RuntimeError: [/opt/conda/conda-bld/pytorch_1634272107467/work/third_party/gloo/gloo/transport/tcp/pair.cc:598] Connection closed by peer [10.3.59.2]:56449
Traceback (most recent call last):
  File "/sciclone/home20/hmbaier/tm/run.py", line 242, in <module>
    main(int(os.environ["RANK"]), int(os.environ['WORLD_SIZE']), model_group)
  File "/sciclone/home20/hmbaier/.conda/envs/dhsrl4/lib/python3.9/site-packages/torch/distributed/elastic/multiprocessing/errors/__init__.py", line 345, in wrapper
    return f(*args, **kwargs)
  File "/sciclone/home20/hmbaier/tm/run.py", line 122, in main
    output = ddp_model(input)
  File "/sciclone/home20/hmbaier/.conda/envs/dhsrl4/lib/python3.9/site-packages/torch/nn/modules/module.py", line 1102, in _call_impl
    return forward_call(*input, **kwargs)
  File "/sciclone/home20/hmbaier/.conda/envs/dhsrl4/lib/python3.9/site-packages/torch/nn/parallel/distributed.py", line 878, in forward
    self._sync_params()
  File "/sciclone/home20/hmbaier/.conda/envs/dhsrl4/lib/python3.9/site-packages/torch/nn/parallel/distributed.py", line 1379, in _sync_params
    self._distributed_broadcast_coalesced(
  File "/sciclone/home20/hmbaier/.conda/envs/dhsrl4/lib/python3.9/site-packages/torch/nn/parallel/distributed.py", line 1334, in _distributed_broadcast_coalesced
Traceback (most recent call last):
  File "/sciclone/home20/hmbaier/tm/run.py", line 242, in <module>
    dist._broadcast_coalesced(
RuntimeError: [/opt/conda/conda-bld/pytorch_1634272107467/work/third_party/gloo/gloo/transport/tcp/pair.cc:598] Connection closed by peer [10.3.59.2]:14482
    main(int(os.environ["RANK"]), int(os.environ['WORLD_SIZE']), model_group)
  File "/sciclone/home20/hmbaier/.conda/envs/dhsrl4/lib/python3.9/site-packages/torch/distributed/elastic/multiprocessing/errors/__init__.py", line 345, in wrapper
    return f(*args, **kwargs)
  File "/sciclone/home20/hmbaier/tm/run.py", line 100, in main
    ddp_model = DDP(model, process_group = model_group)
  File "/sciclone/home20/hmbaier/.conda/envs/dhsrl4/lib/python3.9/site-packages/torch/nn/parallel/distributed.py", line 580, in __init__
    self._sync_params_and_buffers(authoritative_rank=0)
  File "/sciclone/home20/hmbaier/.conda/envs/dhsrl4/lib/python3.9/site-packages/torch/nn/parallel/distributed.py", line 597, in _sync_params_and_buffers
    self._distributed_broadcast_coalesced(
  File "/sciclone/home20/hmbaier/.conda/envs/dhsrl4/lib/python3.9/site-packages/torch/nn/parallel/distributed.py", line 1334, in _distributed_broadcast_coalesced
    dist._broadcast_coalesced(
RuntimeError: [/opt/conda/conda-bld/pytorch_1634272107467/work/third_party/gloo/gloo/transport/tcp/pair.cc:598] Connection closed by peer [10.3.59.2]:8881
Traceback (most recent call last):
  File "/sciclone/home20/hmbaier/tm/run.py", line 242, in <module>
    main(int(os.environ["RANK"]), int(os.environ['WORLD_SIZE']), model_group)
  File "/sciclone/home20/hmbaier/.conda/envs/dhsrl4/lib/python3.9/site-packages/torch/distributed/elastic/multiprocessing/errors/__init__.py", line 345, in wrapper
    return f(*args, **kwargs)
  File "/sciclone/home20/hmbaier/tm/run.py", line 122, in main
    output = ddp_model(input)
  File "/sciclone/home20/hmbaier/.conda/envs/dhsrl4/lib/python3.9/site-packages/torch/nn/modules/module.py", line 1102, in _call_impl
    return forward_call(*input, **kwargs)
  File "/sciclone/home20/hmbaier/.conda/envs/dhsrl4/lib/python3.9/site-packages/torch/nn/parallel/distributed.py", line 878, in forward
    self._sync_params()
  File "/sciclone/home20/hmbaier/.conda/envs/dhsrl4/lib/python3.9/site-packages/torch/nn/parallel/distributed.py", line 1379, in _sync_params
    self._distributed_broadcast_coalesced(
  File "/sciclone/home20/hmbaier/.conda/envs/dhsrl4/lib/python3.9/site-packages/torch/nn/parallel/distributed.py", line 1334, in _distributed_broadcast_coalesced
    dist._broadcast_coalesced(
RuntimeError: [/opt/conda/conda-bld/pytorch_1634272107467/work/third_party/gloo/gloo/transport/tcp/pair.cc:598] Connection closed by peer [10.3.59.2]:15260
Traceback (most recent call last):
  File "/sciclone/home20/hmbaier/tm/run.py", line 242, in <module>
    main(int(os.environ["RANK"]), int(os.environ['WORLD_SIZE']), model_group)
  File "/sciclone/home20/hmbaier/.conda/envs/dhsrl4/lib/python3.9/site-packages/torch/distributed/elastic/multiprocessing/errors/__init__.py", line 345, in wrapper
    return f(*args, **kwargs)
  File "/sciclone/home20/hmbaier/tm/run.py", line 100, in main
    ddp_model = DDP(model, process_group = model_group)
  File "/sciclone/home20/hmbaier/.conda/envs/dhsrl4/lib/python3.9/site-packages/torch/nn/parallel/distributed.py", line 580, in __init__
    self._sync_params_and_buffers(authoritative_rank=0)
  File "/sciclone/home20/hmbaier/.conda/envs/dhsrl4/lib/python3.9/site-packages/torch/nn/parallel/distributed.py", line 597, in _sync_params_and_buffers
    self._distributed_broadcast_coalesced(
  File "/sciclone/home20/hmbaier/.conda/envs/dhsrl4/lib/python3.9/site-packages/torch/nn/parallel/distributed.py", line 1334, in _distributed_broadcast_coalesced
    dist._broadcast_coalesced(
RuntimeError: [/opt/conda/conda-bld/pytorch_1634272107467/work/third_party/gloo/gloo/transport/tcp/pair.cc:598] Connection closed by peer [10.3.59.2]:34694
Traceback (most recent call last):
  File "/sciclone/home20/hmbaier/tm/run.py", line 242, in <module>
    main(int(os.environ["RANK"]), int(os.environ['WORLD_SIZE']), model_group)
  File "/sciclone/home20/hmbaier/.conda/envs/dhsrl4/lib/python3.9/site-packages/torch/distributed/elastic/multiprocessing/errors/__init__.py", line 345, in wrapper
    return f(*args, **kwargs)
  File "/sciclone/home20/hmbaier/tm/run.py", line 100, in main
    ddp_model = DDP(model, process_group = model_group)
  File "/sciclone/home20/hmbaier/.conda/envs/dhsrl4/lib/python3.9/site-packages/torch/nn/parallel/distributed.py", line 580, in __init__
    self._sync_params_and_buffers(authoritative_rank=0)
  File "/sciclone/home20/hmbaier/.conda/envs/dhsrl4/lib/python3.9/site-packages/torch/nn/parallel/distributed.py", line 597, in _sync_params_and_buffers
    self._distributed_broadcast_coalesced(
  File "/sciclone/home20/hmbaier/.conda/envs/dhsrl4/lib/python3.9/site-packages/torch/nn/parallel/distributed.py", line 1334, in _distributed_broadcast_coalesced
    dist._broadcast_coalesced(
RuntimeError: [/opt/conda/conda-bld/pytorch_1634272107467/work/third_party/gloo/gloo/transport/tcp/pair.cc:598] Connection closed by peer [10.3.59.2]:50048
Traceback (most recent call last):
  File "/sciclone/home20/hmbaier/tm/run.py", line 242, in <module>
    main(int(os.environ["RANK"]), int(os.environ['WORLD_SIZE']), model_group)
  File "/sciclone/home20/hmbaier/.conda/envs/dhsrl4/lib/python3.9/site-packages/torch/distributed/elastic/multiprocessing/errors/__init__.py", line 345, in wrapper
    return f(*args, **kwargs)
  File "/sciclone/home20/hmbaier/tm/run.py", line 122, in main
    output = ddp_model(input)
  File "/sciclone/home20/hmbaier/.conda/envs/dhsrl4/lib/python3.9/site-packages/torch/nn/modules/module.py", line 1102, in _call_impl
    return forward_call(*input, **kwargs)
  File "/sciclone/home20/hmbaier/.conda/envs/dhsrl4/lib/python3.9/site-packages/torch/nn/parallel/distributed.py", line 878, in forward
    self._sync_params()
  File "/sciclone/home20/hmbaier/.conda/envs/dhsrl4/lib/python3.9/site-packages/torch/nn/parallel/distributed.py", line 1379, in _sync_params
Traceback (most recent call last):
  File "/sciclone/home20/hmbaier/tm/run.py", line 242, in <module>
    main(int(os.environ["RANK"]), int(os.environ['WORLD_SIZE']), model_group)
  File "/sciclone/home20/hmbaier/.conda/envs/dhsrl4/lib/python3.9/site-packages/torch/distributed/elastic/multiprocessing/errors/__init__.py", line 345, in wrapper
    return f(*args, **kwargs)
  File "/sciclone/home20/hmbaier/tm/run.py", line 100, in main
    ddp_model = DDP(model, process_group = model_group)
  File "/sciclone/home20/hmbaier/.conda/envs/dhsrl4/lib/python3.9/site-packages/torch/nn/parallel/distributed.py", line 580, in __init__
    self._sync_params_and_buffers(authoritative_rank=0)
  File "/sciclone/home20/hmbaier/.conda/envs/dhsrl4/lib/python3.9/site-packages/torch/nn/parallel/distributed.py", line 597, in _sync_params_and_buffers
    self._distributed_broadcast_coalesced(
  File "/sciclone/home20/hmbaier/.conda/envs/dhsrl4/lib/python3.9/site-packages/torch/nn/parallel/distributed.py", line 1334, in _distributed_broadcast_coalesced
    dist._broadcast_coalesced(
RuntimeError: [/opt/conda/conda-bld/pytorch_1634272107467/work/third_party/gloo/gloo/transport/tcp/pair.cc:598] Connection closed by peer [10.3.59.2]:36254
    self._distributed_broadcast_coalesced(
  File "/sciclone/home20/hmbaier/.conda/envs/dhsrl4/lib/python3.9/site-packages/torch/nn/parallel/distributed.py", line 1334, in _distributed_broadcast_coalesced
    dist._broadcast_coalesced(
RuntimeError: [/opt/conda/conda-bld/pytorch_1634272107467/work/third_party/gloo/gloo/transport/tcp/pair.cc:598] Connection closed by peer [10.3.59.2]:10371
Traceback (most recent call last):
  File "/sciclone/home20/hmbaier/tm/run.py", line 242, in <module>
    main(int(os.environ["RANK"]), int(os.environ['WORLD_SIZE']), model_group)
  File "/sciclone/home20/hmbaier/.conda/envs/dhsrl4/lib/python3.9/site-packages/torch/distributed/elastic/multiprocessing/errors/__init__.py", line 345, in wrapper
    return f(*args, **kwargs)
  File "/sciclone/home20/hmbaier/tm/run.py", line 122, in main
    output = ddp_model(input)
  File "/sciclone/home20/hmbaier/.conda/envs/dhsrl4/lib/python3.9/site-packages/torch/nn/modules/module.py", line 1102, in _call_impl
    return forward_call(*input, **kwargs)
  File "/sciclone/home20/hmbaier/.conda/envs/dhsrl4/lib/python3.9/site-packages/torch/nn/parallel/distributed.py", line 878, in forward
    self._sync_params()
  File "/sciclone/home20/hmbaier/.conda/envs/dhsrl4/lib/python3.9/site-packages/torch/nn/parallel/distributed.py", line 1379, in _sync_params
    self._distributed_broadcast_coalesced(
  File "/sciclone/home20/hmbaier/.conda/envs/dhsrl4/lib/python3.9/site-packages/torch/nn/parallel/distributed.py", line 1334, in _distributed_broadcast_coalesced
Traceback (most recent call last):
  File "/sciclone/home20/hmbaier/tm/run.py", line 242, in <module>
    dist._broadcast_coalesced(
Traceback (most recent call last):
RuntimeError  File "/sciclone/home20/hmbaier/tm/run.py", line 242, in <module>
:     [/opt/conda/conda-bld/pytorch_1634272107467/work/third_party/gloo/gloo/transport/tcp/pair.cc:598] Connection closed by peer [10.3.59.2]:35727main(int(os.environ["RANK"]), int(os.environ['WORLD_SIZE']), model_group)

  File "/sciclone/home20/hmbaier/.conda/envs/dhsrl4/lib/python3.9/site-packages/torch/distributed/elastic/multiprocessing/errors/__init__.py", line 345, in wrapper
    main(int(os.environ["RANK"]), int(os.environ['WORLD_SIZE']), model_group)
  File "/sciclone/home20/hmbaier/.conda/envs/dhsrl4/lib/python3.9/site-packages/torch/distributed/elastic/multiprocessing/errors/__init__.py", line 345, in wrapper
    return f(*args, **kwargs)
  File "/sciclone/home20/hmbaier/tm/run.py", line 100, in main
        ddp_model = DDP(model, process_group = model_group)return f(*args, **kwargs)

  File "/sciclone/home20/hmbaier/.conda/envs/dhsrl4/lib/python3.9/site-packages/torch/nn/parallel/distributed.py", line 580, in __init__
  File "/sciclone/home20/hmbaier/tm/run.py", line 100, in main
    ddp_model = DDP(model, process_group = model_group)
  File "/sciclone/home20/hmbaier/.conda/envs/dhsrl4/lib/python3.9/site-packages/torch/nn/parallel/distributed.py", line 580, in __init__
    self._sync_params_and_buffers(authoritative_rank=0)
  File "/sciclone/home20/hmbaier/.conda/envs/dhsrl4/lib/python3.9/site-packages/torch/nn/parallel/distributed.py", line 597, in _sync_params_and_buffers
        self._sync_params_and_buffers(authoritative_rank=0)self._distributed_broadcast_coalesced(

  File "/sciclone/home20/hmbaier/.conda/envs/dhsrl4/lib/python3.9/site-packages/torch/nn/parallel/distributed.py", line 597, in _sync_params_and_buffers
  File "/sciclone/home20/hmbaier/.conda/envs/dhsrl4/lib/python3.9/site-packages/torch/nn/parallel/distributed.py", line 1334, in _distributed_broadcast_coalesced
    dist._broadcast_coalesced(
RuntimeError: [/opt/conda/conda-bld/pytorch_1634272107467/work/third_party/gloo/gloo/transport/tcp/pair.cc:598] Connection closed by peer [10.3.59.2]:6554
    self._distributed_broadcast_coalesced(
  File "/sciclone/home20/hmbaier/.conda/envs/dhsrl4/lib/python3.9/site-packages/torch/nn/parallel/distributed.py", line 1334, in _distributed_broadcast_coalesced
    dist._broadcast_coalesced(
RuntimeError: [/opt/conda/conda-bld/pytorch_1634272107467/work/third_party/gloo/gloo/transport/tcp/pair.cc:598] Connection closed by peer [10.3.59.2]:14255
Traceback (most recent call last):
  File "/sciclone/home20/hmbaier/tm/run.py", line 242, in <module>
Traceback (most recent call last):
      File "/sciclone/home20/hmbaier/tm/run.py", line 242, in <module>
main(int(os.environ["RANK"]), int(os.environ['WORLD_SIZE']), model_group)
  File "/sciclone/home20/hmbaier/.conda/envs/dhsrl4/lib/python3.9/site-packages/torch/distributed/elastic/multiprocessing/errors/__init__.py", line 345, in wrapper
        main(int(os.environ["RANK"]), int(os.environ['WORLD_SIZE']), model_group)return f(*args, **kwargs)

  File "/sciclone/home20/hmbaier/.conda/envs/dhsrl4/lib/python3.9/site-packages/torch/distributed/elastic/multiprocessing/errors/__init__.py", line 345, in wrapper
  File "/sciclone/home20/hmbaier/tm/run.py", line 122, in main
    output = ddp_model(input)
  File "/sciclone/home20/hmbaier/.conda/envs/dhsrl4/lib/python3.9/site-packages/torch/nn/modules/module.py", line 1102, in _call_impl
    return f(*args, **kwargs)
  File "/sciclone/home20/hmbaier/tm/run.py", line 100, in main
    ddp_model = DDP(model, process_group = model_group)
  File "/sciclone/home20/hmbaier/.conda/envs/dhsrl4/lib/python3.9/site-packages/torch/nn/parallel/distributed.py", line 580, in __init__
    return forward_call(*input, **kwargs)
  File "/sciclone/home20/hmbaier/.conda/envs/dhsrl4/lib/python3.9/site-packages/torch/nn/parallel/distributed.py", line 878, in forward
    self._sync_params_and_buffers(authoritative_rank=0)
  File "/sciclone/home20/hmbaier/.conda/envs/dhsrl4/lib/python3.9/site-packages/torch/nn/parallel/distributed.py", line 597, in _sync_params_and_buffers
    self._sync_params()
  File "/sciclone/home20/hmbaier/.conda/envs/dhsrl4/lib/python3.9/site-packages/torch/nn/parallel/distributed.py", line 1379, in _sync_params
    self._distributed_broadcast_coalesced(
  File "/sciclone/home20/hmbaier/.conda/envs/dhsrl4/lib/python3.9/site-packages/torch/nn/parallel/distributed.py", line 1334, in _distributed_broadcast_coalesced
        dist._broadcast_coalesced(self._distributed_broadcast_coalesced(

RuntimeError  File "/sciclone/home20/hmbaier/.conda/envs/dhsrl4/lib/python3.9/site-packages/torch/nn/parallel/distributed.py", line 1334, in _distributed_broadcast_coalesced
: [/opt/conda/conda-bld/pytorch_1634272107467/work/third_party/gloo/gloo/transport/tcp/pair.cc:598] Connection closed by peer [10.3.59.2]:43162
    dist._broadcast_coalesced(
RuntimeError: [/opt/conda/conda-bld/pytorch_1634272107467/work/third_party/gloo/gloo/transport/tcp/pair.cc:598] Connection closed by peer [10.3.59.2]:26797
Traceback (most recent call last):
  File "/sciclone/home20/hmbaier/tm/run.py", line 242, in <module>
    main(int(os.environ["RANK"]), int(os.environ['WORLD_SIZE']), model_group)
  File "/sciclone/home20/hmbaier/.conda/envs/dhsrl4/lib/python3.9/site-packages/torch/distributed/elastic/multiprocessing/errors/__init__.py", line 345, in wrapper
    return f(*args, **kwargs)
  File "/sciclone/home20/hmbaier/tm/run.py", line 100, in main
    ddp_model = DDP(model, process_group = model_group)
  File "/sciclone/home20/hmbaier/.conda/envs/dhsrl4/lib/python3.9/site-packages/torch/nn/parallel/distributed.py", line 580, in __init__
    self._sync_params_and_buffers(authoritative_rank=0)
  File "/sciclone/home20/hmbaier/.conda/envs/dhsrl4/lib/python3.9/site-packages/torch/nn/parallel/distributed.py", line 597, in _sync_params_and_buffers
    self._distributed_broadcast_coalesced(
  File "/sciclone/home20/hmbaier/.conda/envs/dhsrl4/lib/python3.9/site-packages/torch/nn/parallel/distributed.py", line 1334, in _distributed_broadcast_coalesced
    dist._broadcast_coalesced(
RuntimeError: [/opt/conda/conda-bld/pytorch_1634272107467/work/third_party/gloo/gloo/transport/tcp/pair.cc:598] Connection closed by peer [10.3.59.2]:47280
Traceback (most recent call last):
  File "/sciclone/home20/hmbaier/tm/run.py", line 242, in <module>
    main(int(os.environ["RANK"]), int(os.environ['WORLD_SIZE']), model_group)
  File "/sciclone/home20/hmbaier/.conda/envs/dhsrl4/lib/python3.9/site-packages/torch/distributed/elastic/multiprocessing/errors/__init__.py", line 345, in wrapper
    return f(*args, **kwargs)
  File "/sciclone/home20/hmbaier/tm/run.py", line 122, in main
    output = ddp_model(input)
  File "/sciclone/home20/hmbaier/.conda/envs/dhsrl4/lib/python3.9/site-packages/torch/nn/modules/module.py", line 1102, in _call_impl
    return forward_call(*input, **kwargs)
  File "/sciclone/home20/hmbaier/.conda/envs/dhsrl4/lib/python3.9/site-packages/torch/nn/parallel/distributed.py", line 878, in forward
    self._sync_params()
  File "/sciclone/home20/hmbaier/.conda/envs/dhsrl4/lib/python3.9/site-packages/torch/nn/parallel/distributed.py", line 1379, in _sync_params
Traceback (most recent call last):
  File "/sciclone/home20/hmbaier/tm/run.py", line 242, in <module>
    main(int(os.environ["RANK"]), int(os.environ['WORLD_SIZE']), model_group)
  File "/sciclone/home20/hmbaier/.conda/envs/dhsrl4/lib/python3.9/site-packages/torch/distributed/elastic/multiprocessing/errors/__init__.py", line 345, in wrapper
    self._distributed_broadcast_coalesced(
  File "/sciclone/home20/hmbaier/.conda/envs/dhsrl4/lib/python3.9/site-packages/torch/nn/parallel/distributed.py", line 1334, in _distributed_broadcast_coalesced
    return f(*args, **kwargs)
  File "/sciclone/home20/hmbaier/tm/run.py", line 100, in main
    ddp_model = DDP(model, process_group = model_group)
  File "/sciclone/home20/hmbaier/.conda/envs/dhsrl4/lib/python3.9/site-packages/torch/nn/parallel/distributed.py", line 580, in __init__
    dist._broadcast_coalesced(
RuntimeError: [/opt/conda/conda-bld/pytorch_1634272107467/work/third_party/gloo/gloo/transport/tcp/pair.cc:598] Connection closed by peer [10.3.59.2]:3981
    self._sync_params_and_buffers(authoritative_rank=0)
  File "/sciclone/home20/hmbaier/.conda/envs/dhsrl4/lib/python3.9/site-packages/torch/nn/parallel/distributed.py", line 597, in _sync_params_and_buffers
    self._distributed_broadcast_coalesced(
  File "/sciclone/home20/hmbaier/.conda/envs/dhsrl4/lib/python3.9/site-packages/torch/nn/parallel/distributed.py", line 1334, in _distributed_broadcast_coalesced
    dist._broadcast_coalesced(
RuntimeError: [/opt/conda/conda-bld/pytorch_1634272107467/work/third_party/gloo/gloo/transport/tcp/pair.cc:598] Connection closed by peer [10.3.59.2]:64410
Traceback (most recent call last):
  File "/sciclone/home20/hmbaier/tm/run.py", line 242, in <module>
    main(int(os.environ["RANK"]), int(os.environ['WORLD_SIZE']), model_group)
  File "/sciclone/home20/hmbaier/.conda/envs/dhsrl4/lib/python3.9/site-packages/torch/distributed/elastic/multiprocessing/errors/__init__.py", line 345, in wrapper
    return f(*args, **kwargs)
  File "/sciclone/home20/hmbaier/tm/run.py", line 100, in main
    ddp_model = DDP(model, process_group = model_group)
  File "/sciclone/home20/hmbaier/.conda/envs/dhsrl4/lib/python3.9/site-packages/torch/nn/parallel/distributed.py", line 580, in __init__
    self._sync_params_and_buffers(authoritative_rank=0)
  File "/sciclone/home20/hmbaier/.conda/envs/dhsrl4/lib/python3.9/site-packages/torch/nn/parallel/distributed.py", line 597, in _sync_params_and_buffers
    self._distributed_broadcast_coalesced(
  File "/sciclone/home20/hmbaier/.conda/envs/dhsrl4/lib/python3.9/site-packages/torch/nn/parallel/distributed.py", line 1334, in _distributed_broadcast_coalesced
    dist._broadcast_coalesced(
RuntimeError: [/opt/conda/conda-bld/pytorch_1634272107467/work/third_party/gloo/gloo/transport/tcp/pair.cc:598] Connection closed by peer [10.3.59.2]:12174
Traceback (most recent call last):
  File "/sciclone/home20/hmbaier/tm/run.py", line 242, in <module>
    main(int(os.environ["RANK"]), int(os.environ['WORLD_SIZE']), model_group)
  File "/sciclone/home20/hmbaier/.conda/envs/dhsrl4/lib/python3.9/site-packages/torch/distributed/elastic/multiprocessing/errors/__init__.py", line 345, in wrapper
    return f(*args, **kwargs)
  File "/sciclone/home20/hmbaier/tm/run.py", line 100, in main
    ddp_model = DDP(model, process_group = model_group)
  File "/sciclone/home20/hmbaier/.conda/envs/dhsrl4/lib/python3.9/site-packages/torch/nn/parallel/distributed.py", line 580, in __init__
    self._sync_params_and_buffers(authoritative_rank=0)
  File "/sciclone/home20/hmbaier/.conda/envs/dhsrl4/lib/python3.9/site-packages/torch/nn/parallel/distributed.py", line 597, in _sync_params_and_buffers
    self._distributed_broadcast_coalesced(
  File "/sciclone/home20/hmbaier/.conda/envs/dhsrl4/lib/python3.9/site-packages/torch/nn/parallel/distributed.py", line 1334, in _distributed_broadcast_coalesced
Traceback (most recent call last):
  File "/sciclone/home20/hmbaier/tm/run.py", line 242, in <module>
    dist._broadcast_coalesced(
RuntimeError: [/opt/conda/conda-bld/pytorch_1634272107467/work/third_party/gloo/gloo/transport/tcp/pair.cc:598] Connection closed by peer [10.3.59.2]:49559
    main(int(os.environ["RANK"]), int(os.environ['WORLD_SIZE']), model_group)
  File "/sciclone/home20/hmbaier/.conda/envs/dhsrl4/lib/python3.9/site-packages/torch/distributed/elastic/multiprocessing/errors/__init__.py", line 345, in wrapper
    return f(*args, **kwargs)
  File "/sciclone/home20/hmbaier/tm/run.py", line 122, in main
    output = ddp_model(input)
  File "/sciclone/home20/hmbaier/.conda/envs/dhsrl4/lib/python3.9/site-packages/torch/nn/modules/module.py", line 1102, in _call_impl
    return forward_call(*input, **kwargs)
  File "/sciclone/home20/hmbaier/.conda/envs/dhsrl4/lib/python3.9/site-packages/torch/nn/parallel/distributed.py", line 878, in forward
    self._sync_params()
  File "/sciclone/home20/hmbaier/.conda/envs/dhsrl4/lib/python3.9/site-packages/torch/nn/parallel/distributed.py", line 1379, in _sync_params
    self._distributed_broadcast_coalesced(
  File "/sciclone/home20/hmbaier/.conda/envs/dhsrl4/lib/python3.9/site-packages/torch/nn/parallel/distributed.py", line 1334, in _distributed_broadcast_coalesced
    dist._broadcast_coalesced(
RuntimeError: [/opt/conda/conda-bld/pytorch_1634272107467/work/third_party/gloo/gloo/transport/tcp/pair.cc:598] Connection closed by peer [10.3.59.2]:11442
WARNING:torch.distributed.elastic.multiprocessing.api:Sending process 173410 closing signal SIGTERM
WARNING:torch.distributed.elastic.multiprocessing.api:Sending process 173412 closing signal SIGTERM
WARNING:torch.distributed.elastic.multiprocessing.api:Sending process 173414 closing signal SIGTERM
WARNING:torch.distributed.elastic.multiprocessing.api:Sending process 173416 closing signal SIGTERM
WARNING:torch.distributed.elastic.multiprocessing.api:Sending process 173418 closing signal SIGTERM
WARNING:torch.distributed.elastic.multiprocessing.api:Sending process 173422 closing signal SIGTERM
ERROR:torch.distributed.elastic.multiprocessing.api:failed (exitcode: 1) local_rank: 2 (pid: 173411) of binary: /sciclone/home20/hmbaier/.conda/envs/dhsrl4/bin/python
ERROR:torch.distributed.elastic.agent.server.api:Error waiting on exit barrier. Elapsed: 0.0010271072387695312 seconds
Traceback (most recent call last):
  File "/sciclone/home20/hmbaier/.conda/envs/dhsrl4/lib/python3.9/site-packages/torch/distributed/elastic/agent/server/api.py", line 899, in _exit_barrier
    store_util.barrier(
  File "/sciclone/home20/hmbaier/.conda/envs/dhsrl4/lib/python3.9/site-packages/torch/distributed/elastic/utils/store.py", line 67, in barrier
    synchronize(store, data, rank, world_size, key_prefix, barrier_timeout)
  File "/sciclone/home20/hmbaier/.conda/envs/dhsrl4/lib/python3.9/site-packages/torch/distributed/elastic/utils/store.py", line 53, in synchronize
    agent_data = get_all(store, key_prefix, world_size)
  File "/sciclone/home20/hmbaier/.conda/envs/dhsrl4/lib/python3.9/site-packages/torch/distributed/elastic/utils/store.py", line 31, in get_all
    data = store.get(f"{prefix}{idx}")
RuntimeError: Connection reset by peer
WARNING:torch.distributed.elastic.rendezvous.dynamic_rendezvous:The node 'mlt004.sciclone.wm.edu_173402_0' has failed to shutdown the rendezvous '790876' due to an error of type RendezvousConnectionError.
ERROR:torch.distributed.elastic.multiprocessing.errors.error_handler:no error file defined for parent, to copy child error file (/local/scr/hmbaier/TMPDIR/torchelastic_ru6z6ucj/790876_zq3gxtp6/attempt_0/2/error.json)
Traceback (most recent call last):
  File "/sciclone/home20/hmbaier/.conda/envs/dhsrl4/bin/torchrun", line 33, in <module>
    sys.exit(load_entry_point('torch==1.10.0', 'console_scripts', 'torchrun')())
  File "/sciclone/home20/hmbaier/.conda/envs/dhsrl4/lib/python3.9/site-packages/torch/distributed/elastic/multiprocessing/errors/__init__.py", line 345, in wrapper
    return f(*args, **kwargs)
  File "/sciclone/home20/hmbaier/.conda/envs/dhsrl4/lib/python3.9/site-packages/torch/distributed/run.py", line 719, in main
    run(args)
  File "/sciclone/home20/hmbaier/.conda/envs/dhsrl4/lib/python3.9/site-packages/torch/distributed/run.py", line 710, in run
    elastic_launch(
  File "/sciclone/home20/hmbaier/.conda/envs/dhsrl4/lib/python3.9/site-packages/torch/distributed/launcher/api.py", line 131, in __call__
    return launch_agent(self._config, self._entrypoint, list(args))
  File "/sciclone/home20/hmbaier/.conda/envs/dhsrl4/lib/python3.9/site-packages/torch/distributed/launcher/api.py", line 259, in launch_agent
    raise ChildFailedError(
torch.distributed.elastic.multiprocessing.errors.ChildFailedError: 
============================================================
/sciclone/home20/hmbaier/tm/run.py FAILED
------------------------------------------------------------
Failures:
[0]:
  time      : 2022-03-10_15:54:51
  host      : mlt004.sciclone.wm.edu
  rank      : 96 (local_rank: 0)
  exitcode  : 1 (pid: 173409)
  error_file: /local/scr/hmbaier/TMPDIR/torchelastic_ru6z6ucj/790876_zq3gxtp6/attempt_0/0/error.json
  traceback : Traceback (most recent call last):
    File "/sciclone/home20/hmbaier/.conda/envs/dhsrl4/lib/python3.9/site-packages/torch/distributed/elastic/multiprocessing/errors/__init__.py", line 345, in wrapper
      return f(*args, **kwargs)
    File "/sciclone/home20/hmbaier/tm/run.py", line 100, in main
      ddp_model = DDP(model, process_group = model_group)
    File "/sciclone/home20/hmbaier/.conda/envs/dhsrl4/lib/python3.9/site-packages/torch/nn/parallel/distributed.py", line 580, in __init__
      self._sync_params_and_buffers(authoritative_rank=0)
    File "/sciclone/home20/hmbaier/.conda/envs/dhsrl4/lib/python3.9/site-packages/torch/nn/parallel/distributed.py", line 597, in _sync_params_and_buffers
      self._distributed_broadcast_coalesced(
    File "/sciclone/home20/hmbaier/.conda/envs/dhsrl4/lib/python3.9/site-packages/torch/nn/parallel/distributed.py", line 1334, in _distributed_broadcast_coalesced
      dist._broadcast_coalesced(
  RuntimeError: [/opt/conda/conda-bld/pytorch_1634272107467/work/third_party/gloo/gloo/transport/tcp/pair.cc:598] Connection closed by peer [10.3.59.2]:30367
  
[2]:
  time      : 2022-03-10_15:54:50
  host      : mlt004.sciclone.wm.edu
  rank      : 100 (local_rank: 4)
  exitcode  : 1 (pid: 173413)
  error_file: /local/scr/hmbaier/TMPDIR/torchelastic_ru6z6ucj/790876_zq3gxtp6/attempt_0/4/error.json
  traceback : Traceback (most recent call last):
    File "/sciclone/home20/hmbaier/.conda/envs/dhsrl4/lib/python3.9/site-packages/torch/distributed/elastic/multiprocessing/errors/__init__.py", line 345, in wrapper
      return f(*args, **kwargs)
    File "/sciclone/home20/hmbaier/tm/run.py", line 100, in main
      ddp_model = DDP(model, process_group = model_group)
    File "/sciclone/home20/hmbaier/.conda/envs/dhsrl4/lib/python3.9/site-packages/torch/nn/parallel/distributed.py", line 580, in __init__
      self._sync_params_and_buffers(authoritative_rank=0)
    File "/sciclone/home20/hmbaier/.conda/envs/dhsrl4/lib/python3.9/site-packages/torch/nn/parallel/distributed.py", line 597, in _sync_params_and_buffers
      self._distributed_broadcast_coalesced(
    File "/sciclone/home20/hmbaier/.conda/envs/dhsrl4/lib/python3.9/site-packages/torch/nn/parallel/distributed.py", line 1334, in _distributed_broadcast_coalesced
      dist._broadcast_coalesced(
  RuntimeError: [/opt/conda/conda-bld/pytorch_1634272107467/work/third_party/gloo/gloo/transport/tcp/pair.cc:598] Connection closed by peer [10.3.59.2]:62118
  
[3]:
  time      : 2022-03-10_15:54:50
  host      : mlt004.sciclone.wm.edu
  rank      : 102 (local_rank: 6)
  exitcode  : 1 (pid: 173415)
  error_file: /local/scr/hmbaier/TMPDIR/torchelastic_ru6z6ucj/790876_zq3gxtp6/attempt_0/6/error.json
  traceback : Traceback (most recent call last):
    File "/sciclone/home20/hmbaier/.conda/envs/dhsrl4/lib/python3.9/site-packages/torch/distributed/elastic/multiprocessing/errors/__init__.py", line 345, in wrapper
      return f(*args, **kwargs)
    File "/sciclone/home20/hmbaier/tm/run.py", line 100, in main
      ddp_model = DDP(model, process_group = model_group)
    File "/sciclone/home20/hmbaier/.conda/envs/dhsrl4/lib/python3.9/site-packages/torch/nn/parallel/distributed.py", line 580, in __init__
      self._sync_params_and_buffers(authoritative_rank=0)
    File "/sciclone/home20/hmbaier/.conda/envs/dhsrl4/lib/python3.9/site-packages/torch/nn/parallel/distributed.py", line 597, in _sync_params_and_buffers
      self._distributed_broadcast_coalesced(
    File "/sciclone/home20/hmbaier/.conda/envs/dhsrl4/lib/python3.9/site-packages/torch/nn/parallel/distributed.py", line 1334, in _distributed_broadcast_coalesced
      dist._broadcast_coalesced(
  RuntimeError: [/opt/conda/conda-bld/pytorch_1634272107467/work/third_party/gloo/gloo/transport/tcp/pair.cc:598] Connection closed by peer [10.3.59.2]:7861
  
[4]:
  time      : 2022-03-10_15:54:50
  host      : mlt004.sciclone.wm.edu
  rank      : 104 (local_rank: 8)
  exitcode  : 1 (pid: 173417)
  error_file: /local/scr/hmbaier/TMPDIR/torchelastic_ru6z6ucj/790876_zq3gxtp6/attempt_0/8/error.json
  traceback : Traceback (most recent call last):
    File "/sciclone/home20/hmbaier/.conda/envs/dhsrl4/lib/python3.9/site-packages/torch/distributed/elastic/multiprocessing/errors/__init__.py", line 345, in wrapper
      return f(*args, **kwargs)
    File "/sciclone/home20/hmbaier/tm/run.py", line 100, in main
      ddp_model = DDP(model, process_group = model_group)
    File "/sciclone/home20/hmbaier/.conda/envs/dhsrl4/lib/python3.9/site-packages/torch/nn/parallel/distributed.py", line 580, in __init__
      self._sync_params_and_buffers(authoritative_rank=0)
    File "/sciclone/home20/hmbaier/.conda/envs/dhsrl4/lib/python3.9/site-packages/torch/nn/parallel/distributed.py", line 597, in _sync_params_and_buffers
      self._distributed_broadcast_coalesced(
    File "/sciclone/home20/hmbaier/.conda/envs/dhsrl4/lib/python3.9/site-packages/torch/nn/parallel/distributed.py", line 1334, in _distributed_broadcast_coalesced
      dist._broadcast_coalesced(
  RuntimeError: [/opt/conda/conda-bld/pytorch_1634272107467/work/third_party/gloo/gloo/transport/tcp/pair.cc:598] Connection closed by peer [10.3.59.2]:2956
  
[5]:
  time      : 2022-03-10_15:54:50
  host      : mlt004.sciclone.wm.edu
  rank      : 106 (local_rank: 10)
  exitcode  : 1 (pid: 173419)
  error_file: /local/scr/hmbaier/TMPDIR/torchelastic_ru6z6ucj/790876_zq3gxtp6/attempt_0/10/error.json
  traceback : Traceback (most recent call last):
    File "/sciclone/home20/hmbaier/.conda/envs/dhsrl4/lib/python3.9/site-packages/torch/distributed/elastic/multiprocessing/errors/__init__.py", line 345, in wrapper
      return f(*args, **kwargs)
    File "/sciclone/home20/hmbaier/tm/run.py", line 100, in main
      ddp_model = DDP(model, process_group = model_group)
    File "/sciclone/home20/hmbaier/.conda/envs/dhsrl4/lib/python3.9/site-packages/torch/nn/parallel/distributed.py", line 580, in __init__
      self._sync_params_and_buffers(authoritative_rank=0)
    File "/sciclone/home20/hmbaier/.conda/envs/dhsrl4/lib/python3.9/site-packages/torch/nn/parallel/distributed.py", line 597, in _sync_params_and_buffers
      self._distributed_broadcast_coalesced(
    File "/sciclone/home20/hmbaier/.conda/envs/dhsrl4/lib/python3.9/site-packages/torch/nn/parallel/distributed.py", line 1334, in _distributed_broadcast_coalesced
      dist._broadcast_coalesced(
  RuntimeError: [/opt/conda/conda-bld/pytorch_1634272107467/work/third_party/gloo/gloo/transport/tcp/pair.cc:598] Connection closed by peer [10.3.59.2]:27786
  
[6]:
  time      : 2022-03-10_15:54:51
  host      : mlt004.sciclone.wm.edu
  rank      : 107 (local_rank: 11)
  exitcode  : 1 (pid: 173420)
  error_file: /local/scr/hmbaier/TMPDIR/torchelastic_ru6z6ucj/790876_zq3gxtp6/attempt_0/11/error.json
  traceback : Traceback (most recent call last):
    File "/sciclone/home20/hmbaier/.conda/envs/dhsrl4/lib/python3.9/site-packages/torch/distributed/elastic/multiprocessing/errors/__init__.py", line 345, in wrapper
      return f(*args, **kwargs)
    File "/sciclone/home20/hmbaier/tm/run.py", line 100, in main
      ddp_model = DDP(model, process_group = model_group)
    File "/sciclone/home20/hmbaier/.conda/envs/dhsrl4/lib/python3.9/site-packages/torch/nn/parallel/distributed.py", line 580, in __init__
      self._sync_params_and_buffers(authoritative_rank=0)
    File "/sciclone/home20/hmbaier/.conda/envs/dhsrl4/lib/python3.9/site-packages/torch/nn/parallel/distributed.py", line 597, in _sync_params_and_buffers
      self._distributed_broadcast_coalesced(
    File "/sciclone/home20/hmbaier/.conda/envs/dhsrl4/lib/python3.9/site-packages/torch/nn/parallel/distributed.py", line 1334, in _distributed_broadcast_coalesced
      dist._broadcast_coalesced(
  RuntimeError: [/opt/conda/conda-bld/pytorch_1634272107467/work/third_party/gloo/gloo/transport/tcp/pair.cc:598] Connection closed by peer [10.3.59.2]:6554
  
[7]:
  time      : 2022-03-10_15:54:50
  host      : mlt004.sciclone.wm.edu
  rank      : 108 (local_rank: 12)
  exitcode  : 1 (pid: 173421)
  error_file: /local/scr/hmbaier/TMPDIR/torchelastic_ru6z6ucj/790876_zq3gxtp6/attempt_0/12/error.json
  traceback : Traceback (most recent call last):
    File "/sciclone/home20/hmbaier/.conda/envs/dhsrl4/lib/python3.9/site-packages/torch/distributed/elastic/multiprocessing/errors/__init__.py", line 345, in wrapper
      return f(*args, **kwargs)
    File "/sciclone/home20/hmbaier/tm/run.py", line 100, in main
      ddp_model = DDP(model, process_group = model_group)
    File "/sciclone/home20/hmbaier/.conda/envs/dhsrl4/lib/python3.9/site-packages/torch/nn/parallel/distributed.py", line 580, in __init__
      self._sync_params_and_buffers(authoritative_rank=0)
    File "/sciclone/home20/hmbaier/.conda/envs/dhsrl4/lib/python3.9/site-packages/torch/nn/parallel/distributed.py", line 597, in _sync_params_and_buffers
      self._distributed_broadcast_coalesced(
    File "/sciclone/home20/hmbaier/.conda/envs/dhsrl4/lib/python3.9/site-packages/torch/nn/parallel/distributed.py", line 1334, in _distributed_broadcast_coalesced
      dist._broadcast_coalesced(
  RuntimeError: [/opt/conda/conda-bld/pytorch_1634272107467/work/third_party/gloo/gloo/transport/tcp/pair.cc:598] Connection closed by peer [10.3.59.2]:32420
  
[8]:
  time      : 2022-03-10_15:54:51
  host      : mlt004.sciclone.wm.edu
  rank      : 110 (local_rank: 14)
  exitcode  : 1 (pid: 173423)
  error_file: /local/scr/hmbaier/TMPDIR/torchelastic_ru6z6ucj/790876_zq3gxtp6/attempt_0/14/error.json
  traceback : Traceback (most recent call last):
    File "/sciclone/home20/hmbaier/.conda/envs/dhsrl4/lib/python3.9/site-packages/torch/distributed/elastic/multiprocessing/errors/__init__.py", line 345, in wrapper
      return f(*args, **kwargs)
    File "/sciclone/home20/hmbaier/tm/run.py", line 100, in main
      ddp_model = DDP(model, process_group = model_group)
    File "/sciclone/home20/hmbaier/.conda/envs/dhsrl4/lib/python3.9/site-packages/torch/nn/parallel/distributed.py", line 580, in __init__
      self._sync_params_and_buffers(authoritative_rank=0)
    File "/sciclone/home20/hmbaier/.conda/envs/dhsrl4/lib/python3.9/site-packages/torch/nn/parallel/distributed.py", line 597, in _sync_params_and_buffers
      self._distributed_broadcast_coalesced(
    File "/sciclone/home20/hmbaier/.conda/envs/dhsrl4/lib/python3.9/site-packages/torch/nn/parallel/distributed.py", line 1334, in _distributed_broadcast_coalesced
      dist._broadcast_coalesced(
  RuntimeError: [/opt/conda/conda-bld/pytorch_1634272107467/work/third_party/gloo/gloo/transport/tcp/pair.cc:598] Connection closed by peer [10.3.59.2]:56449
  
[9]:
  time      : 2022-03-10_15:54:51
  host      : mlt004.sciclone.wm.edu
  rank      : 111 (local_rank: 15)
  exitcode  : 1 (pid: 173424)
  error_file: /local/scr/hmbaier/TMPDIR/torchelastic_ru6z6ucj/790876_zq3gxtp6/attempt_0/15/error.json
  traceback : Traceback (most recent call last):
    File "/sciclone/home20/hmbaier/.conda/envs/dhsrl4/lib/python3.9/site-packages/torch/distributed/elastic/multiprocessing/errors/__init__.py", line 345, in wrapper
      return f(*args, **kwargs)
    File "/sciclone/home20/hmbaier/tm/run.py", line 122, in main
      output = ddp_model(input)
    File "/sciclone/home20/hmbaier/.conda/envs/dhsrl4/lib/python3.9/site-packages/torch/nn/modules/module.py", line 1102, in _call_impl
      return forward_call(*input, **kwargs)
    File "/sciclone/home20/hmbaier/.conda/envs/dhsrl4/lib/python3.9/site-packages/torch/nn/parallel/distributed.py", line 878, in forward
      self._sync_params()
    File "/sciclone/home20/hmbaier/.conda/envs/dhsrl4/lib/python3.9/site-packages/torch/nn/parallel/distributed.py", line 1379, in _sync_params
      self._distributed_broadcast_coalesced(
    File "/sciclone/home20/hmbaier/.conda/envs/dhsrl4/lib/python3.9/site-packages/torch/nn/parallel/distributed.py", line 1334, in _distributed_broadcast_coalesced
      dist._broadcast_coalesced(
  RuntimeError: [/opt/conda/conda-bld/pytorch_1634272107467/work/third_party/gloo/gloo/transport/tcp/pair.cc:598] Connection closed by peer [10.3.59.2]:14482
  
[10]:
  time      : 2022-03-10_15:54:51
  host      : mlt004.sciclone.wm.edu
  rank      : 112 (local_rank: 16)
  exitcode  : 1 (pid: 173425)
  error_file: /local/scr/hmbaier/TMPDIR/torchelastic_ru6z6ucj/790876_zq3gxtp6/attempt_0/16/error.json
  traceback : Traceback (most recent call last):
    File "/sciclone/home20/hmbaier/.conda/envs/dhsrl4/lib/python3.9/site-packages/torch/distributed/elastic/multiprocessing/errors/__init__.py", line 345, in wrapper
      return f(*args, **kwargs)
    File "/sciclone/home20/hmbaier/tm/run.py", line 100, in main
      ddp_model = DDP(model, process_group = model_group)
    File "/sciclone/home20/hmbaier/.conda/envs/dhsrl4/lib/python3.9/site-packages/torch/nn/parallel/distributed.py", line 580, in __init__
      self._sync_params_and_buffers(authoritative_rank=0)
    File "/sciclone/home20/hmbaier/.conda/envs/dhsrl4/lib/python3.9/site-packages/torch/nn/parallel/distributed.py", line 597, in _sync_params_and_buffers
      self._distributed_broadcast_coalesced(
    File "/sciclone/home20/hmbaier/.conda/envs/dhsrl4/lib/python3.9/site-packages/torch/nn/parallel/distributed.py", line 1334, in _distributed_broadcast_coalesced
      dist._broadcast_coalesced(
  RuntimeError: [/opt/conda/conda-bld/pytorch_1634272107467/work/third_party/gloo/gloo/transport/tcp/pair.cc:598] Connection closed by peer [10.3.59.2]:8881
  
[11]:
  time      : 2022-03-10_15:54:51
  host      : mlt004.sciclone.wm.edu
  rank      : 113 (local_rank: 17)
  exitcode  : 1 (pid: 173426)
  error_file: /local/scr/hmbaier/TMPDIR/torchelastic_ru6z6ucj/790876_zq3gxtp6/attempt_0/17/error.json
  traceback : Traceback (most recent call last):
    File "/sciclone/home20/hmbaier/.conda/envs/dhsrl4/lib/python3.9/site-packages/torch/distributed/elastic/multiprocessing/errors/__init__.py", line 345, in wrapper
      return f(*args, **kwargs)
    File "/sciclone/home20/hmbaier/tm/run.py", line 122, in main
      output = ddp_model(input)
    File "/sciclone/home20/hmbaier/.conda/envs/dhsrl4/lib/python3.9/site-packages/torch/nn/modules/module.py", line 1102, in _call_impl
      return forward_call(*input, **kwargs)
    File "/sciclone/home20/hmbaier/.conda/envs/dhsrl4/lib/python3.9/site-packages/torch/nn/parallel/distributed.py", line 878, in forward
      self._sync_params()
    File "/sciclone/home20/hmbaier/.conda/envs/dhsrl4/lib/python3.9/site-packages/torch/nn/parallel/distributed.py", line 1379, in _sync_params
      self._distributed_broadcast_coalesced(
    File "/sciclone/home20/hmbaier/.conda/envs/dhsrl4/lib/python3.9/site-packages/torch/nn/parallel/distributed.py", line 1334, in _distributed_broadcast_coalesced
      dist._broadcast_coalesced(
  RuntimeError: [/opt/conda/conda-bld/pytorch_1634272107467/work/third_party/gloo/gloo/transport/tcp/pair.cc:598] Connection closed by peer [10.3.59.2]:15260
  
[12]:
  time      : 2022-03-10_15:54:51
  host      : mlt004.sciclone.wm.edu
  rank      : 114 (local_rank: 18)
  exitcode  : 1 (pid: 173427)
  error_file: /local/scr/hmbaier/TMPDIR/torchelastic_ru6z6ucj/790876_zq3gxtp6/attempt_0/18/error.json
  traceback : Traceback (most recent call last):
    File "/sciclone/home20/hmbaier/.conda/envs/dhsrl4/lib/python3.9/site-packages/torch/distributed/elastic/multiprocessing/errors/__init__.py", line 345, in wrapper
      return f(*args, **kwargs)
    File "/sciclone/home20/hmbaier/tm/run.py", line 100, in main
      ddp_model = DDP(model, process_group = model_group)
    File "/sciclone/home20/hmbaier/.conda/envs/dhsrl4/lib/python3.9/site-packages/torch/nn/parallel/distributed.py", line 580, in __init__
      self._sync_params_and_buffers(authoritative_rank=0)
    File "/sciclone/home20/hmbaier/.conda/envs/dhsrl4/lib/python3.9/site-packages/torch/nn/parallel/distributed.py", line 597, in _sync_params_and_buffers
      self._distributed_broadcast_coalesced(
    File "/sciclone/home20/hmbaier/.conda/envs/dhsrl4/lib/python3.9/site-packages/torch/nn/parallel/distributed.py", line 1334, in _distributed_broadcast_coalesced
      dist._broadcast_coalesced(
  RuntimeError: [/opt/conda/conda-bld/pytorch_1634272107467/work/third_party/gloo/gloo/transport/tcp/pair.cc:598] Connection closed by peer [10.3.59.2]:34694
  
[13]:
  time      : 2022-03-10_15:54:51
  host      : mlt004.sciclone.wm.edu
  rank      : 115 (local_rank: 19)
  exitcode  : 1 (pid: 173428)
  error_file: /local/scr/hmbaier/TMPDIR/torchelastic_ru6z6ucj/790876_zq3gxtp6/attempt_0/19/error.json
  traceback : Traceback (most recent call last):
    File "/sciclone/home20/hmbaier/.conda/envs/dhsrl4/lib/python3.9/site-packages/torch/distributed/elastic/multiprocessing/errors/__init__.py", line 345, in wrapper
      return f(*args, **kwargs)
    File "/sciclone/home20/hmbaier/tm/run.py", line 100, in main
      ddp_model = DDP(model, process_group = model_group)
    File "/sciclone/home20/hmbaier/.conda/envs/dhsrl4/lib/python3.9/site-packages/torch/nn/parallel/distributed.py", line 580, in __init__
      self._sync_params_and_buffers(authoritative_rank=0)
    File "/sciclone/home20/hmbaier/.conda/envs/dhsrl4/lib/python3.9/site-packages/torch/nn/parallel/distributed.py", line 597, in _sync_params_and_buffers
      self._distributed_broadcast_coalesced(
    File "/sciclone/home20/hmbaier/.conda/envs/dhsrl4/lib/python3.9/site-packages/torch/nn/parallel/distributed.py", line 1334, in _distributed_broadcast_coalesced
      dist._broadcast_coalesced(
  RuntimeError: [/opt/conda/conda-bld/pytorch_1634272107467/work/third_party/gloo/gloo/transport/tcp/pair.cc:598] Connection closed by peer [10.3.59.2]:64410
  
[14]:
  time      : 2022-03-10_15:54:51
  host      : mlt004.sciclone.wm.edu
  rank      : 116 (local_rank: 20)
  exitcode  : 1 (pid: 173429)
  error_file: /local/scr/hmbaier/TMPDIR/torchelastic_ru6z6ucj/790876_zq3gxtp6/attempt_0/20/error.json
  traceback : Traceback (most recent call last):
    File "/sciclone/home20/hmbaier/.conda/envs/dhsrl4/lib/python3.9/site-packages/torch/distributed/elastic/multiprocessing/errors/__init__.py", line 345, in wrapper
      return f(*args, **kwargs)
    File "/sciclone/home20/hmbaier/tm/run.py", line 100, in main
      ddp_model = DDP(model, process_group = model_group)
    File "/sciclone/home20/hmbaier/.conda/envs/dhsrl4/lib/python3.9/site-packages/torch/nn/parallel/distributed.py", line 580, in __init__
      self._sync_params_and_buffers(authoritative_rank=0)
    File "/sciclone/home20/hmbaier/.conda/envs/dhsrl4/lib/python3.9/site-packages/torch/nn/parallel/distributed.py", line 597, in _sync_params_and_buffers
      self._distributed_broadcast_coalesced(
    File "/sciclone/home20/hmbaier/.conda/envs/dhsrl4/lib/python3.9/site-packages/torch/nn/parallel/distributed.py", line 1334, in _distributed_broadcast_coalesced
      dist._broadcast_coalesced(
  RuntimeError: [/opt/conda/conda-bld/pytorch_1634272107467/work/third_party/gloo/gloo/transport/tcp/pair.cc:598] Connection closed by peer [10.3.59.2]:50048
  
[15]:
  time      : 2022-03-10_15:54:51
  host      : mlt004.sciclone.wm.edu
  rank      : 117 (local_rank: 21)
  exitcode  : 1 (pid: 173430)
  error_file: /local/scr/hmbaier/TMPDIR/torchelastic_ru6z6ucj/790876_zq3gxtp6/attempt_0/21/error.json
  traceback : Traceback (most recent call last):
    File "/sciclone/home20/hmbaier/.conda/envs/dhsrl4/lib/python3.9/site-packages/torch/distributed/elastic/multiprocessing/errors/__init__.py", line 345, in wrapper
      return f(*args, **kwargs)
    File "/sciclone/home20/hmbaier/tm/run.py", line 122, in main
      output = ddp_model(input)
    File "/sciclone/home20/hmbaier/.conda/envs/dhsrl4/lib/python3.9/site-packages/torch/nn/modules/module.py", line 1102, in _call_impl
      return forward_call(*input, **kwargs)
    File "/sciclone/home20/hmbaier/.conda/envs/dhsrl4/lib/python3.9/site-packages/torch/nn/parallel/distributed.py", line 878, in forward
      self._sync_params()
    File "/sciclone/home20/hmbaier/.conda/envs/dhsrl4/lib/python3.9/site-packages/torch/nn/parallel/distributed.py", line 1379, in _sync_params
      self._distributed_broadcast_coalesced(
    File "/sciclone/home20/hmbaier/.conda/envs/dhsrl4/lib/python3.9/site-packages/torch/nn/parallel/distributed.py", line 1334, in _distributed_broadcast_coalesced
      dist._broadcast_coalesced(
  RuntimeError: [/opt/conda/conda-bld/pytorch_1634272107467/work/third_party/gloo/gloo/transport/tcp/pair.cc:598] Connection closed by peer [10.3.59.2]:10371
  
[16]:
  time      : 2022-03-10_15:54:51
  host      : mlt004.sciclone.wm.edu
  rank      : 118 (local_rank: 22)
  exitcode  : 1 (pid: 173431)
  error_file: /local/scr/hmbaier/TMPDIR/torchelastic_ru6z6ucj/790876_zq3gxtp6/attempt_0/22/error.json
  traceback : Traceback (most recent call last):
    File "/sciclone/home20/hmbaier/.conda/envs/dhsrl4/lib/python3.9/site-packages/torch/distributed/elastic/multiprocessing/errors/__init__.py", line 345, in wrapper
      return f(*args, **kwargs)
    File "/sciclone/home20/hmbaier/tm/run.py", line 100, in main
      ddp_model = DDP(model, process_group = model_group)
    File "/sciclone/home20/hmbaier/.conda/envs/dhsrl4/lib/python3.9/site-packages/torch/nn/parallel/distributed.py", line 580, in __init__
      self._sync_params_and_buffers(authoritative_rank=0)
    File "/sciclone/home20/hmbaier/.conda/envs/dhsrl4/lib/python3.9/site-packages/torch/nn/parallel/distributed.py", line 597, in _sync_params_and_buffers
      self._distributed_broadcast_coalesced(
    File "/sciclone/home20/hmbaier/.conda/envs/dhsrl4/lib/python3.9/site-packages/torch/nn/parallel/distributed.py", line 1334, in _distributed_broadcast_coalesced
      dist._broadcast_coalesced(
  RuntimeError: [/opt/conda/conda-bld/pytorch_1634272107467/work/third_party/gloo/gloo/transport/tcp/pair.cc:598] Connection closed by peer [10.3.59.2]:36254
  
[17]:
  time      : 2022-03-10_15:54:51
  host      : mlt004.sciclone.wm.edu
  rank      : 119 (local_rank: 23)
  exitcode  : 1 (pid: 173432)
  error_file: /local/scr/hmbaier/TMPDIR/torchelastic_ru6z6ucj/790876_zq3gxtp6/attempt_0/23/error.json
  traceback : Traceback (most recent call last):
    File "/sciclone/home20/hmbaier/.conda/envs/dhsrl4/lib/python3.9/site-packages/torch/distributed/elastic/multiprocessing/errors/__init__.py", line 345, in wrapper
      return f(*args, **kwargs)
    File "/sciclone/home20/hmbaier/tm/run.py", line 122, in main
      output = ddp_model(input)
    File "/sciclone/home20/hmbaier/.conda/envs/dhsrl4/lib/python3.9/site-packages/torch/nn/modules/module.py", line 1102, in _call_impl
      return forward_call(*input, **kwargs)
    File "/sciclone/home20/hmbaier/.conda/envs/dhsrl4/lib/python3.9/site-packages/torch/nn/parallel/distributed.py", line 878, in forward
      self._sync_params()
    File "/sciclone/home20/hmbaier/.conda/envs/dhsrl4/lib/python3.9/site-packages/torch/nn/parallel/distributed.py", line 1379, in _sync_params
      self._distributed_broadcast_coalesced(
    File "/sciclone/home20/hmbaier/.conda/envs/dhsrl4/lib/python3.9/site-packages/torch/nn/parallel/distributed.py", line 1334, in _distributed_broadcast_coalesced
      dist._broadcast_coalesced(
  RuntimeError: [/opt/conda/conda-bld/pytorch_1634272107467/work/third_party/gloo/gloo/transport/tcp/pair.cc:598] Connection closed by peer [10.3.59.2]:35727
  
[18]:
  time      : 2022-03-10_15:54:51
  host      : mlt004.sciclone.wm.edu
  rank      : 120 (local_rank: 24)
  exitcode  : 1 (pid: 173433)
  error_file: /local/scr/hmbaier/TMPDIR/torchelastic_ru6z6ucj/790876_zq3gxtp6/attempt_0/24/error.json
  traceback : Traceback (most recent call last):
    File "/sciclone/home20/hmbaier/.conda/envs/dhsrl4/lib/python3.9/site-packages/torch/distributed/elastic/multiprocessing/errors/__init__.py", line 345, in wrapper
      return f(*args, **kwargs)
    File "/sciclone/home20/hmbaier/tm/run.py", line 100, in main
      ddp_model = DDP(model, process_group = model_group)
    File "/sciclone/home20/hmbaier/.conda/envs/dhsrl4/lib/python3.9/site-packages/torch/nn/parallel/distributed.py", line 580, in __init__
      self._sync_params_and_buffers(authoritative_rank=0)
    File "/sciclone/home20/hmbaier/.conda/envs/dhsrl4/lib/python3.9/site-packages/torch/nn/parallel/distributed.py", line 597, in _sync_params_and_buffers
      self._distributed_broadcast_coalesced(
    File "/sciclone/home20/hmbaier/.conda/envs/dhsrl4/lib/python3.9/site-packages/torch/nn/parallel/distributed.py", line 1334, in _distributed_broadcast_coalesced
      dist._broadcast_coalesced(
  RuntimeError: [/opt/conda/conda-bld/pytorch_1634272107467/work/third_party/gloo/gloo/transport/tcp/pair.cc:598] Connection closed by peer [10.3.59.2]:14255
  
[19]:
  time      : 2022-03-10_15:54:51
  host      : mlt004.sciclone.wm.edu
  rank      : 121 (local_rank: 25)
  exitcode  : 1 (pid: 173434)
  error_file: /local/scr/hmbaier/TMPDIR/torchelastic_ru6z6ucj/790876_zq3gxtp6/attempt_0/25/error.json
  traceback : Traceback (most recent call last):
    File "/sciclone/home20/hmbaier/.conda/envs/dhsrl4/lib/python3.9/site-packages/torch/distributed/elastic/multiprocessing/errors/__init__.py", line 345, in wrapper
      return f(*args, **kwargs)
    File "/sciclone/home20/hmbaier/tm/run.py", line 122, in main
      output = ddp_model(input)
    File "/sciclone/home20/hmbaier/.conda/envs/dhsrl4/lib/python3.9/site-packages/torch/nn/modules/module.py", line 1102, in _call_impl
      return forward_call(*input, **kwargs)
    File "/sciclone/home20/hmbaier/.conda/envs/dhsrl4/lib/python3.9/site-packages/torch/nn/parallel/distributed.py", line 878, in forward
      self._sync_params()
    File "/sciclone/home20/hmbaier/.conda/envs/dhsrl4/lib/python3.9/site-packages/torch/nn/parallel/distributed.py", line 1379, in _sync_params
      self._distributed_broadcast_coalesced(
    File "/sciclone/home20/hmbaier/.conda/envs/dhsrl4/lib/python3.9/site-packages/torch/nn/parallel/distributed.py", line 1334, in _distributed_broadcast_coalesced
      dist._broadcast_coalesced(
  RuntimeError: [/opt/conda/conda-bld/pytorch_1634272107467/work/third_party/gloo/gloo/transport/tcp/pair.cc:598] Connection closed by peer [10.3.59.2]:26797
  
[20]:
  time      : 2022-03-10_15:54:51
  host      : mlt004.sciclone.wm.edu
  rank      : 122 (local_rank: 26)
  exitcode  : 1 (pid: 173436)
  error_file: /local/scr/hmbaier/TMPDIR/torchelastic_ru6z6ucj/790876_zq3gxtp6/attempt_0/26/error.json
  traceback : Traceback (most recent call last):
    File "/sciclone/home20/hmbaier/.conda/envs/dhsrl4/lib/python3.9/site-packages/torch/distributed/elastic/multiprocessing/errors/__init__.py", line 345, in wrapper
      return f(*args, **kwargs)
    File "/sciclone/home20/hmbaier/tm/run.py", line 100, in main
      ddp_model = DDP(model, process_group = model_group)
    File "/sciclone/home20/hmbaier/.conda/envs/dhsrl4/lib/python3.9/site-packages/torch/nn/parallel/distributed.py", line 580, in __init__
      self._sync_params_and_buffers(authoritative_rank=0)
    File "/sciclone/home20/hmbaier/.conda/envs/dhsrl4/lib/python3.9/site-packages/torch/nn/parallel/distributed.py", line 597, in _sync_params_and_buffers
      self._distributed_broadcast_coalesced(
    File "/sciclone/home20/hmbaier/.conda/envs/dhsrl4/lib/python3.9/site-packages/torch/nn/parallel/distributed.py", line 1334, in _distributed_broadcast_coalesced
      dist._broadcast_coalesced(
  RuntimeError: [/opt/conda/conda-bld/pytorch_1634272107467/work/third_party/gloo/gloo/transport/tcp/pair.cc:598] Connection closed by peer [10.3.59.2]:43162
  
[21]:
  time      : 2022-03-10_15:54:51
  host      : mlt004.sciclone.wm.edu
  rank      : 123 (local_rank: 27)
  exitcode  : 1 (pid: 173437)
  error_file: /local/scr/hmbaier/TMPDIR/torchelastic_ru6z6ucj/790876_zq3gxtp6/attempt_0/27/error.json
  traceback : Traceback (most recent call last):
    File "/sciclone/home20/hmbaier/.conda/envs/dhsrl4/lib/python3.9/site-packages/torch/distributed/elastic/multiprocessing/errors/__init__.py", line 345, in wrapper
      return f(*args, **kwargs)
    File "/sciclone/home20/hmbaier/tm/run.py", line 100, in main
      ddp_model = DDP(model, process_group = model_group)
    File "/sciclone/home20/hmbaier/.conda/envs/dhsrl4/lib/python3.9/site-packages/torch/nn/parallel/distributed.py", line 580, in __init__
      self._sync_params_and_buffers(authoritative_rank=0)
    File "/sciclone/home20/hmbaier/.conda/envs/dhsrl4/lib/python3.9/site-packages/torch/nn/parallel/distributed.py", line 597, in _sync_params_and_buffers
      self._distributed_broadcast_coalesced(
    File "/sciclone/home20/hmbaier/.conda/envs/dhsrl4/lib/python3.9/site-packages/torch/nn/parallel/distributed.py", line 1334, in _distributed_broadcast_coalesced
      dist._broadcast_coalesced(
  RuntimeError: [/opt/conda/conda-bld/pytorch_1634272107467/work/third_party/gloo/gloo/transport/tcp/pair.cc:598] Connection closed by peer [10.3.59.2]:12174
  
[22]:
  time      : 2022-03-10_15:54:51
  host      : mlt004.sciclone.wm.edu
  rank      : 124 (local_rank: 28)
  exitcode  : 1 (pid: 173438)
  error_file: /local/scr/hmbaier/TMPDIR/torchelastic_ru6z6ucj/790876_zq3gxtp6/attempt_0/28/error.json
  traceback : Traceback (most recent call last):
    File "/sciclone/home20/hmbaier/.conda/envs/dhsrl4/lib/python3.9/site-packages/torch/distributed/elastic/multiprocessing/errors/__init__.py", line 345, in wrapper
      return f(*args, **kwargs)
    File "/sciclone/home20/hmbaier/tm/run.py", line 100, in main
      ddp_model = DDP(model, process_group = model_group)
    File "/sciclone/home20/hmbaier/.conda/envs/dhsrl4/lib/python3.9/site-packages/torch/nn/parallel/distributed.py", line 580, in __init__
      self._sync_params_and_buffers(authoritative_rank=0)
    File "/sciclone/home20/hmbaier/.conda/envs/dhsrl4/lib/python3.9/site-packages/torch/nn/parallel/distributed.py", line 597, in _sync_params_and_buffers
      self._distributed_broadcast_coalesced(
    File "/sciclone/home20/hmbaier/.conda/envs/dhsrl4/lib/python3.9/site-packages/torch/nn/parallel/distributed.py", line 1334, in _distributed_broadcast_coalesced
      dist._broadcast_coalesced(
  RuntimeError: [/opt/conda/conda-bld/pytorch_1634272107467/work/third_party/gloo/gloo/transport/tcp/pair.cc:598] Connection closed by peer [10.3.59.2]:47280
  
[23]:
  time      : 2022-03-10_15:54:51
  host      : mlt004.sciclone.wm.edu
  rank      : 125 (local_rank: 29)
  exitcode  : 1 (pid: 173439)
  error_file: /local/scr/hmbaier/TMPDIR/torchelastic_ru6z6ucj/790876_zq3gxtp6/attempt_0/29/error.json
  traceback : Traceback (most recent call last):
    File "/sciclone/home20/hmbaier/.conda/envs/dhsrl4/lib/python3.9/site-packages/torch/distributed/elastic/multiprocessing/errors/__init__.py", line 345, in wrapper
      return f(*args, **kwargs)
    File "/sciclone/home20/hmbaier/tm/run.py", line 122, in main
      output = ddp_model(input)
    File "/sciclone/home20/hmbaier/.conda/envs/dhsrl4/lib/python3.9/site-packages/torch/nn/modules/module.py", line 1102, in _call_impl
      return forward_call(*input, **kwargs)
    File "/sciclone/home20/hmbaier/.conda/envs/dhsrl4/lib/python3.9/site-packages/torch/nn/parallel/distributed.py", line 878, in forward
      self._sync_params()
    File "/sciclone/home20/hmbaier/.conda/envs/dhsrl4/lib/python3.9/site-packages/torch/nn/parallel/distributed.py", line 1379, in _sync_params
      self._distributed_broadcast_coalesced(
    File "/sciclone/home20/hmbaier/.conda/envs/dhsrl4/lib/python3.9/site-packages/torch/nn/parallel/distributed.py", line 1334, in _distributed_broadcast_coalesced
      dist._broadcast_coalesced(
  RuntimeError: [/opt/conda/conda-bld/pytorch_1634272107467/work/third_party/gloo/gloo/transport/tcp/pair.cc:598] Connection closed by peer [10.3.59.2]:3981
  
[24]:
  time      : 2022-03-10_15:54:51
  host      : mlt004.sciclone.wm.edu
  rank      : 126 (local_rank: 30)
  exitcode  : 1 (pid: 173440)
  error_file: /local/scr/hmbaier/TMPDIR/torchelastic_ru6z6ucj/790876_zq3gxtp6/attempt_0/30/error.json
  traceback : Traceback (most recent call last):
    File "/sciclone/home20/hmbaier/.conda/envs/dhsrl4/lib/python3.9/site-packages/torch/distributed/elastic/multiprocessing/errors/__init__.py", line 345, in wrapper
      return f(*args, **kwargs)
    File "/sciclone/home20/hmbaier/tm/run.py", line 100, in main
      ddp_model = DDP(model, process_group = model_group)
    File "/sciclone/home20/hmbaier/.conda/envs/dhsrl4/lib/python3.9/site-packages/torch/nn/parallel/distributed.py", line 580, in __init__
      self._sync_params_and_buffers(authoritative_rank=0)
    File "/sciclone/home20/hmbaier/.conda/envs/dhsrl4/lib/python3.9/site-packages/torch/nn/parallel/distributed.py", line 597, in _sync_params_and_buffers
      self._distributed_broadcast_coalesced(
    File "/sciclone/home20/hmbaier/.conda/envs/dhsrl4/lib/python3.9/site-packages/torch/nn/parallel/distributed.py", line 1334, in _distributed_broadcast_coalesced
      dist._broadcast_coalesced(
  RuntimeError: [/opt/conda/conda-bld/pytorch_1634272107467/work/third_party/gloo/gloo/transport/tcp/pair.cc:598] Connection closed by peer [10.3.59.2]:49559
  
[25]:
  time      : 2022-03-10_15:54:51
  host      : mlt004.sciclone.wm.edu
  rank      : 127 (local_rank: 31)
  exitcode  : 1 (pid: 173441)
  error_file: /local/scr/hmbaier/TMPDIR/torchelastic_ru6z6ucj/790876_zq3gxtp6/attempt_0/31/error.json
  traceback : Traceback (most recent call last):
    File "/sciclone/home20/hmbaier/.conda/envs/dhsrl4/lib/python3.9/site-packages/torch/distributed/elastic/multiprocessing/errors/__init__.py", line 345, in wrapper
      return f(*args, **kwargs)
    File "/sciclone/home20/hmbaier/tm/run.py", line 122, in main
      output = ddp_model(input)
    File "/sciclone/home20/hmbaier/.conda/envs/dhsrl4/lib/python3.9/site-packages/torch/nn/modules/module.py", line 1102, in _call_impl
      return forward_call(*input, **kwargs)
    File "/sciclone/home20/hmbaier/.conda/envs/dhsrl4/lib/python3.9/site-packages/torch/nn/parallel/distributed.py", line 878, in forward
      self._sync_params()
    File "/sciclone/home20/hmbaier/.conda/envs/dhsrl4/lib/python3.9/site-packages/torch/nn/parallel/distributed.py", line 1379, in _sync_params
      self._distributed_broadcast_coalesced(
    File "/sciclone/home20/hmbaier/.conda/envs/dhsrl4/lib/python3.9/site-packages/torch/nn/parallel/distributed.py", line 1334, in _distributed_broadcast_coalesced
      dist._broadcast_coalesced(
  RuntimeError: [/opt/conda/conda-bld/pytorch_1634272107467/work/third_party/gloo/gloo/transport/tcp/pair.cc:598] Connection closed by peer [10.3.59.2]:11442
  
------------------------------------------------------------
Root Cause (first observed failure):
[1]:
  time      : 2022-03-10_15:54:50
  host      : mlt004.sciclone.wm.edu
  rank      : 98 (local_rank: 2)
  exitcode  : 1 (pid: 173411)
  error_file: /local/scr/hmbaier/TMPDIR/torchelastic_ru6z6ucj/790876_zq3gxtp6/attempt_0/2/error.json
  traceback : Traceback (most recent call last):
    File "/sciclone/home20/hmbaier/.conda/envs/dhsrl4/lib/python3.9/site-packages/torch/distributed/elastic/multiprocessing/errors/__init__.py", line 345, in wrapper
      return f(*args, **kwargs)
    File "/sciclone/home20/hmbaier/tm/run.py", line 100, in main
      ddp_model = DDP(model, process_group = model_group)
    File "/sciclone/home20/hmbaier/.conda/envs/dhsrl4/lib/python3.9/site-packages/torch/nn/parallel/distributed.py", line 580, in __init__
      self._sync_params_and_buffers(authoritative_rank=0)
    File "/sciclone/home20/hmbaier/.conda/envs/dhsrl4/lib/python3.9/site-packages/torch/nn/parallel/distributed.py", line 597, in _sync_params_and_buffers
      self._distributed_broadcast_coalesced(
    File "/sciclone/home20/hmbaier/.conda/envs/dhsrl4/lib/python3.9/site-packages/torch/nn/parallel/distributed.py", line 1334, in _distributed_broadcast_coalesced
      dist._broadcast_coalesced(
  RuntimeError: [/opt/conda/conda-bld/pytorch_1634272107467/work/third_party/gloo/gloo/transport/tcp/pair.cc:598] Connection closed by peer [10.3.59.2]:11396
  
============================================================
