Warning: no access to tty (Bad file descriptor).
Thus no job control in this shell.
128.239.59.1
WARNING:torch.distributed.run:
*****************************************
Setting OMP_NUM_THREADS environment variable for each process to be 1 in default, to avoid your system being overloaded, please further tune the variable for optimal performance in your application as needed. 
*****************************************
Traceback (most recent call last):
  File "/sciclone/home20/hmbaier/tm/run.py", line 242, in <module>
    main(int(os.environ["RANK"]), int(os.environ['WORLD_SIZE']), model_group)
  File "/sciclone/home20/hmbaier/.conda/envs/dhsrl4/lib/python3.9/site-packages/torch/distributed/elastic/multiprocessing/errors/__init__.py", line 345, in wrapper
    return f(*args, **kwargs)
  File "/sciclone/home20/hmbaier/tm/run.py", line 100, in main
    ddp_model = DDP(model, process_group = model_group)
  File "/sciclone/home20/hmbaier/.conda/envs/dhsrl4/lib/python3.9/site-packages/torch/nn/parallel/distributed.py", line 580, in __init__
    self._sync_params_and_buffers(authoritative_rank=0)
  File "/sciclone/home20/hmbaier/.conda/envs/dhsrl4/lib/python3.9/site-packages/torch/nn/parallel/distributed.py", line 597, in _sync_params_and_buffers
    self._distributed_broadcast_coalesced(
  File "/sciclone/home20/hmbaier/.conda/envs/dhsrl4/lib/python3.9/site-packages/torch/nn/parallel/distributed.py", line 1334, in _distributed_broadcast_coalesced
    dist._broadcast_coalesced(
RuntimeError: [/opt/conda/conda-bld/pytorch_1634272107467/work/third_party/gloo/gloo/transport/tcp/pair.cc:598] Connection closed by peer [10.3.59.1]:17054
Traceback (most recent call last):
  File "/sciclone/home20/hmbaier/tm/run.py", line 242, in <module>
    main(int(os.environ["RANK"]), int(os.environ['WORLD_SIZE']), model_group)
  File "/sciclone/home20/hmbaier/.conda/envs/dhsrl4/lib/python3.9/site-packages/torch/distributed/elastic/multiprocessing/errors/__init__.py", line 345, in wrapper
    return f(*args, **kwargs)
  File "/sciclone/home20/hmbaier/tm/run.py", line 100, in main
    ddp_model = DDP(model, process_group = model_group)
  File "/sciclone/home20/hmbaier/.conda/envs/dhsrl4/lib/python3.9/site-packages/torch/nn/parallel/distributed.py", line 580, in __init__
    self._sync_params_and_buffers(authoritative_rank=0)
  File "/sciclone/home20/hmbaier/.conda/envs/dhsrl4/lib/python3.9/site-packages/torch/nn/parallel/distributed.py", line 597, in _sync_params_and_buffers
    self._distributed_broadcast_coalesced(
  File "/sciclone/home20/hmbaier/.conda/envs/dhsrl4/lib/python3.9/site-packages/torch/nn/parallel/distributed.py", line 1334, in _distributed_broadcast_coalesced
    dist._broadcast_coalesced(
RuntimeError: [/opt/conda/conda-bld/pytorch_1634272107467/work/third_party/gloo/gloo/transport/tcp/pair.cc:598] Connection closed by peer [10.3.59.1]:46502
Traceback (most recent call last):
  File "/sciclone/home20/hmbaier/tm/run.py", line 242, in <module>
    main(int(os.environ["RANK"]), int(os.environ['WORLD_SIZE']), model_group)
  File "/sciclone/home20/hmbaier/.conda/envs/dhsrl4/lib/python3.9/site-packages/torch/distributed/elastic/multiprocessing/errors/__init__.py", line 345, in wrapper
    return f(*args, **kwargs)
  File "/sciclone/home20/hmbaier/tm/run.py", line 100, in main
    ddp_model = DDP(model, process_group = model_group)
  File "/sciclone/home20/hmbaier/.conda/envs/dhsrl4/lib/python3.9/site-packages/torch/nn/parallel/distributed.py", line 580, in __init__
    self._sync_params_and_buffers(authoritative_rank=0)
  File "/sciclone/home20/hmbaier/.conda/envs/dhsrl4/lib/python3.9/site-packages/torch/nn/parallel/distributed.py", line 597, in _sync_params_and_buffers
    self._distributed_broadcast_coalesced(
  File "/sciclone/home20/hmbaier/.conda/envs/dhsrl4/lib/python3.9/site-packages/torch/nn/parallel/distributed.py", line 1334, in _distributed_broadcast_coalesced
    dist._broadcast_coalesced(
RuntimeError: [/opt/conda/conda-bld/pytorch_1634272107467/work/third_party/gloo/gloo/transport/tcp/pair.cc:598] Connection closed by peer [10.3.59.1]:47011
Traceback (most recent call last):
  File "/sciclone/home20/hmbaier/tm/run.py", line 242, in <module>
    main(int(os.environ["RANK"]), int(os.environ['WORLD_SIZE']), model_group)
  File "/sciclone/home20/hmbaier/.conda/envs/dhsrl4/lib/python3.9/site-packages/torch/distributed/elastic/multiprocessing/errors/__init__.py", line 345, in wrapper
    return f(*args, **kwargs)
  File "/sciclone/home20/hmbaier/tm/run.py", line 100, in main
    ddp_model = DDP(model, process_group = model_group)
  File "/sciclone/home20/hmbaier/.conda/envs/dhsrl4/lib/python3.9/site-packages/torch/nn/parallel/distributed.py", line 580, in __init__
    self._sync_params_and_buffers(authoritative_rank=0)
  File "/sciclone/home20/hmbaier/.conda/envs/dhsrl4/lib/python3.9/site-packages/torch/nn/parallel/distributed.py", line 597, in _sync_params_and_buffers
    self._distributed_broadcast_coalesced(
  File "/sciclone/home20/hmbaier/.conda/envs/dhsrl4/lib/python3.9/site-packages/torch/nn/parallel/distributed.py", line 1334, in _distributed_broadcast_coalesced
    dist._broadcast_coalesced(
RuntimeError: [/opt/conda/conda-bld/pytorch_1634272107467/work/third_party/gloo/gloo/transport/tcp/pair.cc:598] Connection closed by peer [10.3.59.1]:56221
Traceback (most recent call last):
  File "/sciclone/home20/hmbaier/tm/run.py", line 242, in <module>
    main(int(os.environ["RANK"]), int(os.environ['WORLD_SIZE']), model_group)
  File "/sciclone/home20/hmbaier/.conda/envs/dhsrl4/lib/python3.9/site-packages/torch/distributed/elastic/multiprocessing/errors/__init__.py", line 345, in wrapper
    return f(*args, **kwargs)
  File "/sciclone/home20/hmbaier/tm/run.py", line 100, in main
    ddp_model = DDP(model, process_group = model_group)
  File "/sciclone/home20/hmbaier/.conda/envs/dhsrl4/lib/python3.9/site-packages/torch/nn/parallel/distributed.py", line 580, in __init__
    self._sync_params_and_buffers(authoritative_rank=0)
  File "/sciclone/home20/hmbaier/.conda/envs/dhsrl4/lib/python3.9/site-packages/torch/nn/parallel/distributed.py", line 597, in _sync_params_and_buffers
    self._distributed_broadcast_coalesced(
  File "/sciclone/home20/hmbaier/.conda/envs/dhsrl4/lib/python3.9/site-packages/torch/nn/parallel/distributed.py", line 1334, in _distributed_broadcast_coalesced
    dist._broadcast_coalesced(
RuntimeError: [/opt/conda/conda-bld/pytorch_1634272107467/work/third_party/gloo/gloo/transport/tcp/pair.cc:598] Connection closed by peer [10.3.59.1]:43650
Traceback (most recent call last):
  File "/sciclone/home20/hmbaier/tm/run.py", line 242, in <module>
    main(int(os.environ["RANK"]), int(os.environ['WORLD_SIZE']), model_group)
  File "/sciclone/home20/hmbaier/.conda/envs/dhsrl4/lib/python3.9/site-packages/torch/distributed/elastic/multiprocessing/errors/__init__.py", line 345, in wrapper
    return f(*args, **kwargs)
  File "/sciclone/home20/hmbaier/tm/run.py", line 100, in main
    ddp_model = DDP(model, process_group = model_group)
  File "/sciclone/home20/hmbaier/.conda/envs/dhsrl4/lib/python3.9/site-packages/torch/nn/parallel/distributed.py", line 580, in __init__
    self._sync_params_and_buffers(authoritative_rank=0)
  File "/sciclone/home20/hmbaier/.conda/envs/dhsrl4/lib/python3.9/site-packages/torch/nn/parallel/distributed.py", line 597, in _sync_params_and_buffers
    self._distributed_broadcast_coalesced(
  File "/sciclone/home20/hmbaier/.conda/envs/dhsrl4/lib/python3.9/site-packages/torch/nn/parallel/distributed.py", line 1334, in _distributed_broadcast_coalesced
    dist._broadcast_coalesced(
RuntimeError: [/opt/conda/conda-bld/pytorch_1634272107467/work/third_party/gloo/gloo/transport/tcp/pair.cc:598] Connection closed by peer [10.3.59.1]:32642
Traceback (most recent call last):
  File "/sciclone/home20/hmbaier/tm/run.py", line 242, in <module>
    main(int(os.environ["RANK"]), int(os.environ['WORLD_SIZE']), model_group)
  File "/sciclone/home20/hmbaier/.conda/envs/dhsrl4/lib/python3.9/site-packages/torch/distributed/elastic/multiprocessing/errors/__init__.py", line 345, in wrapper
    return f(*args, **kwargs)
  File "/sciclone/home20/hmbaier/tm/run.py", line 100, in main
    ddp_model = DDP(model, process_group = model_group)
  File "/sciclone/home20/hmbaier/.conda/envs/dhsrl4/lib/python3.9/site-packages/torch/nn/parallel/distributed.py", line 580, in __init__
    self._sync_params_and_buffers(authoritative_rank=0)
  File "/sciclone/home20/hmbaier/.conda/envs/dhsrl4/lib/python3.9/site-packages/torch/nn/parallel/distributed.py", line 597, in _sync_params_and_buffers
    self._distributed_broadcast_coalesced(
  File "/sciclone/home20/hmbaier/.conda/envs/dhsrl4/lib/python3.9/site-packages/torch/nn/parallel/distributed.py", line 1334, in _distributed_broadcast_coalesced
    dist._broadcast_coalesced(
RuntimeError: [/opt/conda/conda-bld/pytorch_1634272107467/work/third_party/gloo/gloo/transport/tcp/pair.cc:598] Connection closed by peer [10.3.59.1]:35237
Traceback (most recent call last):
  File "/sciclone/home20/hmbaier/tm/run.py", line 242, in <module>
    main(int(os.environ["RANK"]), int(os.environ['WORLD_SIZE']), model_group)
  File "/sciclone/home20/hmbaier/.conda/envs/dhsrl4/lib/python3.9/site-packages/torch/distributed/elastic/multiprocessing/errors/__init__.py", line 345, in wrapper
    return f(*args, **kwargs)
  File "/sciclone/home20/hmbaier/tm/run.py", line 122, in main
    output = ddp_model(input)
  File "/sciclone/home20/hmbaier/.conda/envs/dhsrl4/lib/python3.9/site-packages/torch/nn/modules/module.py", line 1102, in _call_impl
    return forward_call(*input, **kwargs)
  File "/sciclone/home20/hmbaier/.conda/envs/dhsrl4/lib/python3.9/site-packages/torch/nn/parallel/distributed.py", line 878, in forward
    self._sync_params()
  File "/sciclone/home20/hmbaier/.conda/envs/dhsrl4/lib/python3.9/site-packages/torch/nn/parallel/distributed.py", line 1379, in _sync_params
    self._distributed_broadcast_coalesced(
  File "/sciclone/home20/hmbaier/.conda/envs/dhsrl4/lib/python3.9/site-packages/torch/nn/parallel/distributed.py", line 1334, in _distributed_broadcast_coalesced
    dist._broadcast_coalesced(
RuntimeError: [/opt/conda/conda-bld/pytorch_1634272107467/work/third_party/gloo/gloo/transport/tcp/pair.cc:598] Connection closed by peer [10.3.59.1]:47268
Traceback (most recent call last):
  File "/sciclone/home20/hmbaier/tm/run.py", line 242, in <module>
    main(int(os.environ["RANK"]), int(os.environ['WORLD_SIZE']), model_group)
  File "/sciclone/home20/hmbaier/.conda/envs/dhsrl4/lib/python3.9/site-packages/torch/distributed/elastic/multiprocessing/errors/__init__.py", line 345, in wrapper
    return f(*args, **kwargs)
  File "/sciclone/home20/hmbaier/tm/run.py", line 100, in main
    ddp_model = DDP(model, process_group = model_group)
  File "/sciclone/home20/hmbaier/.conda/envs/dhsrl4/lib/python3.9/site-packages/torch/nn/parallel/distributed.py", line 580, in __init__
    self._sync_params_and_buffers(authoritative_rank=0)
  File "/sciclone/home20/hmbaier/.conda/envs/dhsrl4/lib/python3.9/site-packages/torch/nn/parallel/distributed.py", line 597, in _sync_params_and_buffers
    self._distributed_broadcast_coalesced(
  File "/sciclone/home20/hmbaier/.conda/envs/dhsrl4/lib/python3.9/site-packages/torch/nn/parallel/distributed.py", line 1334, in _distributed_broadcast_coalesced
    dist._broadcast_coalesced(
RuntimeError: [/opt/conda/conda-bld/pytorch_1634272107467/work/third_party/gloo/gloo/transport/tcp/pair.cc:598] Connection closed by peer [10.3.59.1]:59808
Traceback (most recent call last):
  File "/sciclone/home20/hmbaier/tm/run.py", line 242, in <module>
    main(int(os.environ["RANK"]), int(os.environ['WORLD_SIZE']), model_group)
  File "/sciclone/home20/hmbaier/.conda/envs/dhsrl4/lib/python3.9/site-packages/torch/distributed/elastic/multiprocessing/errors/__init__.py", line 345, in wrapper
    return f(*args, **kwargs)
  File "/sciclone/home20/hmbaier/tm/run.py", line 122, in main
    output = ddp_model(input)
  File "/sciclone/home20/hmbaier/.conda/envs/dhsrl4/lib/python3.9/site-packages/torch/nn/modules/module.py", line 1102, in _call_impl
    return forward_call(*input, **kwargs)
  File "/sciclone/home20/hmbaier/.conda/envs/dhsrl4/lib/python3.9/site-packages/torch/nn/parallel/distributed.py", line 878, in forward
    self._sync_params()
  File "/sciclone/home20/hmbaier/.conda/envs/dhsrl4/lib/python3.9/site-packages/torch/nn/parallel/distributed.py", line 1379, in _sync_params
    self._distributed_broadcast_coalesced(
  File "/sciclone/home20/hmbaier/.conda/envs/dhsrl4/lib/python3.9/site-packages/torch/nn/parallel/distributed.py", line 1334, in _distributed_broadcast_coalesced
    dist._broadcast_coalesced(
RuntimeError: [/opt/conda/conda-bld/pytorch_1634272107467/work/third_party/gloo/gloo/transport/tcp/pair.cc:598] Connection closed by peer [10.3.59.1]:20875
Traceback (most recent call last):
  File "/sciclone/home20/hmbaier/tm/run.py", line 242, in <module>
    main(int(os.environ["RANK"]), int(os.environ['WORLD_SIZE']), model_group)
  File "/sciclone/home20/hmbaier/.conda/envs/dhsrl4/lib/python3.9/site-packages/torch/distributed/elastic/multiprocessing/errors/__init__.py", line 345, in wrapper
    return f(*args, **kwargs)
  File "/sciclone/home20/hmbaier/tm/run.py", line 100, in main
    ddp_model = DDP(model, process_group = model_group)
  File "/sciclone/home20/hmbaier/.conda/envs/dhsrl4/lib/python3.9/site-packages/torch/nn/parallel/distributed.py", line 580, in __init__
    self._sync_params_and_buffers(authoritative_rank=0)
  File "/sciclone/home20/hmbaier/.conda/envs/dhsrl4/lib/python3.9/site-packages/torch/nn/parallel/distributed.py", line 597, in _sync_params_and_buffers
    self._distributed_broadcast_coalesced(
  File "/sciclone/home20/hmbaier/.conda/envs/dhsrl4/lib/python3.9/site-packages/torch/nn/parallel/distributed.py", line 1334, in _distributed_broadcast_coalesced
    dist._broadcast_coalesced(
RuntimeError: [/opt/conda/conda-bld/pytorch_1634272107467/work/third_party/gloo/gloo/transport/tcp/pair.cc:598] Connection closed by peer [10.3.59.1]:47240
Traceback (most recent call last):
  File "/sciclone/home20/hmbaier/tm/run.py", line 242, in <module>
    main(int(os.environ["RANK"]), int(os.environ['WORLD_SIZE']), model_group)
  File "/sciclone/home20/hmbaier/.conda/envs/dhsrl4/lib/python3.9/site-packages/torch/distributed/elastic/multiprocessing/errors/__init__.py", line 345, in wrapper
    return f(*args, **kwargs)
  File "/sciclone/home20/hmbaier/tm/run.py", line 122, in main
    output = ddp_model(input)
  File "/sciclone/home20/hmbaier/.conda/envs/dhsrl4/lib/python3.9/site-packages/torch/nn/modules/module.py", line 1102, in _call_impl
    return forward_call(*input, **kwargs)
  File "/sciclone/home20/hmbaier/.conda/envs/dhsrl4/lib/python3.9/site-packages/torch/nn/parallel/distributed.py", line 878, in forward
    self._sync_params()
  File "/sciclone/home20/hmbaier/.conda/envs/dhsrl4/lib/python3.9/site-packages/torch/nn/parallel/distributed.py", line 1379, in _sync_params
Traceback (most recent call last):
  File "/sciclone/home20/hmbaier/tm/run.py", line 242, in <module>
    main(int(os.environ["RANK"]), int(os.environ['WORLD_SIZE']), model_group)
  File "/sciclone/home20/hmbaier/.conda/envs/dhsrl4/lib/python3.9/site-packages/torch/distributed/elastic/multiprocessing/errors/__init__.py", line 345, in wrapper
    self._distributed_broadcast_coalesced(
  File "/sciclone/home20/hmbaier/.conda/envs/dhsrl4/lib/python3.9/site-packages/torch/nn/parallel/distributed.py", line 1334, in _distributed_broadcast_coalesced
    return f(*args, **kwargs)
  File "/sciclone/home20/hmbaier/tm/run.py", line 100, in main
    ddp_model = DDP(model, process_group = model_group)
  File "/sciclone/home20/hmbaier/.conda/envs/dhsrl4/lib/python3.9/site-packages/torch/nn/parallel/distributed.py", line 580, in __init__
    dist._broadcast_coalesced(
RuntimeError: [/opt/conda/conda-bld/pytorch_1634272107467/work/third_party/gloo/gloo/transport/tcp/pair.cc:598] Connection closed by peer [10.3.59.1]:9900
    self._sync_params_and_buffers(authoritative_rank=0)
  File "/sciclone/home20/hmbaier/.conda/envs/dhsrl4/lib/python3.9/site-packages/torch/nn/parallel/distributed.py", line 597, in _sync_params_and_buffers
    self._distributed_broadcast_coalesced(
  File "/sciclone/home20/hmbaier/.conda/envs/dhsrl4/lib/python3.9/site-packages/torch/nn/parallel/distributed.py", line 1334, in _distributed_broadcast_coalesced
    dist._broadcast_coalesced(
RuntimeError: [/opt/conda/conda-bld/pytorch_1634272107467/work/third_party/gloo/gloo/transport/tcp/pair.cc:598] Connection closed by peer [10.3.59.1]:47027
Traceback (most recent call last):
  File "/sciclone/home20/hmbaier/tm/run.py", line 242, in <module>
    main(int(os.environ["RANK"]), int(os.environ['WORLD_SIZE']), model_group)
  File "/sciclone/home20/hmbaier/.conda/envs/dhsrl4/lib/python3.9/site-packages/torch/distributed/elastic/multiprocessing/errors/__init__.py", line 345, in wrapper
    return f(*args, **kwargs)
  File "/sciclone/home20/hmbaier/tm/run.py", line 100, in main
    ddp_model = DDP(model, process_group = model_group)
  File "/sciclone/home20/hmbaier/.conda/envs/dhsrl4/lib/python3.9/site-packages/torch/nn/parallel/distributed.py", line 580, in __init__
    self._sync_params_and_buffers(authoritative_rank=0)
  File "/sciclone/home20/hmbaier/.conda/envs/dhsrl4/lib/python3.9/site-packages/torch/nn/parallel/distributed.py", line 597, in _sync_params_and_buffers
    self._distributed_broadcast_coalesced(
  File "/sciclone/home20/hmbaier/.conda/envs/dhsrl4/lib/python3.9/site-packages/torch/nn/parallel/distributed.py", line 1334, in _distributed_broadcast_coalesced
    dist._broadcast_coalesced(
RuntimeError: [/opt/conda/conda-bld/pytorch_1634272107467/work/third_party/gloo/gloo/transport/tcp/pair.cc:598] Connection closed by peer [10.3.59.1]:12948
Traceback (most recent call last):
  File "/sciclone/home20/hmbaier/tm/run.py", line 242, in <module>
    main(int(os.environ["RANK"]), int(os.environ['WORLD_SIZE']), model_group)
  File "/sciclone/home20/hmbaier/.conda/envs/dhsrl4/lib/python3.9/site-packages/torch/distributed/elastic/multiprocessing/errors/__init__.py", line 345, in wrapper
    return f(*args, **kwargs)
  File "/sciclone/home20/hmbaier/tm/run.py", line 122, in main
    output = ddp_model(input)
  File "/sciclone/home20/hmbaier/.conda/envs/dhsrl4/lib/python3.9/site-packages/torch/nn/modules/module.py", line 1102, in _call_impl
    return forward_call(*input, **kwargs)
  File "/sciclone/home20/hmbaier/.conda/envs/dhsrl4/lib/python3.9/site-packages/torch/nn/parallel/distributed.py", line 878, in forward
    self._sync_params()
  File "/sciclone/home20/hmbaier/.conda/envs/dhsrl4/lib/python3.9/site-packages/torch/nn/parallel/distributed.py", line 1379, in _sync_params
    self._distributed_broadcast_coalesced(
  File "/sciclone/home20/hmbaier/.conda/envs/dhsrl4/lib/python3.9/site-packages/torch/nn/parallel/distributed.py", line 1334, in _distributed_broadcast_coalesced
    dist._broadcast_coalesced(
RuntimeError: [/opt/conda/conda-bld/pytorch_1634272107467/work/third_party/gloo/gloo/transport/tcp/pair.cc:598] Connection closed by peer [10.3.59.1]:49059
Traceback (most recent call last):
  File "/sciclone/home20/hmbaier/tm/run.py", line 242, in <module>
    main(int(os.environ["RANK"]), int(os.environ['WORLD_SIZE']), model_group)
  File "/sciclone/home20/hmbaier/.conda/envs/dhsrl4/lib/python3.9/site-packages/torch/distributed/elastic/multiprocessing/errors/__init__.py", line 345, in wrapper
    return f(*args, **kwargs)
  File "/sciclone/home20/hmbaier/tm/run.py", line 100, in main
    ddp_model = DDP(model, process_group = model_group)
  File "/sciclone/home20/hmbaier/.conda/envs/dhsrl4/lib/python3.9/site-packages/torch/nn/parallel/distributed.py", line 580, in __init__
    self._sync_params_and_buffers(authoritative_rank=0)
  File "/sciclone/home20/hmbaier/.conda/envs/dhsrl4/lib/python3.9/site-packages/torch/nn/parallel/distributed.py", line 597, in _sync_params_and_buffers
    self._distributed_broadcast_coalesced(
  File "/sciclone/home20/hmbaier/.conda/envs/dhsrl4/lib/python3.9/site-packages/torch/nn/parallel/distributed.py", line 1334, in _distributed_broadcast_coalesced
    dist._broadcast_coalesced(
RuntimeError: [/opt/conda/conda-bld/pytorch_1634272107467/work/third_party/gloo/gloo/transport/tcp/pair.cc:598] Connection closed by peer [10.3.59.1]:33685
Traceback (most recent call last):
  File "/sciclone/home20/hmbaier/tm/run.py", line 242, in <module>
    main(int(os.environ["RANK"]), int(os.environ['WORLD_SIZE']), model_group)
  File "/sciclone/home20/hmbaier/.conda/envs/dhsrl4/lib/python3.9/site-packages/torch/distributed/elastic/multiprocessing/errors/__init__.py", line 345, in wrapper
    return f(*args, **kwargs)
  File "/sciclone/home20/hmbaier/tm/run.py", line 122, in main
    output = ddp_model(input)
  File "/sciclone/home20/hmbaier/.conda/envs/dhsrl4/lib/python3.9/site-packages/torch/nn/modules/module.py", line 1102, in _call_impl
    return forward_call(*input, **kwargs)
  File "/sciclone/home20/hmbaier/.conda/envs/dhsrl4/lib/python3.9/site-packages/torch/nn/parallel/distributed.py", line 878, in forward
    self._sync_params()
  File "/sciclone/home20/hmbaier/.conda/envs/dhsrl4/lib/python3.9/site-packages/torch/nn/parallel/distributed.py", line 1379, in _sync_params
    self._distributed_broadcast_coalesced(
  File "/sciclone/home20/hmbaier/.conda/envs/dhsrl4/lib/python3.9/site-packages/torch/nn/parallel/distributed.py", line 1334, in _distributed_broadcast_coalesced
Traceback (most recent call last):
  File "/sciclone/home20/hmbaier/tm/run.py", line 242, in <module>
    dist._broadcast_coalesced(
RuntimeError: [/opt/conda/conda-bld/pytorch_1634272107467/work/third_party/gloo/gloo/transport/tcp/pair.cc:598] Connection closed by peer [10.3.59.1]:27567
    main(int(os.environ["RANK"]), int(os.environ['WORLD_SIZE']), model_group)
  File "/sciclone/home20/hmbaier/.conda/envs/dhsrl4/lib/python3.9/site-packages/torch/distributed/elastic/multiprocessing/errors/__init__.py", line 345, in wrapper
    return f(*args, **kwargs)
  File "/sciclone/home20/hmbaier/tm/run.py", line 100, in main
    ddp_model = DDP(model, process_group = model_group)
  File "/sciclone/home20/hmbaier/.conda/envs/dhsrl4/lib/python3.9/site-packages/torch/nn/parallel/distributed.py", line 580, in __init__
    self._sync_params_and_buffers(authoritative_rank=0)
  File "/sciclone/home20/hmbaier/.conda/envs/dhsrl4/lib/python3.9/site-packages/torch/nn/parallel/distributed.py", line 597, in _sync_params_and_buffers
    self._distributed_broadcast_coalesced(
  File "/sciclone/home20/hmbaier/.conda/envs/dhsrl4/lib/python3.9/site-packages/torch/nn/parallel/distributed.py", line 1334, in _distributed_broadcast_coalesced
    dist._broadcast_coalesced(
RuntimeError: [/opt/conda/conda-bld/pytorch_1634272107467/work/third_party/gloo/gloo/transport/tcp/pair.cc:598] Connection closed by peer [10.3.59.1]:16310
Traceback (most recent call last):
  File "/sciclone/home20/hmbaier/tm/run.py", line 242, in <module>
    main(int(os.environ["RANK"]), int(os.environ['WORLD_SIZE']), model_group)
  File "/sciclone/home20/hmbaier/.conda/envs/dhsrl4/lib/python3.9/site-packages/torch/distributed/elastic/multiprocessing/errors/__init__.py", line 345, in wrapper
    return f(*args, **kwargs)
  File "/sciclone/home20/hmbaier/tm/run.py", line 100, in main
    ddp_model = DDP(model, process_group = model_group)
  File "/sciclone/home20/hmbaier/.conda/envs/dhsrl4/lib/python3.9/site-packages/torch/nn/parallel/distributed.py", line 580, in __init__
    self._sync_params_and_buffers(authoritative_rank=0)
  File "/sciclone/home20/hmbaier/.conda/envs/dhsrl4/lib/python3.9/site-packages/torch/nn/parallel/distributed.py", line 597, in _sync_params_and_buffers
    self._distributed_broadcast_coalesced(
  File "/sciclone/home20/hmbaier/.conda/envs/dhsrl4/lib/python3.9/site-packages/torch/nn/parallel/distributed.py", line 1334, in _distributed_broadcast_coalesced
    dist._broadcast_coalesced(
RuntimeError: [/opt/conda/conda-bld/pytorch_1634272107467/work/third_party/gloo/gloo/transport/tcp/pair.cc:598] Connection closed by peer [10.3.59.1]:50321
Traceback (most recent call last):
  File "/sciclone/home20/hmbaier/tm/run.py", line 242, in <module>
    main(int(os.environ["RANK"]), int(os.environ['WORLD_SIZE']), model_group)
  File "/sciclone/home20/hmbaier/.conda/envs/dhsrl4/lib/python3.9/site-packages/torch/distributed/elastic/multiprocessing/errors/__init__.py", line 345, in wrapper
    return f(*args, **kwargs)
  File "/sciclone/home20/hmbaier/tm/run.py", line 100, in main
    ddp_model = DDP(model, process_group = model_group)
  File "/sciclone/home20/hmbaier/.conda/envs/dhsrl4/lib/python3.9/site-packages/torch/nn/parallel/distributed.py", line 580, in __init__
    self._sync_params_and_buffers(authoritative_rank=0)
  File "/sciclone/home20/hmbaier/.conda/envs/dhsrl4/lib/python3.9/site-packages/torch/nn/parallel/distributed.py", line 597, in _sync_params_and_buffers
    self._distributed_broadcast_coalesced(
  File "/sciclone/home20/hmbaier/.conda/envs/dhsrl4/lib/python3.9/site-packages/torch/nn/parallel/distributed.py", line 1334, in _distributed_broadcast_coalesced
Traceback (most recent call last):
  File "/sciclone/home20/hmbaier/tm/run.py", line 242, in <module>
    main(int(os.environ["RANK"]), int(os.environ['WORLD_SIZE']), model_group)
  File "/sciclone/home20/hmbaier/.conda/envs/dhsrl4/lib/python3.9/site-packages/torch/distributed/elastic/multiprocessing/errors/__init__.py", line 345, in wrapper
    return f(*args, **kwargs)
  File "/sciclone/home20/hmbaier/tm/run.py", line 122, in main
    output = ddp_model(input)
  File "/sciclone/home20/hmbaier/.conda/envs/dhsrl4/lib/python3.9/site-packages/torch/nn/modules/module.py", line 1102, in _call_impl
    return forward_call(*input, **kwargs)
  File "/sciclone/home20/hmbaier/.conda/envs/dhsrl4/lib/python3.9/site-packages/torch/nn/parallel/distributed.py", line 878, in forward
    self._sync_params()
  File "/sciclone/home20/hmbaier/.conda/envs/dhsrl4/lib/python3.9/site-packages/torch/nn/parallel/distributed.py", line 1379, in _sync_params
    dist._broadcast_coalesced(
RuntimeError: [/opt/conda/conda-bld/pytorch_1634272107467/work/third_party/gloo/gloo/transport/tcp/pair.cc:598] Connection closed by peer [10.3.59.1]:50100
    self._distributed_broadcast_coalesced(
  File "/sciclone/home20/hmbaier/.conda/envs/dhsrl4/lib/python3.9/site-packages/torch/nn/parallel/distributed.py", line 1334, in _distributed_broadcast_coalesced
    dist._broadcast_coalesced(
RuntimeError: [/opt/conda/conda-bld/pytorch_1634272107467/work/third_party/gloo/gloo/transport/tcp/pair.cc:598] Connection closed by peer [10.3.59.1]:9142
Traceback (most recent call last):
  File "/sciclone/home20/hmbaier/tm/run.py", line 242, in <module>
    main(int(os.environ["RANK"]), int(os.environ['WORLD_SIZE']), model_group)
  File "/sciclone/home20/hmbaier/.conda/envs/dhsrl4/lib/python3.9/site-packages/torch/distributed/elastic/multiprocessing/errors/__init__.py", line 345, in wrapper
    return f(*args, **kwargs)
  File "/sciclone/home20/hmbaier/tm/run.py", line 100, in main
    ddp_model = DDP(model, process_group = model_group)
  File "/sciclone/home20/hmbaier/.conda/envs/dhsrl4/lib/python3.9/site-packages/torch/nn/parallel/distributed.py", line 580, in __init__
    self._sync_params_and_buffers(authoritative_rank=0)
  File "/sciclone/home20/hmbaier/.conda/envs/dhsrl4/lib/python3.9/site-packages/torch/nn/parallel/distributed.py", line 597, in _sync_params_and_buffers
    self._distributed_broadcast_coalesced(
  File "/sciclone/home20/hmbaier/.conda/envs/dhsrl4/lib/python3.9/site-packages/torch/nn/parallel/distributed.py", line 1334, in _distributed_broadcast_coalesced
Traceback (most recent call last):
  File "/sciclone/home20/hmbaier/tm/run.py", line 242, in <module>
Traceback (most recent call last):
  File "/sciclone/home20/hmbaier/tm/run.py", line 242, in <module>
    dist._broadcast_coalesced(
RuntimeError: [/opt/conda/conda-bld/pytorch_1634272107467/work/third_party/gloo/gloo/transport/tcp/pair.cc:598] Connection closed by peer [10.3.59.1]:33955
    main(int(os.environ["RANK"]), int(os.environ['WORLD_SIZE']), model_group)
  File "/sciclone/home20/hmbaier/.conda/envs/dhsrl4/lib/python3.9/site-packages/torch/distributed/elastic/multiprocessing/errors/__init__.py", line 345, in wrapper
    main(int(os.environ["RANK"]), int(os.environ['WORLD_SIZE']), model_group)
  File "/sciclone/home20/hmbaier/.conda/envs/dhsrl4/lib/python3.9/site-packages/torch/distributed/elastic/multiprocessing/errors/__init__.py", line 345, in wrapper
    return f(*args, **kwargs)
  File "/sciclone/home20/hmbaier/tm/run.py", line 122, in main
Traceback (most recent call last):
  File "/sciclone/home20/hmbaier/tm/run.py", line 242, in <module>
        return f(*args, **kwargs)output = ddp_model(input)

  File "/sciclone/home20/hmbaier/.conda/envs/dhsrl4/lib/python3.9/site-packages/torch/nn/modules/module.py", line 1102, in _call_impl
  File "/sciclone/home20/hmbaier/tm/run.py", line 100, in main
    ddp_model = DDP(model, process_group = model_group)
  File "/sciclone/home20/hmbaier/.conda/envs/dhsrl4/lib/python3.9/site-packages/torch/nn/parallel/distributed.py", line 580, in __init__
    main(int(os.environ["RANK"]), int(os.environ['WORLD_SIZE']), model_group)
  File "/sciclone/home20/hmbaier/.conda/envs/dhsrl4/lib/python3.9/site-packages/torch/distributed/elastic/multiprocessing/errors/__init__.py", line 345, in wrapper
        return f(*args, **kwargs)return forward_call(*input, **kwargs)

  File "/sciclone/home20/hmbaier/tm/run.py", line 100, in main
  File "/sciclone/home20/hmbaier/.conda/envs/dhsrl4/lib/python3.9/site-packages/torch/nn/parallel/distributed.py", line 878, in forward
    self._sync_params_and_buffers(authoritative_rank=0)
  File "/sciclone/home20/hmbaier/.conda/envs/dhsrl4/lib/python3.9/site-packages/torch/nn/parallel/distributed.py", line 597, in _sync_params_and_buffers
    ddp_model = DDP(model, process_group = model_group)
  File "/sciclone/home20/hmbaier/.conda/envs/dhsrl4/lib/python3.9/site-packages/torch/nn/parallel/distributed.py", line 580, in __init__
        self._sync_params_and_buffers(authoritative_rank=0)self._distributed_broadcast_coalesced(

  File "/sciclone/home20/hmbaier/.conda/envs/dhsrl4/lib/python3.9/site-packages/torch/nn/parallel/distributed.py", line 597, in _sync_params_and_buffers
      File "/sciclone/home20/hmbaier/.conda/envs/dhsrl4/lib/python3.9/site-packages/torch/nn/parallel/distributed.py", line 1334, in _distributed_broadcast_coalesced
self._sync_params()
  File "/sciclone/home20/hmbaier/.conda/envs/dhsrl4/lib/python3.9/site-packages/torch/nn/parallel/distributed.py", line 1379, in _sync_params
    self._distributed_broadcast_coalesced(
  File "/sciclone/home20/hmbaier/.conda/envs/dhsrl4/lib/python3.9/site-packages/torch/nn/parallel/distributed.py", line 1334, in _distributed_broadcast_coalesced
Traceback (most recent call last):
  File "/sciclone/home20/hmbaier/tm/run.py", line 242, in <module>
    dist._broadcast_coalesced(
RuntimeError    : self._distributed_broadcast_coalesced([/opt/conda/conda-bld/pytorch_1634272107467/work/third_party/gloo/gloo/transport/tcp/pair.cc:598] Connection closed by peer [10.3.59.1]:35493

  File "/sciclone/home20/hmbaier/.conda/envs/dhsrl4/lib/python3.9/site-packages/torch/nn/parallel/distributed.py", line 1334, in _distributed_broadcast_coalesced
    main(int(os.environ["RANK"]), int(os.environ['WORLD_SIZE']), model_group)
  File "/sciclone/home20/hmbaier/.conda/envs/dhsrl4/lib/python3.9/site-packages/torch/distributed/elastic/multiprocessing/errors/__init__.py", line 345, in wrapper
    dist._broadcast_coalesced(
RuntimeError: [/opt/conda/conda-bld/pytorch_1634272107467/work/third_party/gloo/gloo/transport/tcp/pair.cc:598] Connection closed by peer [10.3.59.1]:14773
    return f(*args, **kwargs)
      File "/sciclone/home20/hmbaier/tm/run.py", line 100, in main
dist._broadcast_coalesced(
RuntimeError: [/opt/conda/conda-bld/pytorch_1634272107467/work/third_party/gloo/gloo/transport/tcp/pair.cc:598] Connection closed by peer [10.3.59.1]:14740
    ddp_model = DDP(model, process_group = model_group)
  File "/sciclone/home20/hmbaier/.conda/envs/dhsrl4/lib/python3.9/site-packages/torch/nn/parallel/distributed.py", line 580, in __init__
    self._sync_params_and_buffers(authoritative_rank=0)
  File "/sciclone/home20/hmbaier/.conda/envs/dhsrl4/lib/python3.9/site-packages/torch/nn/parallel/distributed.py", line 597, in _sync_params_and_buffers
    self._distributed_broadcast_coalesced(
  File "/sciclone/home20/hmbaier/.conda/envs/dhsrl4/lib/python3.9/site-packages/torch/nn/parallel/distributed.py", line 1334, in _distributed_broadcast_coalesced
    dist._broadcast_coalesced(
RuntimeError: [/opt/conda/conda-bld/pytorch_1634272107467/work/third_party/gloo/gloo/transport/tcp/pair.cc:598] Connection closed by peer [10.3.59.1]:16274
WARNING:torch.distributed.elastic.multiprocessing.api:Sending process 232723 closing signal SIGTERM
WARNING:torch.distributed.elastic.multiprocessing.api:Sending process 232725 closing signal SIGTERM
WARNING:torch.distributed.elastic.multiprocessing.api:Sending process 232727 closing signal SIGTERM
WARNING:torch.distributed.elastic.multiprocessing.api:Sending process 232729 closing signal SIGTERM
WARNING:torch.distributed.elastic.multiprocessing.api:Sending process 232731 closing signal SIGTERM
WARNING:torch.distributed.elastic.multiprocessing.api:Sending process 232735 closing signal SIGTERM
ERROR:torch.distributed.elastic.multiprocessing.api:failed (exitcode: 1) local_rank: 2 (pid: 232724) of binary: /sciclone/home20/hmbaier/.conda/envs/dhsrl4/bin/python
ERROR:torch.distributed.elastic.agent.server.api:Error waiting on exit barrier. Elapsed: 0.000965118408203125 seconds
Traceback (most recent call last):
  File "/sciclone/home20/hmbaier/.conda/envs/dhsrl4/lib/python3.9/site-packages/torch/distributed/elastic/agent/server/api.py", line 899, in _exit_barrier
    store_util.barrier(
  File "/sciclone/home20/hmbaier/.conda/envs/dhsrl4/lib/python3.9/site-packages/torch/distributed/elastic/utils/store.py", line 67, in barrier
    synchronize(store, data, rank, world_size, key_prefix, barrier_timeout)
  File "/sciclone/home20/hmbaier/.conda/envs/dhsrl4/lib/python3.9/site-packages/torch/distributed/elastic/utils/store.py", line 53, in synchronize
    agent_data = get_all(store, key_prefix, world_size)
  File "/sciclone/home20/hmbaier/.conda/envs/dhsrl4/lib/python3.9/site-packages/torch/distributed/elastic/utils/store.py", line 31, in get_all
    data = store.get(f"{prefix}{idx}")
RuntimeError: Connection reset by peer
WARNING:torch.distributed.elastic.rendezvous.dynamic_rendezvous:The node 'mlt002.sciclone.wm.edu_232719_0' has failed to shutdown the rendezvous '790876' due to an error of type RendezvousConnectionError.
ERROR:torch.distributed.elastic.multiprocessing.errors.error_handler:no error file defined for parent, to copy child error file (/local/scr/hmbaier/TMPDIR/torchelastic_oix6t6ac/790876_kpcc1_qs/attempt_0/2/error.json)
Traceback (most recent call last):
  File "/sciclone/home20/hmbaier/.conda/envs/dhsrl4/bin/torchrun", line 33, in <module>
    sys.exit(load_entry_point('torch==1.10.0', 'console_scripts', 'torchrun')())
  File "/sciclone/home20/hmbaier/.conda/envs/dhsrl4/lib/python3.9/site-packages/torch/distributed/elastic/multiprocessing/errors/__init__.py", line 345, in wrapper
    return f(*args, **kwargs)
  File "/sciclone/home20/hmbaier/.conda/envs/dhsrl4/lib/python3.9/site-packages/torch/distributed/run.py", line 719, in main
    run(args)
  File "/sciclone/home20/hmbaier/.conda/envs/dhsrl4/lib/python3.9/site-packages/torch/distributed/run.py", line 710, in run
    elastic_launch(
  File "/sciclone/home20/hmbaier/.conda/envs/dhsrl4/lib/python3.9/site-packages/torch/distributed/launcher/api.py", line 131, in __call__
    return launch_agent(self._config, self._entrypoint, list(args))
  File "/sciclone/home20/hmbaier/.conda/envs/dhsrl4/lib/python3.9/site-packages/torch/distributed/launcher/api.py", line 259, in launch_agent
    raise ChildFailedError(
torch.distributed.elastic.multiprocessing.errors.ChildFailedError: 
============================================================
/sciclone/home20/hmbaier/tm/run.py FAILED
------------------------------------------------------------
Failures:
[0]:
  time      : 2022-03-10_15:54:55
  host      : mlt002.sciclone.wm.edu
  rank      : 32 (local_rank: 0)
  exitcode  : 1 (pid: 232722)
  error_file: /local/scr/hmbaier/TMPDIR/torchelastic_oix6t6ac/790876_kpcc1_qs/attempt_0/0/error.json
  traceback : Traceback (most recent call last):
    File "/sciclone/home20/hmbaier/.conda/envs/dhsrl4/lib/python3.9/site-packages/torch/distributed/elastic/multiprocessing/errors/__init__.py", line 345, in wrapper
      return f(*args, **kwargs)
    File "/sciclone/home20/hmbaier/tm/run.py", line 100, in main
      ddp_model = DDP(model, process_group = model_group)
    File "/sciclone/home20/hmbaier/.conda/envs/dhsrl4/lib/python3.9/site-packages/torch/nn/parallel/distributed.py", line 580, in __init__
      self._sync_params_and_buffers(authoritative_rank=0)
    File "/sciclone/home20/hmbaier/.conda/envs/dhsrl4/lib/python3.9/site-packages/torch/nn/parallel/distributed.py", line 597, in _sync_params_and_buffers
      self._distributed_broadcast_coalesced(
    File "/sciclone/home20/hmbaier/.conda/envs/dhsrl4/lib/python3.9/site-packages/torch/nn/parallel/distributed.py", line 1334, in _distributed_broadcast_coalesced
      dist._broadcast_coalesced(
  RuntimeError: [/opt/conda/conda-bld/pytorch_1634272107467/work/third_party/gloo/gloo/transport/tcp/pair.cc:598] Connection closed by peer [10.3.59.1]:35237
  
[2]:
  time      : 2022-03-10_15:54:53
  host      : mlt002.sciclone.wm.edu
  rank      : 36 (local_rank: 4)
  exitcode  : 1 (pid: 232726)
  error_file: /local/scr/hmbaier/TMPDIR/torchelastic_oix6t6ac/790876_kpcc1_qs/attempt_0/4/error.json
  traceback : Traceback (most recent call last):
    File "/sciclone/home20/hmbaier/.conda/envs/dhsrl4/lib/python3.9/site-packages/torch/distributed/elastic/multiprocessing/errors/__init__.py", line 345, in wrapper
      return f(*args, **kwargs)
    File "/sciclone/home20/hmbaier/tm/run.py", line 100, in main
      ddp_model = DDP(model, process_group = model_group)
    File "/sciclone/home20/hmbaier/.conda/envs/dhsrl4/lib/python3.9/site-packages/torch/nn/parallel/distributed.py", line 580, in __init__
      self._sync_params_and_buffers(authoritative_rank=0)
    File "/sciclone/home20/hmbaier/.conda/envs/dhsrl4/lib/python3.9/site-packages/torch/nn/parallel/distributed.py", line 597, in _sync_params_and_buffers
      self._distributed_broadcast_coalesced(
    File "/sciclone/home20/hmbaier/.conda/envs/dhsrl4/lib/python3.9/site-packages/torch/nn/parallel/distributed.py", line 1334, in _distributed_broadcast_coalesced
      dist._broadcast_coalesced(
  RuntimeError: [/opt/conda/conda-bld/pytorch_1634272107467/work/third_party/gloo/gloo/transport/tcp/pair.cc:598] Connection closed by peer [10.3.59.1]:17054
  
[3]:
  time      : 2022-03-10_15:54:53
  host      : mlt002.sciclone.wm.edu
  rank      : 38 (local_rank: 6)
  exitcode  : 1 (pid: 232728)
  error_file: /local/scr/hmbaier/TMPDIR/torchelastic_oix6t6ac/790876_kpcc1_qs/attempt_0/6/error.json
  traceback : Traceback (most recent call last):
    File "/sciclone/home20/hmbaier/.conda/envs/dhsrl4/lib/python3.9/site-packages/torch/distributed/elastic/multiprocessing/errors/__init__.py", line 345, in wrapper
      return f(*args, **kwargs)
    File "/sciclone/home20/hmbaier/tm/run.py", line 100, in main
      ddp_model = DDP(model, process_group = model_group)
    File "/sciclone/home20/hmbaier/.conda/envs/dhsrl4/lib/python3.9/site-packages/torch/nn/parallel/distributed.py", line 580, in __init__
      self._sync_params_and_buffers(authoritative_rank=0)
    File "/sciclone/home20/hmbaier/.conda/envs/dhsrl4/lib/python3.9/site-packages/torch/nn/parallel/distributed.py", line 597, in _sync_params_and_buffers
      self._distributed_broadcast_coalesced(
    File "/sciclone/home20/hmbaier/.conda/envs/dhsrl4/lib/python3.9/site-packages/torch/nn/parallel/distributed.py", line 1334, in _distributed_broadcast_coalesced
      dist._broadcast_coalesced(
  RuntimeError: [/opt/conda/conda-bld/pytorch_1634272107467/work/third_party/gloo/gloo/transport/tcp/pair.cc:598] Connection closed by peer [10.3.59.1]:46502
  
[4]:
  time      : 2022-03-10_15:54:53
  host      : mlt002.sciclone.wm.edu
  rank      : 40 (local_rank: 8)
  exitcode  : 1 (pid: 232730)
  error_file: /local/scr/hmbaier/TMPDIR/torchelastic_oix6t6ac/790876_kpcc1_qs/attempt_0/8/error.json
  traceback : Traceback (most recent call last):
    File "/sciclone/home20/hmbaier/.conda/envs/dhsrl4/lib/python3.9/site-packages/torch/distributed/elastic/multiprocessing/errors/__init__.py", line 345, in wrapper
      return f(*args, **kwargs)
    File "/sciclone/home20/hmbaier/tm/run.py", line 100, in main
      ddp_model = DDP(model, process_group = model_group)
    File "/sciclone/home20/hmbaier/.conda/envs/dhsrl4/lib/python3.9/site-packages/torch/nn/parallel/distributed.py", line 580, in __init__
      self._sync_params_and_buffers(authoritative_rank=0)
    File "/sciclone/home20/hmbaier/.conda/envs/dhsrl4/lib/python3.9/site-packages/torch/nn/parallel/distributed.py", line 597, in _sync_params_and_buffers
      self._distributed_broadcast_coalesced(
    File "/sciclone/home20/hmbaier/.conda/envs/dhsrl4/lib/python3.9/site-packages/torch/nn/parallel/distributed.py", line 1334, in _distributed_broadcast_coalesced
      dist._broadcast_coalesced(
  RuntimeError: [/opt/conda/conda-bld/pytorch_1634272107467/work/third_party/gloo/gloo/transport/tcp/pair.cc:598] Connection closed by peer [10.3.59.1]:47011
  
[5]:
  time      : 2022-03-10_15:54:53
  host      : mlt002.sciclone.wm.edu
  rank      : 42 (local_rank: 10)
  exitcode  : 1 (pid: 232732)
  error_file: /local/scr/hmbaier/TMPDIR/torchelastic_oix6t6ac/790876_kpcc1_qs/attempt_0/10/error.json
  traceback : Traceback (most recent call last):
    File "/sciclone/home20/hmbaier/.conda/envs/dhsrl4/lib/python3.9/site-packages/torch/distributed/elastic/multiprocessing/errors/__init__.py", line 345, in wrapper
      return f(*args, **kwargs)
    File "/sciclone/home20/hmbaier/tm/run.py", line 100, in main
      ddp_model = DDP(model, process_group = model_group)
    File "/sciclone/home20/hmbaier/.conda/envs/dhsrl4/lib/python3.9/site-packages/torch/nn/parallel/distributed.py", line 580, in __init__
      self._sync_params_and_buffers(authoritative_rank=0)
    File "/sciclone/home20/hmbaier/.conda/envs/dhsrl4/lib/python3.9/site-packages/torch/nn/parallel/distributed.py", line 597, in _sync_params_and_buffers
      self._distributed_broadcast_coalesced(
    File "/sciclone/home20/hmbaier/.conda/envs/dhsrl4/lib/python3.9/site-packages/torch/nn/parallel/distributed.py", line 1334, in _distributed_broadcast_coalesced
      dist._broadcast_coalesced(
  RuntimeError: [/opt/conda/conda-bld/pytorch_1634272107467/work/third_party/gloo/gloo/transport/tcp/pair.cc:598] Connection closed by peer [10.3.59.1]:32642
  
[6]:
  time      : 2022-03-10_15:54:56
  host      : mlt002.sciclone.wm.edu
  rank      : 43 (local_rank: 11)
  exitcode  : 1 (pid: 232733)
  error_file: /local/scr/hmbaier/TMPDIR/torchelastic_oix6t6ac/790876_kpcc1_qs/attempt_0/11/error.json
  traceback : Traceback (most recent call last):
    File "/sciclone/home20/hmbaier/.conda/envs/dhsrl4/lib/python3.9/site-packages/torch/distributed/elastic/multiprocessing/errors/__init__.py", line 345, in wrapper
      return f(*args, **kwargs)
    File "/sciclone/home20/hmbaier/tm/run.py", line 100, in main
      ddp_model = DDP(model, process_group = model_group)
    File "/sciclone/home20/hmbaier/.conda/envs/dhsrl4/lib/python3.9/site-packages/torch/nn/parallel/distributed.py", line 580, in __init__
      self._sync_params_and_buffers(authoritative_rank=0)
    File "/sciclone/home20/hmbaier/.conda/envs/dhsrl4/lib/python3.9/site-packages/torch/nn/parallel/distributed.py", line 597, in _sync_params_and_buffers
      self._distributed_broadcast_coalesced(
    File "/sciclone/home20/hmbaier/.conda/envs/dhsrl4/lib/python3.9/site-packages/torch/nn/parallel/distributed.py", line 1334, in _distributed_broadcast_coalesced
      dist._broadcast_coalesced(
  RuntimeError: [/opt/conda/conda-bld/pytorch_1634272107467/work/third_party/gloo/gloo/transport/tcp/pair.cc:598] Connection closed by peer [10.3.59.1]:33955
  
[7]:
  time      : 2022-03-10_15:54:53
  host      : mlt002.sciclone.wm.edu
  rank      : 44 (local_rank: 12)
  exitcode  : 1 (pid: 232734)
  error_file: /local/scr/hmbaier/TMPDIR/torchelastic_oix6t6ac/790876_kpcc1_qs/attempt_0/12/error.json
  traceback : Traceback (most recent call last):
    File "/sciclone/home20/hmbaier/.conda/envs/dhsrl4/lib/python3.9/site-packages/torch/distributed/elastic/multiprocessing/errors/__init__.py", line 345, in wrapper
      return f(*args, **kwargs)
    File "/sciclone/home20/hmbaier/tm/run.py", line 100, in main
      ddp_model = DDP(model, process_group = model_group)
    File "/sciclone/home20/hmbaier/.conda/envs/dhsrl4/lib/python3.9/site-packages/torch/nn/parallel/distributed.py", line 580, in __init__
      self._sync_params_and_buffers(authoritative_rank=0)
    File "/sciclone/home20/hmbaier/.conda/envs/dhsrl4/lib/python3.9/site-packages/torch/nn/parallel/distributed.py", line 597, in _sync_params_and_buffers
      self._distributed_broadcast_coalesced(
    File "/sciclone/home20/hmbaier/.conda/envs/dhsrl4/lib/python3.9/site-packages/torch/nn/parallel/distributed.py", line 1334, in _distributed_broadcast_coalesced
      dist._broadcast_coalesced(
  RuntimeError: [/opt/conda/conda-bld/pytorch_1634272107467/work/third_party/gloo/gloo/transport/tcp/pair.cc:598] Connection closed by peer [10.3.59.1]:56221
  
[8]:
  time      : 2022-03-10_15:54:55
  host      : mlt002.sciclone.wm.edu
  rank      : 46 (local_rank: 14)
  exitcode  : 1 (pid: 232736)
  error_file: /local/scr/hmbaier/TMPDIR/torchelastic_oix6t6ac/790876_kpcc1_qs/attempt_0/14/error.json
  traceback : Traceback (most recent call last):
    File "/sciclone/home20/hmbaier/.conda/envs/dhsrl4/lib/python3.9/site-packages/torch/distributed/elastic/multiprocessing/errors/__init__.py", line 345, in wrapper
      return f(*args, **kwargs)
    File "/sciclone/home20/hmbaier/tm/run.py", line 100, in main
      ddp_model = DDP(model, process_group = model_group)
    File "/sciclone/home20/hmbaier/.conda/envs/dhsrl4/lib/python3.9/site-packages/torch/nn/parallel/distributed.py", line 580, in __init__
      self._sync_params_and_buffers(authoritative_rank=0)
    File "/sciclone/home20/hmbaier/.conda/envs/dhsrl4/lib/python3.9/site-packages/torch/nn/parallel/distributed.py", line 597, in _sync_params_and_buffers
      self._distributed_broadcast_coalesced(
    File "/sciclone/home20/hmbaier/.conda/envs/dhsrl4/lib/python3.9/site-packages/torch/nn/parallel/distributed.py", line 1334, in _distributed_broadcast_coalesced
      dist._broadcast_coalesced(
  RuntimeError: [/opt/conda/conda-bld/pytorch_1634272107467/work/third_party/gloo/gloo/transport/tcp/pair.cc:598] Connection closed by peer [10.3.59.1]:59808
  
[9]:
  time      : 2022-03-10_15:54:55
  host      : mlt002.sciclone.wm.edu
  rank      : 47 (local_rank: 15)
  exitcode  : 1 (pid: 232737)
  error_file: /local/scr/hmbaier/TMPDIR/torchelastic_oix6t6ac/790876_kpcc1_qs/attempt_0/15/error.json
  traceback : Traceback (most recent call last):
    File "/sciclone/home20/hmbaier/.conda/envs/dhsrl4/lib/python3.9/site-packages/torch/distributed/elastic/multiprocessing/errors/__init__.py", line 345, in wrapper
      return f(*args, **kwargs)
    File "/sciclone/home20/hmbaier/tm/run.py", line 122, in main
      output = ddp_model(input)
    File "/sciclone/home20/hmbaier/.conda/envs/dhsrl4/lib/python3.9/site-packages/torch/nn/modules/module.py", line 1102, in _call_impl
      return forward_call(*input, **kwargs)
    File "/sciclone/home20/hmbaier/.conda/envs/dhsrl4/lib/python3.9/site-packages/torch/nn/parallel/distributed.py", line 878, in forward
      self._sync_params()
    File "/sciclone/home20/hmbaier/.conda/envs/dhsrl4/lib/python3.9/site-packages/torch/nn/parallel/distributed.py", line 1379, in _sync_params
      self._distributed_broadcast_coalesced(
    File "/sciclone/home20/hmbaier/.conda/envs/dhsrl4/lib/python3.9/site-packages/torch/nn/parallel/distributed.py", line 1334, in _distributed_broadcast_coalesced
      dist._broadcast_coalesced(
  RuntimeError: [/opt/conda/conda-bld/pytorch_1634272107467/work/third_party/gloo/gloo/transport/tcp/pair.cc:598] Connection closed by peer [10.3.59.1]:20875
  
[10]:
  time      : 2022-03-10_15:54:55
  host      : mlt002.sciclone.wm.edu
  rank      : 48 (local_rank: 16)
  exitcode  : 1 (pid: 232738)
  error_file: /local/scr/hmbaier/TMPDIR/torchelastic_oix6t6ac/790876_kpcc1_qs/attempt_0/16/error.json
  traceback : Traceback (most recent call last):
    File "/sciclone/home20/hmbaier/.conda/envs/dhsrl4/lib/python3.9/site-packages/torch/distributed/elastic/multiprocessing/errors/__init__.py", line 345, in wrapper
      return f(*args, **kwargs)
    File "/sciclone/home20/hmbaier/tm/run.py", line 100, in main
      ddp_model = DDP(model, process_group = model_group)
    File "/sciclone/home20/hmbaier/.conda/envs/dhsrl4/lib/python3.9/site-packages/torch/nn/parallel/distributed.py", line 580, in __init__
      self._sync_params_and_buffers(authoritative_rank=0)
    File "/sciclone/home20/hmbaier/.conda/envs/dhsrl4/lib/python3.9/site-packages/torch/nn/parallel/distributed.py", line 597, in _sync_params_and_buffers
      self._distributed_broadcast_coalesced(
    File "/sciclone/home20/hmbaier/.conda/envs/dhsrl4/lib/python3.9/site-packages/torch/nn/parallel/distributed.py", line 1334, in _distributed_broadcast_coalesced
      dist._broadcast_coalesced(
  RuntimeError: [/opt/conda/conda-bld/pytorch_1634272107467/work/third_party/gloo/gloo/transport/tcp/pair.cc:598] Connection closed by peer [10.3.59.1]:47240
  
[11]:
  time      : 2022-03-10_15:54:55
  host      : mlt002.sciclone.wm.edu
  rank      : 49 (local_rank: 17)
  exitcode  : 1 (pid: 232739)
  error_file: /local/scr/hmbaier/TMPDIR/torchelastic_oix6t6ac/790876_kpcc1_qs/attempt_0/17/error.json
  traceback : Traceback (most recent call last):
    File "/sciclone/home20/hmbaier/.conda/envs/dhsrl4/lib/python3.9/site-packages/torch/distributed/elastic/multiprocessing/errors/__init__.py", line 345, in wrapper
      return f(*args, **kwargs)
    File "/sciclone/home20/hmbaier/tm/run.py", line 122, in main
      output = ddp_model(input)
    File "/sciclone/home20/hmbaier/.conda/envs/dhsrl4/lib/python3.9/site-packages/torch/nn/modules/module.py", line 1102, in _call_impl
      return forward_call(*input, **kwargs)
    File "/sciclone/home20/hmbaier/.conda/envs/dhsrl4/lib/python3.9/site-packages/torch/nn/parallel/distributed.py", line 878, in forward
      self._sync_params()
    File "/sciclone/home20/hmbaier/.conda/envs/dhsrl4/lib/python3.9/site-packages/torch/nn/parallel/distributed.py", line 1379, in _sync_params
      self._distributed_broadcast_coalesced(
    File "/sciclone/home20/hmbaier/.conda/envs/dhsrl4/lib/python3.9/site-packages/torch/nn/parallel/distributed.py", line 1334, in _distributed_broadcast_coalesced
      dist._broadcast_coalesced(
  RuntimeError: [/opt/conda/conda-bld/pytorch_1634272107467/work/third_party/gloo/gloo/transport/tcp/pair.cc:598] Connection closed by peer [10.3.59.1]:9900
  
[12]:
  time      : 2022-03-10_15:54:55
  host      : mlt002.sciclone.wm.edu
  rank      : 50 (local_rank: 18)
  exitcode  : 1 (pid: 232740)
  error_file: /local/scr/hmbaier/TMPDIR/torchelastic_oix6t6ac/790876_kpcc1_qs/attempt_0/18/error.json
  traceback : Traceback (most recent call last):
    File "/sciclone/home20/hmbaier/.conda/envs/dhsrl4/lib/python3.9/site-packages/torch/distributed/elastic/multiprocessing/errors/__init__.py", line 345, in wrapper
      return f(*args, **kwargs)
    File "/sciclone/home20/hmbaier/tm/run.py", line 100, in main
      ddp_model = DDP(model, process_group = model_group)
    File "/sciclone/home20/hmbaier/.conda/envs/dhsrl4/lib/python3.9/site-packages/torch/nn/parallel/distributed.py", line 580, in __init__
      self._sync_params_and_buffers(authoritative_rank=0)
    File "/sciclone/home20/hmbaier/.conda/envs/dhsrl4/lib/python3.9/site-packages/torch/nn/parallel/distributed.py", line 597, in _sync_params_and_buffers
      self._distributed_broadcast_coalesced(
    File "/sciclone/home20/hmbaier/.conda/envs/dhsrl4/lib/python3.9/site-packages/torch/nn/parallel/distributed.py", line 1334, in _distributed_broadcast_coalesced
      dist._broadcast_coalesced(
  RuntimeError: [/opt/conda/conda-bld/pytorch_1634272107467/work/third_party/gloo/gloo/transport/tcp/pair.cc:598] Connection closed by peer [10.3.59.1]:47027
  
[13]:
  time      : 2022-03-10_15:54:56
  host      : mlt002.sciclone.wm.edu
  rank      : 51 (local_rank: 19)
  exitcode  : 1 (pid: 232741)
  error_file: /local/scr/hmbaier/TMPDIR/torchelastic_oix6t6ac/790876_kpcc1_qs/attempt_0/19/error.json
  traceback : Traceback (most recent call last):
    File "/sciclone/home20/hmbaier/.conda/envs/dhsrl4/lib/python3.9/site-packages/torch/distributed/elastic/multiprocessing/errors/__init__.py", line 345, in wrapper
      return f(*args, **kwargs)
    File "/sciclone/home20/hmbaier/tm/run.py", line 100, in main
      ddp_model = DDP(model, process_group = model_group)
    File "/sciclone/home20/hmbaier/.conda/envs/dhsrl4/lib/python3.9/site-packages/torch/nn/parallel/distributed.py", line 580, in __init__
      self._sync_params_and_buffers(authoritative_rank=0)
    File "/sciclone/home20/hmbaier/.conda/envs/dhsrl4/lib/python3.9/site-packages/torch/nn/parallel/distributed.py", line 597, in _sync_params_and_buffers
      self._distributed_broadcast_coalesced(
    File "/sciclone/home20/hmbaier/.conda/envs/dhsrl4/lib/python3.9/site-packages/torch/nn/parallel/distributed.py", line 1334, in _distributed_broadcast_coalesced
      dist._broadcast_coalesced(
  RuntimeError: [/opt/conda/conda-bld/pytorch_1634272107467/work/third_party/gloo/gloo/transport/tcp/pair.cc:598] Connection closed by peer [10.3.59.1]:16274
  
[14]:
  time      : 2022-03-10_15:54:55
  host      : mlt002.sciclone.wm.edu
  rank      : 52 (local_rank: 20)
  exitcode  : 1 (pid: 232742)
  error_file: /local/scr/hmbaier/TMPDIR/torchelastic_oix6t6ac/790876_kpcc1_qs/attempt_0/20/error.json
  traceback : Traceback (most recent call last):
    File "/sciclone/home20/hmbaier/.conda/envs/dhsrl4/lib/python3.9/site-packages/torch/distributed/elastic/multiprocessing/errors/__init__.py", line 345, in wrapper
      return f(*args, **kwargs)
    File "/sciclone/home20/hmbaier/tm/run.py", line 100, in main
      ddp_model = DDP(model, process_group = model_group)
    File "/sciclone/home20/hmbaier/.conda/envs/dhsrl4/lib/python3.9/site-packages/torch/nn/parallel/distributed.py", line 580, in __init__
      self._sync_params_and_buffers(authoritative_rank=0)
    File "/sciclone/home20/hmbaier/.conda/envs/dhsrl4/lib/python3.9/site-packages/torch/nn/parallel/distributed.py", line 597, in _sync_params_and_buffers
      self._distributed_broadcast_coalesced(
    File "/sciclone/home20/hmbaier/.conda/envs/dhsrl4/lib/python3.9/site-packages/torch/nn/parallel/distributed.py", line 1334, in _distributed_broadcast_coalesced
      dist._broadcast_coalesced(
  RuntimeError: [/opt/conda/conda-bld/pytorch_1634272107467/work/third_party/gloo/gloo/transport/tcp/pair.cc:598] Connection closed by peer [10.3.59.1]:12948
  
[15]:
  time      : 2022-03-10_15:54:55
  host      : mlt002.sciclone.wm.edu
  rank      : 53 (local_rank: 21)
  exitcode  : 1 (pid: 232743)
  error_file: /local/scr/hmbaier/TMPDIR/torchelastic_oix6t6ac/790876_kpcc1_qs/attempt_0/21/error.json
  traceback : Traceback (most recent call last):
    File "/sciclone/home20/hmbaier/.conda/envs/dhsrl4/lib/python3.9/site-packages/torch/distributed/elastic/multiprocessing/errors/__init__.py", line 345, in wrapper
      return f(*args, **kwargs)
    File "/sciclone/home20/hmbaier/tm/run.py", line 122, in main
      output = ddp_model(input)
    File "/sciclone/home20/hmbaier/.conda/envs/dhsrl4/lib/python3.9/site-packages/torch/nn/modules/module.py", line 1102, in _call_impl
      return forward_call(*input, **kwargs)
    File "/sciclone/home20/hmbaier/.conda/envs/dhsrl4/lib/python3.9/site-packages/torch/nn/parallel/distributed.py", line 878, in forward
      self._sync_params()
    File "/sciclone/home20/hmbaier/.conda/envs/dhsrl4/lib/python3.9/site-packages/torch/nn/parallel/distributed.py", line 1379, in _sync_params
      self._distributed_broadcast_coalesced(
    File "/sciclone/home20/hmbaier/.conda/envs/dhsrl4/lib/python3.9/site-packages/torch/nn/parallel/distributed.py", line 1334, in _distributed_broadcast_coalesced
      dist._broadcast_coalesced(
  RuntimeError: [/opt/conda/conda-bld/pytorch_1634272107467/work/third_party/gloo/gloo/transport/tcp/pair.cc:598] Connection closed by peer [10.3.59.1]:49059
  
[16]:
  time      : 2022-03-10_15:54:55
  host      : mlt002.sciclone.wm.edu
  rank      : 54 (local_rank: 22)
  exitcode  : 1 (pid: 232744)
  error_file: /local/scr/hmbaier/TMPDIR/torchelastic_oix6t6ac/790876_kpcc1_qs/attempt_0/22/error.json
  traceback : Traceback (most recent call last):
    File "/sciclone/home20/hmbaier/.conda/envs/dhsrl4/lib/python3.9/site-packages/torch/distributed/elastic/multiprocessing/errors/__init__.py", line 345, in wrapper
      return f(*args, **kwargs)
    File "/sciclone/home20/hmbaier/tm/run.py", line 100, in main
      ddp_model = DDP(model, process_group = model_group)
    File "/sciclone/home20/hmbaier/.conda/envs/dhsrl4/lib/python3.9/site-packages/torch/nn/parallel/distributed.py", line 580, in __init__
      self._sync_params_and_buffers(authoritative_rank=0)
    File "/sciclone/home20/hmbaier/.conda/envs/dhsrl4/lib/python3.9/site-packages/torch/nn/parallel/distributed.py", line 597, in _sync_params_and_buffers
      self._distributed_broadcast_coalesced(
    File "/sciclone/home20/hmbaier/.conda/envs/dhsrl4/lib/python3.9/site-packages/torch/nn/parallel/distributed.py", line 1334, in _distributed_broadcast_coalesced
      dist._broadcast_coalesced(
  RuntimeError: [/opt/conda/conda-bld/pytorch_1634272107467/work/third_party/gloo/gloo/transport/tcp/pair.cc:598] Connection closed by peer [10.3.59.1]:33685
  
[17]:
  time      : 2022-03-10_15:54:55
  host      : mlt002.sciclone.wm.edu
  rank      : 55 (local_rank: 23)
  exitcode  : 1 (pid: 232745)
  error_file: /local/scr/hmbaier/TMPDIR/torchelastic_oix6t6ac/790876_kpcc1_qs/attempt_0/23/error.json
  traceback : Traceback (most recent call last):
    File "/sciclone/home20/hmbaier/.conda/envs/dhsrl4/lib/python3.9/site-packages/torch/distributed/elastic/multiprocessing/errors/__init__.py", line 345, in wrapper
      return f(*args, **kwargs)
    File "/sciclone/home20/hmbaier/tm/run.py", line 122, in main
      output = ddp_model(input)
    File "/sciclone/home20/hmbaier/.conda/envs/dhsrl4/lib/python3.9/site-packages/torch/nn/modules/module.py", line 1102, in _call_impl
      return forward_call(*input, **kwargs)
    File "/sciclone/home20/hmbaier/.conda/envs/dhsrl4/lib/python3.9/site-packages/torch/nn/parallel/distributed.py", line 878, in forward
      self._sync_params()
    File "/sciclone/home20/hmbaier/.conda/envs/dhsrl4/lib/python3.9/site-packages/torch/nn/parallel/distributed.py", line 1379, in _sync_params
      self._distributed_broadcast_coalesced(
    File "/sciclone/home20/hmbaier/.conda/envs/dhsrl4/lib/python3.9/site-packages/torch/nn/parallel/distributed.py", line 1334, in _distributed_broadcast_coalesced
      dist._broadcast_coalesced(
  RuntimeError: [/opt/conda/conda-bld/pytorch_1634272107467/work/third_party/gloo/gloo/transport/tcp/pair.cc:598] Connection closed by peer [10.3.59.1]:27567
  
[18]:
  time      : 2022-03-10_15:54:55
  host      : mlt002.sciclone.wm.edu
  rank      : 56 (local_rank: 24)
  exitcode  : 1 (pid: 232746)
  error_file: /local/scr/hmbaier/TMPDIR/torchelastic_oix6t6ac/790876_kpcc1_qs/attempt_0/24/error.json
  traceback : Traceback (most recent call last):
    File "/sciclone/home20/hmbaier/.conda/envs/dhsrl4/lib/python3.9/site-packages/torch/distributed/elastic/multiprocessing/errors/__init__.py", line 345, in wrapper
      return f(*args, **kwargs)
    File "/sciclone/home20/hmbaier/tm/run.py", line 100, in main
      ddp_model = DDP(model, process_group = model_group)
    File "/sciclone/home20/hmbaier/.conda/envs/dhsrl4/lib/python3.9/site-packages/torch/nn/parallel/distributed.py", line 580, in __init__
      self._sync_params_and_buffers(authoritative_rank=0)
    File "/sciclone/home20/hmbaier/.conda/envs/dhsrl4/lib/python3.9/site-packages/torch/nn/parallel/distributed.py", line 597, in _sync_params_and_buffers
      self._distributed_broadcast_coalesced(
    File "/sciclone/home20/hmbaier/.conda/envs/dhsrl4/lib/python3.9/site-packages/torch/nn/parallel/distributed.py", line 1334, in _distributed_broadcast_coalesced
      dist._broadcast_coalesced(
  RuntimeError: [/opt/conda/conda-bld/pytorch_1634272107467/work/third_party/gloo/gloo/transport/tcp/pair.cc:598] Connection closed by peer [10.3.59.1]:16310
  
[19]:
  time      : 2022-03-10_15:54:55
  host      : mlt002.sciclone.wm.edu
  rank      : 57 (local_rank: 25)
  exitcode  : 1 (pid: 232747)
  error_file: /local/scr/hmbaier/TMPDIR/torchelastic_oix6t6ac/790876_kpcc1_qs/attempt_0/25/error.json
  traceback : Traceback (most recent call last):
    File "/sciclone/home20/hmbaier/.conda/envs/dhsrl4/lib/python3.9/site-packages/torch/distributed/elastic/multiprocessing/errors/__init__.py", line 345, in wrapper
      return f(*args, **kwargs)
    File "/sciclone/home20/hmbaier/tm/run.py", line 122, in main
      output = ddp_model(input)
    File "/sciclone/home20/hmbaier/.conda/envs/dhsrl4/lib/python3.9/site-packages/torch/nn/modules/module.py", line 1102, in _call_impl
      return forward_call(*input, **kwargs)
    File "/sciclone/home20/hmbaier/.conda/envs/dhsrl4/lib/python3.9/site-packages/torch/nn/parallel/distributed.py", line 878, in forward
      self._sync_params()
    File "/sciclone/home20/hmbaier/.conda/envs/dhsrl4/lib/python3.9/site-packages/torch/nn/parallel/distributed.py", line 1379, in _sync_params
      self._distributed_broadcast_coalesced(
    File "/sciclone/home20/hmbaier/.conda/envs/dhsrl4/lib/python3.9/site-packages/torch/nn/parallel/distributed.py", line 1334, in _distributed_broadcast_coalesced
      dist._broadcast_coalesced(
  RuntimeError: [/opt/conda/conda-bld/pytorch_1634272107467/work/third_party/gloo/gloo/transport/tcp/pair.cc:598] Connection closed by peer [10.3.59.1]:47268
  
[20]:
  time      : 2022-03-10_15:54:55
  host      : mlt002.sciclone.wm.edu
  rank      : 58 (local_rank: 26)
  exitcode  : 1 (pid: 232748)
  error_file: /local/scr/hmbaier/TMPDIR/torchelastic_oix6t6ac/790876_kpcc1_qs/attempt_0/26/error.json
  traceback : Traceback (most recent call last):
    File "/sciclone/home20/hmbaier/.conda/envs/dhsrl4/lib/python3.9/site-packages/torch/distributed/elastic/multiprocessing/errors/__init__.py", line 345, in wrapper
      return f(*args, **kwargs)
    File "/sciclone/home20/hmbaier/tm/run.py", line 100, in main
      ddp_model = DDP(model, process_group = model_group)
    File "/sciclone/home20/hmbaier/.conda/envs/dhsrl4/lib/python3.9/site-packages/torch/nn/parallel/distributed.py", line 580, in __init__
      self._sync_params_and_buffers(authoritative_rank=0)
    File "/sciclone/home20/hmbaier/.conda/envs/dhsrl4/lib/python3.9/site-packages/torch/nn/parallel/distributed.py", line 597, in _sync_params_and_buffers
      self._distributed_broadcast_coalesced(
    File "/sciclone/home20/hmbaier/.conda/envs/dhsrl4/lib/python3.9/site-packages/torch/nn/parallel/distributed.py", line 1334, in _distributed_broadcast_coalesced
      dist._broadcast_coalesced(
  RuntimeError: [/opt/conda/conda-bld/pytorch_1634272107467/work/third_party/gloo/gloo/transport/tcp/pair.cc:598] Connection closed by peer [10.3.59.1]:50321
  
[21]:
  time      : 2022-03-10_15:54:56
  host      : mlt002.sciclone.wm.edu
  rank      : 59 (local_rank: 27)
  exitcode  : 1 (pid: 232749)
  error_file: /local/scr/hmbaier/TMPDIR/torchelastic_oix6t6ac/790876_kpcc1_qs/attempt_0/27/error.json
  traceback : Traceback (most recent call last):
    File "/sciclone/home20/hmbaier/.conda/envs/dhsrl4/lib/python3.9/site-packages/torch/distributed/elastic/multiprocessing/errors/__init__.py", line 345, in wrapper
      return f(*args, **kwargs)
    File "/sciclone/home20/hmbaier/tm/run.py", line 100, in main
      ddp_model = DDP(model, process_group = model_group)
    File "/sciclone/home20/hmbaier/.conda/envs/dhsrl4/lib/python3.9/site-packages/torch/nn/parallel/distributed.py", line 580, in __init__
      self._sync_params_and_buffers(authoritative_rank=0)
    File "/sciclone/home20/hmbaier/.conda/envs/dhsrl4/lib/python3.9/site-packages/torch/nn/parallel/distributed.py", line 597, in _sync_params_and_buffers
      self._distributed_broadcast_coalesced(
    File "/sciclone/home20/hmbaier/.conda/envs/dhsrl4/lib/python3.9/site-packages/torch/nn/parallel/distributed.py", line 1334, in _distributed_broadcast_coalesced
      dist._broadcast_coalesced(
  RuntimeError: [/opt/conda/conda-bld/pytorch_1634272107467/work/third_party/gloo/gloo/transport/tcp/pair.cc:598] Connection closed by peer [10.3.59.1]:14773
  
[22]:
  time      : 2022-03-10_15:54:55
  host      : mlt002.sciclone.wm.edu
  rank      : 60 (local_rank: 28)
  exitcode  : 1 (pid: 232750)
  error_file: /local/scr/hmbaier/TMPDIR/torchelastic_oix6t6ac/790876_kpcc1_qs/attempt_0/28/error.json
  traceback : Traceback (most recent call last):
    File "/sciclone/home20/hmbaier/.conda/envs/dhsrl4/lib/python3.9/site-packages/torch/distributed/elastic/multiprocessing/errors/__init__.py", line 345, in wrapper
      return f(*args, **kwargs)
    File "/sciclone/home20/hmbaier/tm/run.py", line 100, in main
      ddp_model = DDP(model, process_group = model_group)
    File "/sciclone/home20/hmbaier/.conda/envs/dhsrl4/lib/python3.9/site-packages/torch/nn/parallel/distributed.py", line 580, in __init__
      self._sync_params_and_buffers(authoritative_rank=0)
    File "/sciclone/home20/hmbaier/.conda/envs/dhsrl4/lib/python3.9/site-packages/torch/nn/parallel/distributed.py", line 597, in _sync_params_and_buffers
      self._distributed_broadcast_coalesced(
    File "/sciclone/home20/hmbaier/.conda/envs/dhsrl4/lib/python3.9/site-packages/torch/nn/parallel/distributed.py", line 1334, in _distributed_broadcast_coalesced
      dist._broadcast_coalesced(
  RuntimeError: [/opt/conda/conda-bld/pytorch_1634272107467/work/third_party/gloo/gloo/transport/tcp/pair.cc:598] Connection closed by peer [10.3.59.1]:50100
  
[23]:
  time      : 2022-03-10_15:54:55
  host      : mlt002.sciclone.wm.edu
  rank      : 61 (local_rank: 29)
  exitcode  : 1 (pid: 232751)
  error_file: /local/scr/hmbaier/TMPDIR/torchelastic_oix6t6ac/790876_kpcc1_qs/attempt_0/29/error.json
  traceback : Traceback (most recent call last):
    File "/sciclone/home20/hmbaier/.conda/envs/dhsrl4/lib/python3.9/site-packages/torch/distributed/elastic/multiprocessing/errors/__init__.py", line 345, in wrapper
      return f(*args, **kwargs)
    File "/sciclone/home20/hmbaier/tm/run.py", line 122, in main
      output = ddp_model(input)
    File "/sciclone/home20/hmbaier/.conda/envs/dhsrl4/lib/python3.9/site-packages/torch/nn/modules/module.py", line 1102, in _call_impl
      return forward_call(*input, **kwargs)
    File "/sciclone/home20/hmbaier/.conda/envs/dhsrl4/lib/python3.9/site-packages/torch/nn/parallel/distributed.py", line 878, in forward
      self._sync_params()
    File "/sciclone/home20/hmbaier/.conda/envs/dhsrl4/lib/python3.9/site-packages/torch/nn/parallel/distributed.py", line 1379, in _sync_params
      self._distributed_broadcast_coalesced(
    File "/sciclone/home20/hmbaier/.conda/envs/dhsrl4/lib/python3.9/site-packages/torch/nn/parallel/distributed.py", line 1334, in _distributed_broadcast_coalesced
      dist._broadcast_coalesced(
  RuntimeError: [/opt/conda/conda-bld/pytorch_1634272107467/work/third_party/gloo/gloo/transport/tcp/pair.cc:598] Connection closed by peer [10.3.59.1]:9142
  
[24]:
  time      : 2022-03-10_15:54:56
  host      : mlt002.sciclone.wm.edu
  rank      : 62 (local_rank: 30)
  exitcode  : 1 (pid: 232752)
  error_file: /local/scr/hmbaier/TMPDIR/torchelastic_oix6t6ac/790876_kpcc1_qs/attempt_0/30/error.json
  traceback : Traceback (most recent call last):
    File "/sciclone/home20/hmbaier/.conda/envs/dhsrl4/lib/python3.9/site-packages/torch/distributed/elastic/multiprocessing/errors/__init__.py", line 345, in wrapper
      return f(*args, **kwargs)
    File "/sciclone/home20/hmbaier/tm/run.py", line 100, in main
      ddp_model = DDP(model, process_group = model_group)
    File "/sciclone/home20/hmbaier/.conda/envs/dhsrl4/lib/python3.9/site-packages/torch/nn/parallel/distributed.py", line 580, in __init__
      self._sync_params_and_buffers(authoritative_rank=0)
    File "/sciclone/home20/hmbaier/.conda/envs/dhsrl4/lib/python3.9/site-packages/torch/nn/parallel/distributed.py", line 597, in _sync_params_and_buffers
      self._distributed_broadcast_coalesced(
    File "/sciclone/home20/hmbaier/.conda/envs/dhsrl4/lib/python3.9/site-packages/torch/nn/parallel/distributed.py", line 1334, in _distributed_broadcast_coalesced
      dist._broadcast_coalesced(
  RuntimeError: [/opt/conda/conda-bld/pytorch_1634272107467/work/third_party/gloo/gloo/transport/tcp/pair.cc:598] Connection closed by peer [10.3.59.1]:35493
  
[25]:
  time      : 2022-03-10_15:54:56
  host      : mlt002.sciclone.wm.edu
  rank      : 63 (local_rank: 31)
  exitcode  : 1 (pid: 232753)
  error_file: /local/scr/hmbaier/TMPDIR/torchelastic_oix6t6ac/790876_kpcc1_qs/attempt_0/31/error.json
  traceback : Traceback (most recent call last):
    File "/sciclone/home20/hmbaier/.conda/envs/dhsrl4/lib/python3.9/site-packages/torch/distributed/elastic/multiprocessing/errors/__init__.py", line 345, in wrapper
      return f(*args, **kwargs)
    File "/sciclone/home20/hmbaier/tm/run.py", line 122, in main
      output = ddp_model(input)
    File "/sciclone/home20/hmbaier/.conda/envs/dhsrl4/lib/python3.9/site-packages/torch/nn/modules/module.py", line 1102, in _call_impl
      return forward_call(*input, **kwargs)
    File "/sciclone/home20/hmbaier/.conda/envs/dhsrl4/lib/python3.9/site-packages/torch/nn/parallel/distributed.py", line 878, in forward
      self._sync_params()
    File "/sciclone/home20/hmbaier/.conda/envs/dhsrl4/lib/python3.9/site-packages/torch/nn/parallel/distributed.py", line 1379, in _sync_params
      self._distributed_broadcast_coalesced(
    File "/sciclone/home20/hmbaier/.conda/envs/dhsrl4/lib/python3.9/site-packages/torch/nn/parallel/distributed.py", line 1334, in _distributed_broadcast_coalesced
      dist._broadcast_coalesced(
  RuntimeError: [/opt/conda/conda-bld/pytorch_1634272107467/work/third_party/gloo/gloo/transport/tcp/pair.cc:598] Connection closed by peer [10.3.59.1]:14740
  
------------------------------------------------------------
Root Cause (first observed failure):
[1]:
  time      : 2022-03-10_15:54:53
  host      : mlt002.sciclone.wm.edu
  rank      : 34 (local_rank: 2)
  exitcode  : 1 (pid: 232724)
  error_file: /local/scr/hmbaier/TMPDIR/torchelastic_oix6t6ac/790876_kpcc1_qs/attempt_0/2/error.json
  traceback : Traceback (most recent call last):
    File "/sciclone/home20/hmbaier/.conda/envs/dhsrl4/lib/python3.9/site-packages/torch/distributed/elastic/multiprocessing/errors/__init__.py", line 345, in wrapper
      return f(*args, **kwargs)
    File "/sciclone/home20/hmbaier/tm/run.py", line 100, in main
      ddp_model = DDP(model, process_group = model_group)
    File "/sciclone/home20/hmbaier/.conda/envs/dhsrl4/lib/python3.9/site-packages/torch/nn/parallel/distributed.py", line 580, in __init__
      self._sync_params_and_buffers(authoritative_rank=0)
    File "/sciclone/home20/hmbaier/.conda/envs/dhsrl4/lib/python3.9/site-packages/torch/nn/parallel/distributed.py", line 597, in _sync_params_and_buffers
      self._distributed_broadcast_coalesced(
    File "/sciclone/home20/hmbaier/.conda/envs/dhsrl4/lib/python3.9/site-packages/torch/nn/parallel/distributed.py", line 1334, in _distributed_broadcast_coalesced
      dist._broadcast_coalesced(
  RuntimeError: [/opt/conda/conda-bld/pytorch_1634272107467/work/third_party/gloo/gloo/transport/tcp/pair.cc:598] Connection closed by peer [10.3.59.1]:43650
  
============================================================
